Workbook
Name SpeciesList1: 'M1'!#REF!
Name SpeciesList2: 'M2'!#REF!

Sheet SUMMARY
A3: Sum of Total | C3: Date | D3: Site No. | E3: Depth
C4: 4/22/2024 | E4: 4/23/2024 | J4: 4/24/2024 | L4: 4/25/2024 | O4: 4/26/2024 | T4: 45404 | X4: 45405 | AA4: 45406 | AD4: 45407 | AE4: 45411 | AH4: 45412 | AJ4: 45413 | AL4: 45414 | AN4: 45415 | AP4: (blank) | AQ4: Grand Total
F6: Frequency | G6: av abund
F7: =COUNT(C7:D7) -> 0 | G7: =AVERAGE(C7:D7) -> #DIV/0! | H7: =COUNTIFS(DATA!Q:Q,SUMMARY!B7,DATA!S:S,1) -> 0
F8: =COUNT(C8:D8) -> 0 | G8: =AVERAGE(C8:D8) -> #DIV/0!
F9: =COUNT(C9:D9) -> 0 | G9: =AVERAGE(C9:D9) -> #DIV/0!
F10: =COUNT(C10:D10) -> 0 | G10: =AVERAGE(C10:D10) -> #DIV/0!
F11: =COUNT(C11:D11) -> 0 | G11: =AVERAGE(C11:D11) -> #DIV/0!
F12: =COUNT(C12:D12) -> 0 | G12: =AVERAGE(C12:D12) -> #DIV/0!
F13: =COUNT(C13:D13) -> 0 | G13: =AVERAGE(C13:D13) -> #DIV/0!
F14: =COUNT(C14:D14) -> 0 | G14: =AVERAGE(C14:D14) -> #DIV/0!
F15: =COUNT(C15:D15) -> 0 | G15: =AVERAGE(C15:D15) -> #DIV/0!
F16: =COUNT(C16:D16) -> 0 | G16: =AVERAGE(C16:D16) -> #DIV/0!
F17: =COUNT(C17:D17) -> 0 | G17: =AVERAGE(C17:D17) -> #DIV/0!
F18: =COUNT(C18:D18) -> 0 | G18: =AVERAGE(C18:D18) -> #DIV/0!
F19: =COUNT(C19:D19) -> 0 | G19: =AVERAGE(C19:D19) -> #DIV/0!
... F46: =COUNT(C46:D46) -> 0 | G46: =AVERAGE(C46:D46) -> #DIV/0!

Sheet DATA
A1: ID | B1: Diver | C1: Buddy | D1: Site No. | E1: Site Name | F1: Latitude | G1: Longitude | H1: Date | I1: vis | J1: Direction | K1: Time | L1: Depth | M1: Method | N1: Block | O1: Quadrat # (m) | P1: Code | Q1: Species | R1: Common name | S1: Total | T1: Inverts | U1: =2.5*U2 -> 2.5 | V1: =2.5*V2 -> 5 | W1: =2.5*W2 -> 7.5 | X1: =2.5*X2 -> 10 | Y1: =2.5*Y2 -> 12.5 | Z1: =2.5*Z2 -> 15 | AA1: =2.5*AA2 -> 20 | AB1: =2.5*AB2 -> 25 | ... AR1: =2.5*AR2 -> 200 | AS1: 250 | AT1: 300 | AU1: 350 | AV1: 400
K2: 0.5 | M2: Quadrat | N2: 0, 1, 2 | Q2: 2 | R2: 3 | S2: =SUM(S3:S10820) -> 1524 | T2: =SUM(T3:T10820) -> 4 | U2: 1 | V2: 2 | W2: 3 | X2: 4 | Y2: 5 | Z2: 6 | AA2: 8 | AB2: 10 | AC2: 12 | AD2: 14 | AE2: 16 | AF2: 20 | AG2: 25 | AH2: 30 | AI2: 35 | AJ2: 40 | AK2: 45 | AL2: 50 | AM2: 55 | AN2: 60 | AO2: 65 | AP2: 70 | AQ2: 75 | AR2: 80 | AS2: 100 | AT2: 120 | AU2: 140 | AV2: 160
A3: =MAX($A$1:$A2)+1 -> 1 | B3: Jasmin Schuster | C3: Tom Bird | D3: BMSC8 | E3: =IF(ISERROR(VLOOKUP($D3,SITES!$A:$E,2,FALSE)),"",VLOOKUP($D3,SITES!$A:$E,2,FALSE)) -> Baeria Rocks North Island Northside | F3: =IF(ISERROR(VLOOKUP($D3,SITES!$A:$E,3,FALSE)),"",VLOOKUP($D3,SITES!$A:$E,3,FALSE)) -> 48.955082 | G3: =IF(ISERROR(VLOOKUP($D3,SITES!$A:$E,4,FALSE)),"",VLOOKUP($D3,SITES!$A:$E,4,FALSE)) -> -125.15337 | H3: 45404 | I3: 1 | J3: NW | K3: 0.42361111 | L3: 7.5 | M3: 2 | N3: 1 | O3: 48 | P3: Pmi | Q3: =IF($M3=1,IF(ISERROR(VLOOKUP($P3,'M1'!$A:$C,Q$2,FALSE)),"NOT PRESENT",VLOOKUP($P3,'M1'!$A:$C,Q$2,FALSE)),IF($M3=2,IF(ISERROR(VLOOKUP(DATA!$P3,'M2'!$A:$C,Q$2,FALSE)),"NOT PRESENT",VLOOKUP(DATA!$P3,'M2'!$A:$C,Q$2,FALSE)),IF($M3=0,IF(ISERROR(VLOOKUP($P3,'M1'!$A:$C,Q$2,FALSE)),IF(ISERROR(VLOOKUP(DATA!$P3,'M2'!$A:$C,Q$2,FALSE)),"NOT PRESENT",VLOOKUP(DATA!$P3,'M2'!$A:$C,Q$2,FALSE)),VLOOKUP($P3,'M1'!$A:$C,Q$2,FALSE)),"SPECIFY METHOD"))) -> Patiria miniata | R3: =IF($M3=1,IF(ISERROR(VLOOKUP($P3,'M1'!$A:$C,R$2,FALSE)),"NOT PRESENT",VLOOKUP($P3,'M1'!$A:$C,R$2,FALSE)),IF($M3=2,IF(ISERROR(VLOOKUP(DATA!$P3,'M2'!$A:$C,R$2,FALSE)),"NOT PRESENT",VLOOKUP(DATA!$P3,'M2'!$A:$C,R$2,FALSE)),IF($M3=0,IF(ISERROR(VLOOKUP($P3,'M1'!$A:$C,R$2,FALSE)),IF(ISERROR(VLOOKUP(DATA!$P3,'M2'!$A:$C,R$2,FALSE)),"NOT PRESENT",VLOOKUP(DATA!$P3,'M2'!$A:$C,R$2,FALSE)),VLOOKUP($P3,'M1'!$A:$C,R$2,FALSE)),"SPECIFY METHOD"))) -> Bat star | S3: =SUM(T3:AV3) -> 4 | T3: 0 | U3: 1 | V3: 1 | W3: 2
A4: =MAX($A$1:$A3)+1 -> 2 | B4: =IF(ISERROR(B3),IF(ISERROR(B2),IF(ISERROR(B1),"BLANK",B1),B2),B3) -> Jasmin Schuster | C4: =IF(ISERROR(C3),IF(ISERROR(C2),IF(ISERROR(C1),"BLANK",C1),C2),C3) -> Tom Bird | D4: =IF(ISERROR(D3),IF(ISERROR(D2),IF(ISERROR(D1),"BLANK",D1),D2),D3) -> BMSC8 | E4: =IF(ISERROR(VLOOKUP($D4,SITES!$A:$E,2,FALSE)),"",VLOOKUP($D4,SITES!$A:$E,2,FALSE)) -> Baeria Rocks North Island Northside | F4: =IF(ISERROR(VLOOKUP($D4,SITES!$A:$E,3,FALSE)),"",VLOOKUP($D4,SITES!$A:$E,3,FALSE)) -> 48.955082 | G4: =IF(ISERROR(VLOOKUP($D4,SITES!$A:$E,4,FALSE)),"",VLOOKUP($D4,SITES!$A:$E,4,FALSE)) -> -125.15337 | H4: =IF(ISERROR(H3),IF(ISERROR(H2),IF(ISERROR(H1),"BLANK",H1),H2),H3) -> 45404 | I4: =IF(ISERROR(I3),IF(ISERROR(I2),IF(ISERROR(I1),"BLANK",I1),I2),I3) -> 1 | J4: =IF(ISERROR(J3),IF(ISERROR(J2),IF(ISERROR(J1),"BLANK",J1),J2),J3) -> NW | K4: =IF(ISERROR(K3),IF(ISERROR(K2),IF(ISERROR(K1),"BLANK",K1),K2),K3) -> 0.42361111 | L4: =IF(ISERROR(L3),IF(ISERROR(L2),IF(ISERROR(L1),"BLANK",L1),L2),L3) -> 7.5 | M4: =IF(ISERROR(M3),IF(ISERROR(M2),IF(ISERROR(M1),"BLANK",M1),M2),M3) -> 2 | N4: =IF(ISERROR(N3),IF(ISERROR(N2),IF(ISERROR(N1),"BLANK",N1),N2),N3) -> 1 | O4: 48 | P4: Mfra | Q4: =IF($M4=1,IF(ISERROR(VLOOKUP($P4,'M1'!$A:$C,Q$2,FALSE)),"NOT PRESENT",VLOOKUP($P4,'M1'!$A:$C,Q$2,FALSE)),IF($M4=2,IF(ISERROR(VLOOKUP(DATA!$P4,'M2'!$A:$C,Q$2,FALSE)),"NOT PRESENT",VLOOKUP(DATA!$P4,'M2'!$A:$C,Q$2,FALSE)),IF($M4=0,IF(ISERROR(VLOOKUP($P4,'M1'!$A:$C,Q$2,FALSE)),IF(ISERROR(VLOOKUP(DATA!$P4,'M2'!$A:$C,Q$2,FALSE)),"NOT PRESENT",VLOOKUP(DATA!$P4,'M2'!$A:$C,Q$2,FALSE)),VLOOKUP($P4,'M1'!$A:$C,Q$2,FALSE)),"SPECIFY METHOD"))) -> Mesocentrotus franciscanus | R4: =IF($M4=1,IF(ISERROR(VLOOKUP($P4,'M1'!$A:$C,R$2,FALSE)),"NOT PRESENT",VLOOKUP($P4,'M1'!$A:$C,R$2,FALSE)),IF($M4=2,IF(ISERROR(VLOOKUP(DATA!$P4,'M2'!$A:$C,R$2,FALSE)),"NOT PRESENT",VLOOKUP(DATA!$P4,'M2'!$A:$C,R$2,FALSE)),IF($M4=0,IF(ISERROR(VLOOKUP($P4,'M1'!$A:$C,R$2,FALSE)),IF(ISERROR(VLOOKUP(DATA!$P4,'M2'!$A:$C,R$2,FALSE)),"NOT PRESENT",VLOOKUP(DATA!$P4,'M2'!$A:$C,R$2,FALSE)),VLOOKUP($P4,'M1'!$A:$C,R$2,FALSE)),"SPECIFY METHOD"))) -> Red sea urchin | S4: =SUM(T4:AV4) -> 3 | T4: 0 | U4: 1 | V4: 2
A5: =MAX($A$1:$A4)+1 -> 3 | B5: =IF(ISERROR(B4),IF(ISERROR(B3),IF(ISERROR(B2),"BLANK",B2),B3),B4) -> Jasmin Schuster | C5: =IF(ISERROR(C4),IF(ISERROR(C3),IF(ISERROR(C2),"BLANK",C2),C3),C4) -> Tom Bird | D5: =IF(ISERROR(D4),IF(ISERROR(D3),IF(ISERROR(D2),"BLANK",D2),D3),D4) -> BMSC8 | E5: =IF(ISERROR(VLOOKUP($D5,SITES!$A:$E,2,FALSE)),"",VLOOKUP($D5,SITES!$A:$E,2,FALSE)) -> Baeria Rocks North Island Northside | F5: =IF(ISERROR(VLOOKUP($D5,SITES!$A:$E,3,FALSE)),"",VLOOKUP($D5,SITES!$A:$E,3,FALSE)) -> 48.955082 | G5: =IF(ISERROR(VLOOKUP($D5,SITES!$A:$E,4,FALSE)),"",VLOOKUP($D5,SITES!$A:$E,4,FALSE)) -> -125.15337 | H5: =IF(ISERROR(H4),IF(ISERROR(H3),IF(ISERROR(H2),"BLANK",H2),H3),H4) -> 45404 | I5: =IF(ISERROR(I4),IF(ISERROR(I3),IF(ISERROR(I2),"BLANK",I2),I3),I4) -> 1 | J5: =IF(ISERROR(J4),IF(ISERROR(J3),IF(ISERROR(J2),"BLANK",J2),J3),J4) -> NW | K5: =IF(ISERROR(K4),IF(ISERROR(K3),IF(ISERROR(K2),"BLANK",K2),K3),K4) -> 0.42361111 | L5: =IF(ISERROR(L4),IF(ISERROR(L3),IF(ISERROR(L2),"BLANK",L2),L3),L4) -> 7.5 | M5: =IF(ISERROR(M4),IF(ISERROR(M3),IF(ISERROR(M2),"BLANK",M2),M3),M4) -> 2 | N5: =IF(ISERROR(N4),IF(ISERROR(N3),IF(ISERROR(N2),"BLANK",N2),N3),N4) -> 1 | O5: 32 | P5: Mfra | Q5: =IF($M5=1,IF(ISERROR(VLOOKUP($P5,'M1'!$A:$C,Q$2,FALSE)),"NOT PRESENT",VLOOKUP($P5,'M1'!$A:$C,Q$2,FALSE)),IF($M5=2,IF(ISERROR(VLOOKUP(DATA!$P5,'M2'!$A:$C,Q$2,FALSE)),"NOT PRESENT",VLOOKUP(DATA!$P5,'M2'!$A:$C,Q$2,FALSE)),IF($M5=0,IF(ISERROR(VLOOKUP($P5,'M1'!$A:$C,Q$2,FALSE)),IF(ISERROR(VLOOKUP(DATA!$P5,'M2'!$A:$C,Q$2,FALSE)),"NOT PRESENT",VLOOKUP(DATA!$P5,'M2'!$A:$C,Q$2,FALSE)),VLOOKUP($P5,'M1'!$A:$C,Q$2,FALSE)),"SPECIFY METHOD"))) -> Mesocentrotus franciscanus | R5: =IF($M5=1,IF(ISERROR(VLOOKUP($P5,'M1'!$A:$C,R$2,FALSE)),"NOT PRESENT",VLOOKUP($P5,'M1'!$A:$C,R$2,FALSE)),IF($M5=2,IF(ISERROR(VLOOKUP(DATA!$P5,'M2'!$A:$C,R$2,FALSE)),"NOT PRESENT",VLOOKUP(DATA!$P5,'M2'!$A:$C,R$2,FALSE)),IF($M5=0,IF(ISERROR(VLOOKUP($P5,'M1'!$A:$C,R$2,FALSE)),IF(ISERROR(VLOOKUP(DATA!$P5,'M2'!$A:$C,R$2,FALSE)),"NOT PRESENT",VLOOKUP(DATA!$P5,'M2'!$A:$C,R$2,FALSE)),VLOOKUP($P5,'M1'!$A:$C,R$2,FALSE)),"SPECIFY METHOD"))) -> Red sea urchin | S5: =SUM(T5:AV5) -> 11 | T5: 0 | U5: 6 | V5: 3 | W5: 2
A6: =MAX($A$1:$A5)+1 -> 4 | B6: =IF(ISERROR(B5),IF(ISERROR(B4),IF(ISERROR(B3),"BLANK",B3),B4),B5) -> Jasmin Schuster | C6: =IF(ISERROR(C5),IF(ISERROR(C4),IF(ISERROR(C3),"BLANK",C3),C4),C5) -> Tom Bird | D6: =IF(ISERROR(D5),IF(ISERROR(D4),IF(ISERROR(D3),"BLANK",D3),D4),D5) -> BMSC8 | E6: =IF(ISERROR(VLOOKUP($D6,SITES!$A:$E,2,FALSE)),"",VLOOKUP($D6,SITES!$A:$E,2,FALSE)) -> Baeria Rocks North Island Northside | F6: =IF(ISERROR(VLOOKUP($D6,SITES!$A:$E,3,FALSE)),"",VLOOKUP($D6,SITES!$A:$E,3,FALSE)) -> 48.955082 | G6: =IF(ISERROR(VLOOKUP($D6,SITES!$A:$E,4,FALSE)),"",VLOOKUP($D6,SITES!$A:$E,4,FALSE)) -> -125.15337 | H6: =IF(ISERROR(H5),IF(ISERROR(H4),IF(ISERROR(H3),"BLANK",H3),H4),H5) -> 45404 | I6: =IF(ISERROR(I5),IF(ISERROR(I4),IF(ISERROR(I3),"BLANK",I3),I4),I5) -> 1 | J6: =IF(ISERROR(J5),IF(ISERROR(J4),IF(ISERROR(J3),"BLANK",J3),J4),J5) -> NW | K6: =IF(ISERROR(K5),IF(ISERROR(K4),IF(ISERROR(K3),"BLANK",K3),K4),K5) -> 0.42361111 | L6: =IF(ISERROR(L5),IF(ISERROR(L4),IF(ISERROR(L3),"BLANK",L3),L4),L5) -> 7.5 | M6: =IF(ISERROR(M5),IF(ISERROR(M4),IF(ISERROR(M3),"BLANK",M3),M4),M5) -> 2 | N6: =IF(ISERROR(N5),IF(ISERROR(N4),IF(ISERROR(N3),"BLANK",N3),N4),N5) -> 1 | O6: 32 | P6: Pmi | Q6: =IF($M6=1,IF(ISERROR(VLOOKUP($P6,'M1'!$A:$C,Q$2,FALSE)),"NOT PRESENT",VLOOKUP($P6,'M1'!$A:$C,Q$2,FALSE)),IF($M6=2,IF(ISERROR(VLOOKUP(DATA!$P6,'M2'!$A:$C,Q$2,FALSE)),"NOT PRESENT",VLOOKUP(DATA!$P6,'M2'!$A:$C,Q$2,FALSE)),IF($M6=0,IF(ISERROR(VLOOKUP($P6,'M1'!$A:$C,Q$2,FALSE)),IF(ISERROR(VLOOKUP(DATA!$P6,'M2'!$A:$C,Q$2,FALSE)),"NOT PRESENT",VLOOKUP(DATA!$P6,'M2'!$A:$C,Q$2,FALSE)),VLOOKUP($P6,'M1'!$A:$C,Q$2,FALSE)),"SPECIFY METHOD"))) -> Patiria miniata | R6: =IF($M6=1,IF(ISERROR(VLOOKUP($P6,'M1'!$A:$C,R$2,FALSE)),"NOT PRESENT",VLOOKUP($P6,'M1'!$A:$C,R$2,FALSE)),IF($M6=2,IF(ISERROR(VLOOKUP(DATA!$P6,'M2'!$A:$C,R$2,FALSE)),"NOT PRESENT",VLOOKUP(DATA!$P6,'M2'!$A:$C,R$2,FALSE)),IF($M6=0,IF(ISERROR(VLOOKUP($P6,'M1'!$A:$C,R$2,FALSE)),IF(ISERROR(VLOOKUP(DATA!$P6,'M2'!$A:$C,R$2,FALSE)),"NOT PRESENT",VLOOKUP(DATA!$P6,'M2'!$A:$C,R$2,FALSE)),VLOOKUP($P6,'M1'!$A:$C,R$2,FALSE)),"SPECIFY METHOD"))) -> Bat star | S6: =SUM(T6:AV6) -> 2 | T6: 0 | U6: 2
A7: =MAX($A$1:$A6)+1 -> 5 | B7: =IF(ISERROR(B6),IF(ISERROR(B5),IF(ISERROR(B4),"BLANK",B4),B5),B6) -> Jasmin Schuster | C7: =IF(ISERROR(C6),IF(ISERROR(C5),IF(ISERROR(C4),"BLANK",C4),C5),C6) -> Tom Bird | D7: =IF(ISERROR(D6),IF(ISERROR(D5),IF(ISERROR(D4),"BLANK",D4),D5),D6) -> BMSC8 | E7: =IF(ISERROR(VLOOKUP($D7,SITES!$A:$E,2,FALSE)),"",VLOOKUP($D7,SITES!$A:$E,2,FALSE)) -> Baeria Rocks North Island Northside | F7: =IF(ISERROR(VLOOKUP($D7,SITES!$A:$E,3,FALSE)),"",VLOOKUP($D7,SITES!$A:$E,3,FALSE)) -> 48.955082 | G7: =IF(ISERROR(VLOOKUP($D7,SITES!$A:$E,4,FALSE)),"",VLOOKUP($D7,SITES!$A:$E,4,FALSE)) -> -125.15337 | H7: =IF(ISERROR(H6),IF(ISERROR(H5),IF(ISERROR(H4),"BLANK",H4),H5),H6) -> 45404 | I7: =IF(ISERROR(I6),IF(ISERROR(I5),IF(ISERROR(I4),"BLANK",I4),I5),I6) -> 1 | J7: =IF(ISERROR(J6),IF(ISERROR(J5),IF(ISERROR(J4),"BLANK",J4),J5),J6) -> NW | K7: =IF(ISERROR(K6),IF(ISERROR(K5),IF(ISERROR(K4),"BLANK",K4),K5),K6) -> 0.42361111 | L7: =IF(ISERROR(L6),IF(ISERROR(L5),IF(ISERROR(L4),"BLANK",L4),L5),L6) -> 7.5 | M7: =IF(ISERROR(M6),IF(ISERROR(M5),IF(ISERROR(M4),"BLANK",M4),M5),M6) -> 2 | N7: =IF(ISERROR(N6),IF(ISERROR(N5),IF(ISERROR(N4),"BLANK",N4),N5),N6) -> 1 | O7: 16 | P7: =IF(ISERROR(P6),IF(ISERROR(P5),IF(ISERROR(P4),"BLANK",P4),P5),P6) -> Pmi | Q7: =IF($M7=1,IF(ISERROR(VLOOKUP($P7,'M1'!$A:$C,Q$2,FALSE)),"NOT PRESENT",VLOOKUP($P7,'M1'!$A:$C,Q$2,FALSE)),IF($M7=2,IF(ISERROR(VLOOKUP(DATA!$P7,'M2'!$A:$C,Q$2,FALSE)),"NOT PRESENT",VLOOKUP(DATA!$P7,'M2'!$A:$C,Q$2,FALSE)),IF($M7=0,IF(ISERROR(VLOOKUP($P7,'M1'!$A:$C,Q$2,FALSE)),IF(ISERROR(VLOOKUP(DATA!$P7,'M2'!$A:$C,Q$2,FALSE)),"NOT PRESENT",VLOOKUP(DATA!$P7,'M2'!$A:$C,Q$2,FALSE)),VLOOKUP($P7,'M1'!$A:$C,Q$2,FALSE)),"SPECIFY METHOD"))) -> Patiria miniata | R7: =IF($M7=1,IF(ISERROR(VLOOKUP($P7,'M1'!$A:$C,R$2,FALSE)),"NOT PRESENT",VLOOKUP($P7,'M1'!$A:$C,R$2,FALSE)),IF($M7=2,IF(ISERROR(VLOOKUP(DATA!$P7,'M2'!$A:$C,R$2,FALSE)),"NOT PRESENT",VLOOKUP(DATA!$P7,'M2'!$A:$C,R$2,FALSE)),IF($M7=0,IF(ISERROR(VLOOKUP($P7,'M1'!$A:$C,R$2,FALSE)),IF(ISERROR(VLOOKUP(DATA!$P7,'M2'!$A:$C,R$2,FALSE)),"NOT PRESENT",VLOOKUP(DATA!$P7,'M2'!$A:$C,R$2,FALSE)),VLOOKUP($P7,'M1'!$A:$C,R$2,FALSE)),"SPECIFY METHOD"))) -> Bat star | S7: =SUM(T7:AV7) -> 1 | T7: 0 | W7: 1
A8: =MAX($A$1:$A7)+1 -> 6 | B8: =IF(ISERROR(B7),IF(ISERROR(B6),IF(ISERROR(B5),"BLANK",B5),B6),B7) -> Jasmin Schuster | C8: =IF(ISERROR(C7),IF(ISERROR(C6),IF(ISERROR(C5),"BLANK",C5),C6),C7) -> Tom Bird | D8: =IF(ISERROR(D7),IF(ISERROR(D6),IF(ISERROR(D5),"BLANK",D5),D6),D7) -> BMSC8 | E8: =IF(ISERROR(VLOOKUP($D8,SITES!$A:$E,2,FALSE)),"",VLOOKUP($D8,SITES!$A:$E,2,FALSE)) -> Baeria Rocks North Island Northside | F8: =IF(ISERROR(VLOOKUP($D8,SITES!$A:$E,3,FALSE)),"",VLOOKUP($D8,SITES!$A:$E,3,FALSE)) -> 48.955082 | G8: =IF(ISERROR(VLOOKUP($D8,SITES!$A:$E,4,FALSE)),"",VLOOKUP($D8,SITES!$A:$E,4,FALSE)) -> -125.15337 | H8: =IF(ISERROR(H7),IF(ISERROR(H6),IF(ISERROR(H5),"BLANK",H5),H6),H7) -> 45404 | I8: =IF(ISERROR(I7),IF(ISERROR(I6),IF(ISERROR(I5),"BLANK",I5),I6),I7) -> 1 | J8: =IF(ISERROR(J7),IF(ISERROR(J6),IF(ISERROR(J5),"BLANK",J5),J6),J7) -> NW | K8: =IF(ISERROR(K7),IF(ISERROR(K6),IF(ISERROR(K5),"BLANK",K5),K6),K7) -> 0.42361111 | L8: =IF(ISERROR(L7),IF(ISERROR(L6),IF(ISERROR(L5),"BLANK",L5),L6),L7) -> 7.5 | M8: =IF(ISERROR(M7),IF(ISERROR(M6),IF(ISERROR(M5),"BLANK",M5),M6),M7) -> 2 | N8: =IF(ISERROR(N7),IF(ISERROR(N6),IF(ISERROR(N5),"BLANK",N5),N6),N7) -> 1 | O8: 16 | P8: Mfra | Q8: =IF($M8=1,IF(ISERROR(VLOOKUP($P8,'M1'!$A:$C,Q$2,FALSE)),"NOT PRESENT",VLOOKUP($P8,'M1'!$A:$C,Q$2,FALSE)),IF($M8=2,IF(ISERROR(VLOOKUP(DATA!$P8,'M2'!$A:$C,Q$2,FALSE)),"NOT PRESENT",VLOOKUP(DATA!$P8,'M2'!$A:$C,Q$2,FALSE)),IF($M8=0,IF(ISERROR(VLOOKUP($P8,'M1'!$A:$C,Q$2,FALSE)),IF(ISERROR(VLOOKUP(DATA!$P8,'M2'!$A:$C,Q$2,FALSE)),"NOT PRESENT",VLOOKUP(DATA!$P8,'M2'!$A:$C,Q$2,FALSE)),VLOOKUP($P8,'M1'!$A:$C,Q$2,FALSE)),"SPECIFY METHOD"))) -> Mesocentrotus franciscanus | R8: =IF($M8=1,IF(ISERROR(VLOOKUP($P8,'M1'!$A:$C,R$2,FALSE)),"NOT PRESENT",VLOOKUP($P8,'M1'!$A:$C,R$2,FALSE)),IF($M8=2,IF(ISERROR(VLOOKUP(DATA!$P8,'M2'!$A:$C,R$2,FALSE)),"NOT PRESENT",VLOOKUP(DATA!$P8,'M2'!$A:$C,R$2,FALSE)),IF($M8=0,IF(ISERROR(VLOOKUP($P8,'M1'!$A:$C,R$2,FALSE)),IF(ISERROR(VLOOKUP(DATA!$P8,'M2'!$A:$C,R$2,FALSE)),"NOT PRESENT",VLOOKUP(DATA!$P8,'M2'!$A:$C,R$2,FALSE)),VLOOKUP($P8,'M1'!$A:$C,R$2,FALSE)),"SPECIFY METHOD"))) -> Red sea urchin | S8: =SUM(T8:AV8) -> 8 | T8: 0 | U8: 1 | V8: 6 | W8: 1
A9: =MAX($A$1:$A8)+1 -> 7 | B9: =IF(ISERROR(B8),IF(ISERROR(B7),IF(ISERROR(B6),"BLANK",B6),B7),B8) -> Jasmin Schuster | C9: =IF(ISERROR(C8),IF(ISERROR(C7),IF(ISERROR(C6),"BLANK",C6),C7),C8) -> Tom Bird | D9: =IF(ISERROR(D8),IF(ISERROR(D7),IF(ISERROR(D6),"BLANK",D6),D7),D8) -> BMSC8 | E9: =IF(ISERROR(VLOOKUP($D9,SITES!$A:$E,2,FALSE)),"",VLOOKUP($D9,SITES!$A:$E,2,FALSE)) -> Baeria Rocks North Island Northside | F9: =IF(ISERROR(VLOOKUP($D9,SITES!$A:$E,3,FALSE)),"",VLOOKUP($D9,SITES!$A:$E,3,FALSE)) -> 48.955082 | G9: =IF(ISERROR(VLOOKUP($D9,SITES!$A:$E,4,FALSE)),"",VLOOKUP($D9,SITES!$A:$E,4,FALSE)) -> -125.15337 | H9: =IF(ISERROR(H8),IF(ISERROR(H7),IF(ISERROR(H6),"BLANK",H6),H7),H8) -> 45404 | I9: =IF(ISERROR(I8),IF(ISERROR(I7),IF(ISERROR(I6),"BLANK",I6),I7),I8) -> 1 | J9: =IF(ISERROR(J8),IF(ISERROR(J7),IF(ISERROR(J6),"BLANK",J6),J7),J8) -> NW | K9: =IF(ISERROR(K8),IF(ISERROR(K7),IF(ISERROR(K6),"BLANK",K6),K7),K8) -> 0.42361111 | L9: =IF(ISERROR(L8),IF(ISERROR(L7),IF(ISERROR(L6),"BLANK",L6),L7),L8) -> 7.5 | M9: =IF(ISERROR(M8),IF(ISERROR(M7),IF(ISERROR(M6),"BLANK",M6),M7),M8) -> 2 | N9: =IF(ISERROR(N8),IF(ISERROR(N7),IF(ISERROR(N6),"BLANK",N6),N7),N8) -> 1 | O9: 16 | P9: Poc | Q9: =IF($M9=1,IF(ISERROR(VLOOKUP($P9,'M1'!$A:$C,Q$2,FALSE)),"NOT PRESENT",VLOOKUP($P9,'M1'!$A:$C,Q$2,FALSE)),IF($M9=2,IF(ISERROR(VLOOKUP(DATA!$P9,'M2'!$A:$C,Q$2,FALSE)),"NOT PRESENT",VLOOKUP(DATA!$P9,'M2'!$A:$C,Q$2,FALSE)),IF($M9=0,IF(ISERROR(VLOOKUP($P9,'M1'!$A:$C,Q$2,FALSE)),IF(ISERROR(VLOOKUP(DATA!$P9,'M2'!$A:$C,Q$2,FALSE)),"NOT PRESENT",VLOOKUP(DATA!$P9,'M2'!$A:$C,Q$2,FALSE)),VLOOKUP($P9,'M1'!$A:$C,Q$2,FALSE)),"SPECIFY METHOD"))) -> Pisaster ochraceus | R9: Unidentified star?? | S9: =SUM(T9:AV9) -> 1 | T9: 0 | U9: 1
A10: =MAX($A$1:$A9)+1 -> 8 | B10: =IF(ISERROR(B9),IF(ISERROR(B8),IF(ISERROR(B7),"BLANK",B7),B8),B9) -> Jasmin Schuster | C10: =IF(ISERROR(C9),IF(ISERROR(C8),IF(ISERROR(C7),"BLANK",C7),C8),C9) -> Tom Bird | D10: =IF(ISERROR(D9),IF(ISERROR(D8),IF(ISERROR(D7),"BLANK",D7),D8),D9) -> BMSC8 | E10: =IF(ISERROR(VLOOKUP($D10,SITES!$A:$E,2,FALSE)),"",VLOOKUP($D10,SITES!$A:$E,2,FALSE)) -> Baeria Rocks North Island Northside | F10: =IF(ISERROR(VLOOKUP($D10,SITES!$A:$E,3,FALSE)),"",VLOOKUP($D10,SITES!$A:$E,3,FALSE)) -> 48.955082 | G10: =IF(ISERROR(VLOOKUP($D10,SITES!$A:$E,4,FALSE)),"",VLOOKUP($D10,SITES!$A:$E,4,FALSE)) -> -125.15337 | H10: =IF(ISERROR(H9),IF(ISERROR(H8),IF(ISERROR(H7),"BLANK",H7),H8),H9) -> 45404 | I10: =IF(ISERROR(I9),IF(ISERROR(I8),IF(ISERROR(I7),"BLANK",I7),I8),I9) -> 1 | J10: =IF(ISERROR(J9),IF(ISERROR(J8),IF(ISERROR(J7),"BLANK",J7),J8),J9) -> NW | K10: =IF(ISERROR(K9),IF(ISERROR(K8),IF(ISERROR(K7),"BLANK",K7),K8),K9) -> 0.42361111 | L10: =IF(ISERROR(L9),IF(ISERROR(L8),IF(ISERROR(L7),"BLANK",L7),L8),L9) -> 7.5 | M10: =IF(ISERROR(M9),IF(ISERROR(M8),IF(ISERROR(M7),"BLANK",M7),M8),M9) -> 2 | N10: =IF(ISERROR(N9),IF(ISERROR(N8),IF(ISERROR(N7),"BLANK",N7),N8),N9) -> 1 | O10: 0 | P10: Mfra | Q10: =IF($M10=1,IF(ISERROR(VLOOKUP($P10,'M1'!$A:$C,Q$2,FALSE)),"NOT PRESENT",VLOOKUP($P10,'M1'!$A:$C,Q$2,FALSE)),IF($M10=2,IF(ISERROR(VLOOKUP(DATA!$P10,'M2'!$A:$C,Q$2,FALSE)),"NOT PRESENT",VLOOKUP(DATA!$P10,'M2'!$A:$C,Q$2,FALSE)),IF($M10=0,IF(ISERROR(VLOOKUP($P10,'M1'!$A:$C,Q$2,FALSE)),IF(ISERROR(VLOOKUP(DATA!$P10,'M2'!$A:$C,Q$2,FALSE)),"NOT PRESENT",VLOOKUP(DATA!$P10,'M2'!$A:$C,Q$2,FALSE)),VLOOKUP($P10,'M1'!$A:$C,Q$2,FALSE)),"SPECIFY METHOD"))) -> Mesocentrotus franciscanus | R10: =IF($M10=1,IF(ISERROR(VLOOKUP($P10,'M1'!$A:$C,R$2,FALSE)),"NOT PRESENT",VLOOKUP($P10,'M1'!$A:$C,R$2,FALSE)),IF($M10=2,IF(ISERROR(VLOOKUP(DATA!$P10,'M2'!$A:$C,R$2,FALSE)),"NOT PRESENT",VLOOKUP(DATA!$P10,'M2'!$A:$C,R$2,FALSE)),IF($M10=0,IF(ISERROR(VLOOKUP($P10,'M1'!$A:$C,R$2,FALSE)),IF(ISERROR(VLOOKUP(DATA!$P10,'M2'!$A:$C,R$2,FALSE)),"NOT PRESENT",VLOOKUP(DATA!$P10,'M2'!$A:$C,R$2,FALSE)),VLOOKUP($P10,'M1'!$A:$C,R$2,FALSE)),"SPECIFY METHOD"))) -> Red sea urchin | S10: =SUM(T10:AV10) -> 5 | T10: 0 | V10: 4 | W10: 1
A11: =MAX($A$1:$A10)+1 -> 9 | B11: =IF(ISERROR(B10),IF(ISERROR(B9),IF(ISERROR(B8),"BLANK",B8),B9),B10) -> Jasmin Schuster | C11: =IF(ISERROR(C10),IF(ISERROR(C9),IF(ISERROR(C8),"BLANK",C8),C9),C10) -> Tom Bird | D11: =IF(ISERROR(D10),IF(ISERROR(D9),IF(ISERROR(D8),"BLANK",D8),D9),D10) -> BMSC8 | E11: =IF(ISERROR(VLOOKUP($D11,SITES!$A:$E,2,FALSE)),"",VLOOKUP($D11,SITES!$A:$E,2,FALSE)) -> Baeria Rocks North Island Northside | F11: =IF(ISERROR(VLOOKUP($D11,SITES!$A:$E,3,FALSE)),"",VLOOKUP($D11,SITES!$A:$E,3,FALSE)) -> 48.955082 | G11: =IF(ISERROR(VLOOKUP($D11,SITES!$A:$E,4,FALSE)),"",VLOOKUP($D11,SITES!$A:$E,4,FALSE)) -> -125.15337 | H11: =IF(ISERROR(H10),IF(ISERROR(H9),IF(ISERROR(H8),"BLANK",H8),H9),H10) -> 45404 | I11: =IF(ISERROR(I10),IF(ISERROR(I9),IF(ISERROR(I8),"BLANK",I8),I9),I10) -> 1 | J11: =IF(ISERROR(J10),IF(ISERROR(J9),IF(ISERROR(J8),"BLANK",J8),J9),J10) -> NW | K11: =IF(ISERROR(K10),IF(ISERROR(K9),IF(ISERROR(K8),"BLANK",K8),K9),K10) -> 0.42361111 | L11: =IF(ISERROR(L10),IF(ISERROR(L9),IF(ISERROR(L8),"BLANK",L8),L9),L10) -> 7.5 | M11: =IF(ISERROR(M10),IF(ISERROR(M9),IF(ISERROR(M8),"BLANK",M8),M9),M10) -> 2 | N11: =IF(ISERROR(N10),IF(ISERROR(N9),IF(ISERROR(N8),"BLANK",N8),N9),N10) -> 1 | O11: 0 | P11: Pmi | Q11: =IF($M11=1,IF(ISERROR(VLOOKUP($P11,'M1'!$A:$C,Q$2,FALSE)),"NOT PRESENT",VLOOKUP($P11,'M1'!$A:$C,Q$2,FALSE)),IF($M11=2,IF(ISERROR(VLOOKUP(DATA!$P11,'M2'!$A:$C,Q$2,FALSE)),"NOT PRESENT",VLOOKUP(DATA!$P11,'M2'!$A:$C,Q$2,FALSE)),IF($M11=0,IF(ISERROR(VLOOKUP($P11,'M1'!$A:$C,Q$2,FALSE)),IF(ISERROR(VLOOKUP(DATA!$P11,'M2'!$A:$C,Q$2,FALSE)),"NOT PRESENT",VLOOKUP(DATA!$P11,'M2'!$A:$C,Q$2,FALSE)),VLOOKUP($P11,'M1'!$A:$C,Q$2,FALSE)),"SPECIFY METHOD"))) -> Patiria miniata | R11: =IF($M11=1,IF(ISERROR(VLOOKUP($P11,'M1'!$A:$C,R$2,FALSE)),"NOT PRESENT",VLOOKUP($P11,'M1'!$A:$C,R$2,FALSE)),IF($M11=2,IF(ISERROR(VLOOKUP(DATA!$P11,'M2'!$A:$C,R$2,FALSE)),"NOT PRESENT",VLOOKUP(DATA!$P11,'M2'!$A:$C,R$2,FALSE)),IF($M11=0,IF(ISERROR(VLOOKUP($P11,'M1'!$A:$C,R$2,FALSE)),IF(ISERROR(VLOOKUP(DATA!$P11,'M2'!$A:$C,R$2,FALSE)),"NOT PRESENT",VLOOKUP(DATA!$P11,'M2'!$A:$C,R$2,FALSE)),VLOOKUP($P11,'M1'!$A:$C,R$2,FALSE)),"SPECIFY METHOD"))) -> Bat star | S11: =SUM(T11:AV11) -> 1 | T11: 0 | U11: 1
A12: =MAX($A$1:$A11)+1 -> 10 | B12: =IF(ISERROR(B11),IF(ISERROR(B10),IF(ISERROR(B9),"BLANK",B9),B10),B11) -> Jasmin Schuster | C12: =IF(ISERROR(C11),IF(ISERROR(C10),IF(ISERROR(C9),"BLANK",C9),C10),C11) -> Tom Bird | D12: BMSC6 | E12: =IF(ISERROR(VLOOKUP($D12,SITES!$A:$E,2,FALSE)),"",VLOOKUP($D12,SITES!$A:$E,2,FALSE)) -> Baeria Rocks South Island | F12: =IF(ISERROR(VLOOKUP($D12,SITES!$A:$E,3,FALSE)),"",VLOOKUP($D12,SITES!$A:$E,3,FALSE)) -> 48.950233 | G12: =IF(ISERROR(VLOOKUP($D12,SITES!$A:$E,4,FALSE)),"",VLOOKUP($D12,SITES!$A:$E,4,FALSE)) -> -125.15555 | H12: =IF(ISERROR(H11),IF(ISERROR(H10),IF(ISERROR(H9),"BLANK",H9),H10),H11) -> 45404 | I12: 1.5 | J12: SW | K12: 0.52986111 | L12: 8 | M12: =IF(ISERROR(M11),IF(ISERROR(M10),IF(ISERROR(M9),"BLANK",M9),M10),M11) -> 2 | N12: =IF(ISERROR(N11),IF(ISERROR(N10),IF(ISERROR(N9),"BLANK",N9),N10),N11) -> 1 | O12: 48 | P12: Pmi | Q12: =IF($M12=1,IF(ISERROR(VLOOKUP($P12,'M1'!$A:$C,Q$2,FALSE)),"NOT PRESENT",VLOOKUP($P12,'M1'!$A:$C,Q$2,FALSE)),IF($M12=2,IF(ISERROR(VLOOKUP(DATA!$P12,'M2'!$A:$C,Q$2,FALSE)),"NOT PRESENT",VLOOKUP(DATA!$P12,'M2'!$A:$C,Q$2,FALSE)),IF($M12=0,IF(ISERROR(VLOOKUP($P12,'M1'!$A:$C,Q$2,FALSE)),IF(ISERROR(VLOOKUP(DATA!$P12,'M2'!$A:$C,Q$2,FALSE)),"NOT PRESENT",VLOOKUP(DATA!$P12,'M2'!$A:$C,Q$2,FALSE)),VLOOKUP($P12,'M1'!$A:$C,Q$2,FALSE)),"SPECIFY METHOD"))) -> Patiria miniata | R12: =IF($M12=1,IF(ISERROR(VLOOKUP($P12,'M1'!$A:$C,R$2,FALSE)),"NOT PRESENT",VLOOKUP($P12,'M1'!$A:$C,R$2,FALSE)),IF($M12=2,IF(ISERROR(VLOOKUP(DATA!$P12,'M2'!$A:$C,R$2,FALSE)),"NOT PRESENT",VLOOKUP(DATA!$P12,'M2'!$A:$C,R$2,FALSE)),IF($M12=0,IF(ISERROR(VLOOKUP($P12,'M1'!$A:$C,R$2,FALSE)),IF(ISERROR(VLOOKUP(DATA!$P12,'M2'!$A:$C,R$2,FALSE)),"NOT PRESENT",VLOOKUP(DATA!$P12,'M2'!$A:$C,R$2,FALSE)),VLOOKUP($P12,'M1'!$A:$C,R$2,FALSE)),"SPECIFY METHOD"))) -> Bat star | S12: =SUM(T12:AV12) -> 3 | T12: 0 | V12: 3
A13: =MAX($A$1:$A12)+1 -> 11 | B13: =IF(ISERROR(B12),IF(ISERROR(B11),IF(ISERROR(B10),"BLANK",B10),B11),B12) -> Jasmin Schuster | C13: =IF(ISERROR(C12),IF(ISERROR(C11),IF(ISERROR(C10),"BLANK",C10),C11),C12) -> Tom Bird | D13: =IF(ISERROR(D12),IF(ISERROR(D11),IF(ISERROR(D10),"BLANK",D10),D11),D12) -> BMSC6 | E13: =IF(ISERROR(VLOOKUP($D13,SITES!$A:$E,2,FALSE)),"",VLOOKUP($D13,SITES!$A:$E,2,FALSE)) -> Baeria Rocks South Island | F13: =IF(ISERROR(VLOOKUP($D13,SITES!$A:$E,3,FALSE)),"",VLOOKUP($D13,SITES!$A:$E,3,FALSE)) -> 48.950233 | G13: =IF(ISERROR(VLOOKUP($D13,SITES!$A:$E,4,FALSE)),"",VLOOKUP($D13,SITES!$A:$E,4,FALSE)) -> -125.15555 | H13: =IF(ISERROR(H12),IF(ISERROR(H11),IF(ISERROR(H10),"BLANK",H10),H11),H12) -> 45404 | I13: =IF(ISERROR(I12),IF(ISERROR(I11),IF(ISERROR(I10),"BLANK",I10),I11),I12) -> 1.5 | J13: =IF(ISERROR(J12),IF(ISERROR(J11),IF(ISERROR(J10),"BLANK",J10),J11),J12) -> SW | K13: =IF(ISERROR(K12),IF(ISERROR(K11),IF(ISERROR(K10),"BLANK",K10),K11),K12) -> 0.52986111 | L13: =IF(ISERROR(L12),IF(ISERROR(L11),IF(ISERROR(L10),"BLANK",L10),L11),L12) -> 8 | M13: =IF(ISERROR(M12),IF(ISERROR(M11),IF(ISERROR(M10),"BLANK",M10),M11),M12) -> 2 | N13: =IF(ISERROR(N12),IF(ISERROR(N11),IF(ISERROR(N10),"BLANK",N10),N11),N12) -> 1 | O13: 48 | P13: Mfra | Q13: =IF($M13=1,IF(ISERROR(VLOOKUP($P13,'M1'!$A:$C,Q$2,FALSE)),"NOT PRESENT",VLOOKUP($P13,'M1'!$A:$C,Q$2,FALSE)),IF($M13=2,IF(ISERROR(VLOOKUP(DATA!$P13,'M2'!$A:$C,Q$2,FALSE)),"NOT PRESENT",VLOOKUP(DATA!$P13,'M2'!$A:$C,Q$2,FALSE)),IF($M13=0,IF(ISERROR(VLOOKUP($P13,'M1'!$A:$C,Q$2,FALSE)),IF(ISERROR(VLOOKUP(DATA!$P13,'M2'!$A:$C,Q$2,FALSE)),"NOT PRESENT",VLOOKUP(DATA!$P13,'M2'!$A:$C,Q$2,FALSE)),VLOOKUP($P13,'M1'!$A:$C,Q$2,FALSE)),"SPECIFY METHOD"))) -> Mesocentrotus franciscanus | R13: =IF($M13=1,IF(ISERROR(VLOOKUP($P13,'M1'!$A:$C,R$2,FALSE)),"NOT PRESENT",VLOOKUP($P13,'M1'!$A:$C,R$2,FALSE)),IF($M13=2,IF(ISERROR(VLOOKUP(DATA!$P13,'M2'!$A:$C,R$2,FALSE)),"NOT PRESENT",VLOOKUP(DATA!$P13,'M2'!$A:$C,R$2,FALSE)),IF($M13=0,IF(ISERROR(VLOOKUP($P13,'M1'!$A:$C,R$2,FALSE)),IF(ISERROR(VLOOKUP(DATA!$P13,'M2'!$A:$C,R$2,FALSE)),"NOT PRESENT",VLOOKUP(DATA!$P13,'M2'!$A:$C,R$2,FALSE)),VLOOKUP($P13,'M1'!$A:$C,R$2,FALSE)),"SPECIFY METHOD"))) -> Red sea urchin | S13: =SUM(T13:AV13) -> 5 | T13: 0 | U13: 3 | V13: 1 | W13: 1
A14: =MAX($A$1:$A13)+1 -> 12 | B14: =IF(ISERROR(B13),IF(ISERROR(B12),IF(ISERROR(B11),"BLANK",B11),B12),B13) -> Jasmin Schuster | C14: =IF(ISERROR(C13),IF(ISERROR(C12),IF(ISERROR(C11),"BLANK",C11),C12),C13) -> Tom Bird | D14: =IF(ISERROR(D13),IF(ISERROR(D12),IF(ISERROR(D11),"BLANK",D11),D12),D13) -> BMSC6 | E14: =IF(ISERROR(VLOOKUP($D14,SITES!$A:$E,2,FALSE)),"",VLOOKUP($D14,SITES!$A:$E,2,FALSE)) -> Baeria Rocks South Island | F14: =IF(ISERROR(VLOOKUP($D14,SITES!$A:$E,3,FALSE)),"",VLOOKUP($D14,SITES!$A:$E,3,FALSE)) -> 48.950233 | G14: =IF(ISERROR(VLOOKUP($D14,SITES!$A:$E,4,FALSE)),"",VLOOKUP($D14,SITES!$A:$E,4,FALSE)) -> -125.15555 | H14: =IF(ISERROR(H13),IF(ISERROR(H12),IF(ISERROR(H11),"BLANK",H11),H12),H13) -> 45404 | I14: =IF(ISERROR(I13),IF(ISERROR(I12),IF(ISERROR(I11),"BLANK",I11),I12),I13) -> 1.5 | J14: =IF(ISERROR(J13),IF(ISERROR(J12),IF(ISERROR(J11),"BLANK",J11),J12),J13) -> SW | K14: =IF(ISERROR(K13),IF(ISERROR(K12),IF(ISERROR(K11),"BLANK",K11),K12),K13) -> 0.52986111 | L14: =IF(ISERROR(L13),IF(ISERROR(L12),IF(ISERROR(L11),"BLANK",L11),L12),L13) -> 8 | M14: =IF(ISERROR(M13),IF(ISERROR(M12),IF(ISERROR(M11),"BLANK",M11),M12),M13) -> 2 | N14: =IF(ISERROR(N13),IF(ISERROR(N12),IF(ISERROR(N11),"BLANK",N11),N12),N13) -> 1 | O14: 32 | P14: =IF(ISERROR(P13),IF(ISERROR(P12),IF(ISERROR(P11),"BLANK",P11),P12),P13) -> Mfra | Q14: =IF($M14=1,IF(ISERROR(VLOOKUP($P14,'M1'!$A:$C,Q$2,FALSE)),"NOT PRESENT",VLOOKUP($P14,'M1'!$A:$C,Q$2,FALSE)),IF($M14=2,IF(ISERROR(VLOOKUP(DATA!$P14,'M2'!$A:$C,Q$2,FALSE)),"NOT PRESENT",VLOOKUP(DATA!$P14,'M2'!$A:$C,Q$2,FALSE)),IF($M14=0,IF(ISERROR(VLOOKUP($P14,'M1'!$A:$C,Q$2,FALSE)),IF(ISERROR(VLOOKUP(DATA!$P14,'M2'!$A:$C,Q$2,FALSE)),"NOT PRESENT",VLOOKUP(DATA!$P14,'M2'!$A:$C,Q$2,FALSE)),VLOOKUP($P14,'M1'!$A:$C,Q$2,FALSE)),"SPECIFY METHOD"))) -> Mesocentrotus franciscanus | R14: =IF($M14=1,IF(ISERROR(VLOOKUP($P14,'M1'!$A:$C,R$2,FALSE)),"NOT PRESENT",VLOOKUP($P14,'M1'!$A:$C,R$2,FALSE)),IF($M14=2,IF(ISERROR(VLOOKUP(DATA!$P14,'M2'!$A:$C,R$2,FALSE)),"NOT PRESENT",VLOOKUP(DATA!$P14,'M2'!$A:$C,R$2,FALSE)),IF($M14=0,IF(ISERROR(VLOOKUP($P14,'M1'!$A:$C,R$2,FALSE)),IF(ISERROR(VLOOKUP(DATA!$P14,'M2'!$A:$C,R$2,FALSE)),"NOT PRESENT",VLOOKUP(DATA!$P14,'M2'!$A:$C,R$2,FALSE)),VLOOKUP($P14,'M1'!$A:$C,R$2,FALSE)),"SPECIFY METHOD"))) -> Red sea urchin | S14: =SUM(T14:AV14) -> 8 | T14: 0 | U14: 5 | V14: 2 | W14: 1
A15: =MAX($A$1:$A14)+1 -> 13 | B15: =IF(ISERROR(B14),IF(ISERROR(B13),IF(ISERROR(B12),"BLANK",B12),B13),B14) -> Jasmin Schuster | C15: =IF(ISERROR(C14),IF(ISERROR(C13),IF(ISERROR(C12),"BLANK",C12),C13),C14) -> Tom Bird | D15: =IF(ISERROR(D14),IF(ISERROR(D13),IF(ISERROR(D12),"BLANK",D12),D13),D14) -> BMSC6 | E15: =IF(ISERROR(VLOOKUP($D15,SITES!$A:$E,2,FALSE)),"",VLOOKUP($D15,SITES!$A:$E,2,FALSE)) -> Baeria Rocks South Island | F15: =IF(ISERROR(VLOOKUP($D15,SITES!$A:$E,3,FALSE)),"",VLOOKUP($D15,SITES!$A:$E,3,FALSE)) -> 48.950233 | G15: =IF(ISERROR(VLOOKUP($D15,SITES!$A:$E,4,FALSE)),"",VLOOKUP($D15,SITES!$A:$E,4,FALSE)) -> -125.15555 | H15: =IF(ISERROR(H14),IF(ISERROR(H13),IF(ISERROR(H12),"BLANK",H12),H13),H14) -> 45404 | I15: =IF(ISERROR(I14),IF(ISERROR(I13),IF(ISERROR(I12),"BLANK",I12),I13),I14) -> 1.5 | J15: =IF(ISERROR(J14),IF(ISERROR(J13),IF(ISERROR(J12),"BLANK",J12),J13),J14) -> SW | K15: =IF(ISERROR(K14),IF(ISERROR(K13),IF(ISERROR(K12),"BLANK",K12),K13),K14) -> 0.52986111 | L15: =IF(ISERROR(L14),IF(ISERROR(L13),IF(ISERROR(L12),"BLANK",L12),L13),L14) -> 8 | M15: =IF(ISERROR(M14),IF(ISERROR(M13),IF(ISERROR(M12),"BLANK",M12),M13),M14) -> 2 | N15: =IF(ISERROR(N14),IF(ISERROR(N13),IF(ISERROR(N12),"BLANK",N12),N13),N14) -> 1 | O15: 32 | P15: Pmi | Q15: =IF($M15=1,IF(ISERROR(VLOOKUP($P15,'M1'!$A:$C,Q$2,FALSE)),"NOT PRESENT",VLOOKUP($P15,'M1'!$A:$C,Q$2,FALSE)),IF($M15=2,IF(ISERROR(VLOOKUP(DATA!$P15,'M2'!$A:$C,Q$2,FALSE)),"NOT PRESENT",VLOOKUP(DATA!$P15,'M2'!$A:$C,Q$2,FALSE)),IF($M15=0,IF(ISERROR(VLOOKUP($P15,'M1'!$A:$C,Q$2,FALSE)),IF(ISERROR(VLOOKUP(DATA!$P15,'M2'!$A:$C,Q$2,FALSE)),"NOT PRESENT",VLOOKUP(DATA!$P15,'M2'!$A:$C,Q$2,FALSE)),VLOOKUP($P15,'M1'!$A:$C,Q$2,FALSE)),"SPECIFY METHOD"))) -> Patiria miniata | R15: =IF($M15=1,IF(ISERROR(VLOOKUP($P15,'M1'!$A:$C,R$2,FALSE)),"NOT PRESENT",VLOOKUP($P15,'M1'!$A:$C,R$2,FALSE)),IF($M15=2,IF(ISERROR(VLOOKUP(DATA!$P15,'M2'!$A:$C,R$2,FALSE)),"NOT PRESENT",VLOOKUP(DATA!$P15,'M2'!$A:$C,R$2,FALSE)),IF($M15=0,IF(ISERROR(VLOOKUP($P15,'M1'!$A:$C,R$2,FALSE)),IF(ISERROR(VLOOKUP(DATA!$P15,'M2'!$A:$C,R$2,FALSE)),"NOT PRESENT",VLOOKUP(DATA!$P15,'M2'!$A:$C,R$2,FALSE)),VLOOKUP($P15,'M1'!$A:$C,R$2,FALSE)),"SPECIFY METHOD"))) -> Bat star | S15: =SUM(T15:AV15) -> 1 | T15: 0 | V15: 1
A16: =MAX($A$1:$A15)+1 -> 14 | B16: =IF(ISERROR(B15),IF(ISERROR(B14),IF(ISERROR(B13),"BLANK",B13),B14),B15) -> Jasmin Schuster | C16: =IF(ISERROR(C15),IF(ISERROR(C14),IF(ISERROR(C13),"BLANK",C13),C14),C15) -> Tom Bird | D16: =IF(ISERROR(D15),IF(ISERROR(D14),IF(ISERROR(D13),"BLANK",D13),D14),D15) -> BMSC6 | E16: =IF(ISERROR(VLOOKUP($D16,SITES!$A:$E,2,FALSE)),"",VLOOKUP($D16,SITES!$A:$E,2,FALSE)) -> Baeria Rocks South Island | F16: =IF(ISERROR(VLOOKUP($D16,SITES!$A:$E,3,FALSE)),"",VLOOKUP($D16,SITES!$A:$E,3,FALSE)) -> 48.950233 | G16: =IF(ISERROR(VLOOKUP($D16,SITES!$A:$E,4,FALSE)),"",VLOOKUP($D16,SITES!$A:$E,4,FALSE)) -> -125.15555 | H16: =IF(ISERROR(H15),IF(ISERROR(H14),IF(ISERROR(H13),"BLANK",H13),H14),H15) -> 45404 | I16: =IF(ISERROR(I15),IF(ISERROR(I14),IF(ISERROR(I13),"BLANK",I13),I14),I15) -> 1.5 | J16: =IF(ISERROR(J15),IF(ISERROR(J14),IF(ISERROR(J13),"BLANK",J13),J14),J15) -> SW | K16: =IF(ISERROR(K15),IF(ISERROR(K14),IF(ISERROR(K13),"BLANK",K13),K14),K15) -> 0.52986111 | L16: =IF(ISERROR(L15),IF(ISERROR(L14),IF(ISERROR(L13),"BLANK",L13),L14),L15) -> 8 | M16: =IF(ISERROR(M15),IF(ISERROR(M14),IF(ISERROR(M13),"BLANK",M13),M14),M15) -> 2 | N16: =IF(ISERROR(N15),IF(ISERROR(N14),IF(ISERROR(N13),"BLANK",N13),N14),N15) -> 1 | O16: 16 | P16: =IF(ISERROR(P15),IF(ISERROR(P14),IF(ISERROR(P13),"BLANK",P13),P14),P15) -> Pmi | Q16: =IF($M16=1,IF(ISERROR(VLOOKUP($P16,'M1'!$A:$C,Q$2,FALSE)),"NOT PRESENT",VLOOKUP($P16,'M1'!$A:$C,Q$2,FALSE)),IF($M16=2,IF(ISERROR(VLOOKUP(DATA!$P16,'M2'!$A:$C,Q$2,FALSE)),"NOT PRESENT",VLOOKUP(DATA!$P16,'M2'!$A:$C,Q$2,FALSE)),IF($M16=0,IF(ISERROR(VLOOKUP($P16,'M1'!$A:$C,Q$2,FALSE)),IF(ISERROR(VLOOKUP(DATA!$P16,'M2'!$A:$C,Q$2,FALSE)),"NOT PRESENT",VLOOKUP(DATA!$P16,'M2'!$A:$C,Q$2,FALSE)),VLOOKUP($P16,'M1'!$A:$C,Q$2,FALSE)),"SPECIFY METHOD"))) -> Patiria miniata | R16: =IF($M16=1,IF(ISERROR(VLOOKUP($P16,'M1'!$A:$C,R$2,FALSE)),"NOT PRESENT",VLOOKUP($P16,'M1'!$A:$C,R$2,FALSE)),IF($M16=2,IF(ISERROR(VLOOKUP(DATA!$P16,'M2'!$A:$C,R$2,FALSE)),"NOT PRESENT",VLOOKUP(DATA!$P16,'M2'!$A:$C,R$2,FALSE)),IF($M16=0,IF(ISERROR(VLOOKUP($P16,'M1'!$A:$C,R$2,FALSE)),IF(ISERROR(VLOOKUP(DATA!$P16,'M2'!$A:$C,R$2,FALSE)),"NOT PRESENT",VLOOKUP(DATA!$P16,'M2'!$A:$C,R$2,FALSE)),VLOOKUP($P16,'M1'!$A:$C,R$2,FALSE)),"SPECIFY METHOD"))) -> Bat star | S16: =SUM(T16:AV16) -> 2 | T16: 0 | V16: 2
A17: =MAX($A$1:$A16)+1 -> 15 | B17: =IF(ISERROR(B16),IF(ISERROR(B15),IF(ISERROR(B14),"BLANK",B14),B15),B16) -> Jasmin Schuster | C17: =IF(ISERROR(C16),IF(ISERROR(C15),IF(ISERROR(C14),"BLANK",C14),C15),C16) -> Tom Bird | D17: =IF(ISERROR(D16),IF(ISERROR(D15),IF(ISERROR(D14),"BLANK",D14),D15),D16) -> BMSC6 | E17: =IF(ISERROR(VLOOKUP($D17,SITES!$A:$E,2,FALSE)),"",VLOOKUP($D17,SITES!$A:$E,2,FALSE)) -> Baeria Rocks South Island | F17: =IF(ISERROR(VLOOKUP($D17,SITES!$A:$E,3,FALSE)),"",VLOOKUP($D17,SITES!$A:$E,3,FALSE)) -> 48.950233 | G17: =IF(ISERROR(VLOOKUP($D17,SITES!$A:$E,4,FALSE)),"",VLOOKUP($D17,SITES!$A:$E,4,FALSE)) -> -125.15555 | H17: =IF(ISERROR(H16),IF(ISERROR(H15),IF(ISERROR(H14),"BLANK",H14),H15),H16) -> 45404 | I17: =IF(ISERROR(I16),IF(ISERROR(I15),IF(ISERROR(I14),"BLANK",I14),I15),I16) -> 1.5 | J17: =IF(ISERROR(J16),IF(ISERROR(J15),IF(ISERROR(J14),"BLANK",J14),J15),J16) -> SW | K17: =IF(ISERROR(K16),IF(ISERROR(K15),IF(ISERROR(K14),"BLANK",K14),K15),K16) -> 0.52986111 | L17: =IF(ISERROR(L16),IF(ISERROR(L15),IF(ISERROR(L14),"BLANK",L14),L15),L16) -> 8 | M17: =IF(ISERROR(M16),IF(ISERROR(M15),IF(ISERROR(M14),"BLANK",M14),M15),M16) -> 2 | N17: =IF(ISERROR(N16),IF(ISERROR(N15),IF(ISERROR(N14),"BLANK",N14),N15),N16) -> 1 | O17: 16 | P17: Mfra | Q17: =IF($M17=1,IF(ISERROR(VLOOKUP($P17,'M1'!$A:$C,Q$2,FALSE)),"NOT PRESENT",VLOOKUP($P17,'M1'!$A:$C,Q$2,FALSE)),IF($M17=2,IF(ISERROR(VLOOKUP(DATA!$P17,'M2'!$A:$C,Q$2,FALSE)),"NOT PRESENT",VLOOKUP(DATA!$P17,'M2'!$A:$C,Q$2,FALSE)),IF($M17=0,IF(ISERROR(VLOOKUP($P17,'M1'!$A:$C,Q$2,FALSE)),IF(ISERROR(VLOOKUP(DATA!$P17,'M2'!$A:$C,Q$2,FALSE)),"NOT PRESENT",VLOOKUP(DATA!$P17,'M2'!$A:$C,Q$2,FALSE)),VLOOKUP($P17,'M1'!$A:$C,Q$2,FALSE)),"SPECIFY METHOD"))) -> Mesocentrotus franciscanus | R17: =IF($M17=1,IF(ISERROR(VLOOKUP($P17,'M1'!$A:$C,R$2,FALSE)),"NOT PRESENT",VLOOKUP($P17,'M1'!$A:$C,R$2,FALSE)),IF($M17=2,IF(ISERROR(VLOOKUP(DATA!$P17,'M2'!$A:$C,R$2,FALSE)),"NOT PRESENT",VLOOKUP(DATA!$P17,'M2'!$A:$C,R$2,FALSE)),IF($M17=0,IF(ISERROR(VLOOKUP($P17,'M1'!$A:$C,R$2,FALSE)),IF(ISERROR(VLOOKUP(DATA!$P17,'M2'!$A:$C,R$2,FALSE)),"NOT PRESENT",VLOOKUP(DATA!$P17,'M2'!$A:$C,R$2,FALSE)),VLOOKUP($P17,'M1'!$A:$C,R$2,FALSE)),"SPECIFY METHOD"))) -> Red sea urchin | S17: =SUM(T17:AV17) -> 6 | U17: 4 | V17: 2
A18: =MAX($A$1:$A17)+1 -> 16 | B18: =IF(ISERROR(#REF!),IF(ISERROR(B17),IF(ISERROR(B16),"BLANK",B16),B17),#REF!) -> Jasmin Schuster | C18: =IF(ISERROR(#REF!),IF(ISERROR(C17),IF(ISERROR(C16),"BLANK",C16),C17),#REF!) -> Tom Bird | D18: =IF(ISERROR(#REF!),IF(ISERROR(D17),IF(ISERROR(D16),"BLANK",D16),D17),#REF!) -> BMSC6 | E18: =IF(ISERROR(VLOOKUP($D18,SITES!$A:$E,2,FALSE)),"",VLOOKUP($D18,SITES!$A:$E,2,FALSE)) -> Baeria Rocks South Island | F18: =IF(ISERROR(VLOOKUP($D18,SITES!$A:$E,3,FALSE)),"",VLOOKUP($D18,SITES!$A:$E,3,FALSE)) -> 48.950233 | G18: =IF(ISERROR(VLOOKUP($D18,SITES!$A:$E,4,FALSE)),"",VLOOKUP($D18,SITES!$A:$E,4,FALSE)) -> -125.15555 | H18: =IF(ISERROR(#REF!),IF(ISERROR(H17),IF(ISERROR(H16),"BLANK",H16),H17),#REF!) -> 45404 | I18: =IF(ISERROR(#REF!),IF(ISERROR(I17),IF(ISERROR(I16),"BLANK",I16),I17),#REF!) -> 1.5 | J18: =IF(ISERROR(#REF!),IF(ISERROR(J17),IF(ISERROR(J16),"BLANK",J16),J17),#REF!) -> SW | K18: =IF(ISERROR(#REF!),IF(ISERROR(K17),IF(ISERROR(K16),"BLANK",K16),K17),#REF!) -> 0.52986111 | L18: =IF(ISERROR(#REF!),IF(ISERROR(L17),IF(ISERROR(L16),"BLANK",L16),L17),#REF!) -> 8 | M18: =IF(ISERROR(#REF!),IF(ISERROR(M17),IF(ISERROR(M16),"BLANK",M16),M17),#REF!) -> 2 | N18: =IF(ISERROR(#REF!),IF(ISERROR(N17),IF(ISERROR(N16),"BLANK",N16),N17),#REF!) -> 1 | O18: 16 | P18: Oko | Q18: =IF($M18=1,IF(ISERROR(VLOOKUP($P18,'M1'!$A:$C,Q$2,FALSE)),"NOT PRESENT",VLOOKUP($P18,'M1'!$A:$C,Q$2,FALSE)),IF($M18=2,IF(ISERROR(VLOOKUP(DATA!$P18,'M2'!$A:$C,Q$2,FALSE)),"NOT PRESENT",VLOOKUP(DATA!$P18,'M2'!$A:$C,Q$2,FALSE)),IF($M18=0,IF(ISERROR(VLOOKUP($P18,'M1'!$A:$C,Q$2,FALSE)),IF(ISERROR(VLOOKUP(DATA!$P18,'M2'!$A:$C,Q$2,FALSE)),"NOT PRESENT",VLOOKUP(DATA!$P18,'M2'!$A:$C,Q$2,FALSE)),VLOOKUP($P18,'M1'!$A:$C,Q$2,FALSE)),"SPECIFY METHOD"))) -> Orthasterias koehleri | R18: =IF($M18=1,IF(ISERROR(VLOOKUP($P18,'M1'!$A:$C,R$2,FALSE)),"NOT PRESENT",VLOOKUP($P18,'M1'!$A:$C,R$2,FALSE)),IF($M18=2,IF(ISERROR(VLOOKUP(DATA!$P18,'M2'!$A:$C,R$2,FALSE)),"NOT PRESENT",VLOOKUP(DATA!$P18,'M2'!$A:$C,R$2,FALSE)),IF($M18=0,IF(ISERROR(VLOOKUP($P18,'M1'!$A:$C,R$2,FALSE)),IF(ISERROR(VLOOKUP(DATA!$P18,'M2'!$A:$C,R$2,FALSE)),"NOT PRESENT",VLOOKUP(DATA!$P18,'M2'!$A:$C,R$2,FALSE)),VLOOKUP($P18,'M1'!$A:$C,R$2,FALSE)),"SPECIFY METHOD"))) -> Rainbow star | S18: =SUM(T18:AV18) -> 1 | T18: 0 | V18: 1
A19: =MAX($A$1:$A18)+1 -> 17 | B19: =IF(ISERROR(B18),IF(ISERROR(#REF!),IF(ISERROR(B17),"BLANK",B17),#REF!),B18) -> Jasmin Schuster | C19: =IF(ISERROR(C18),IF(ISERROR(#REF!),IF(ISERROR(C17),"BLANK",C17),#REF!),C18) -> Tom Bird | D19: =IF(ISERROR(D18),IF(ISERROR(#REF!),IF(ISERROR(D17),"BLANK",D17),#REF!),D18) -> BMSC6 | E19: =IF(ISERROR(VLOOKUP($D19,SITES!$A:$E,2,FALSE)),"",VLOOKUP($D19,SITES!$A:$E,2,FALSE)) -> Baeria Rocks South Island | F19: =IF(ISERROR(VLOOKUP($D19,SITES!$A:$E,3,FALSE)),"",VLOOKUP($D19,SITES!$A:$E,3,FALSE)) -> 48.950233 | G19: =IF(ISERROR(VLOOKUP($D19,SITES!$A:$E,4,FALSE)),"",VLOOKUP($D19,SITES!$A:$E,4,FALSE)) -> -125.15555 | H19: =IF(ISERROR(H18),IF(ISERROR(#REF!),IF(ISERROR(H17),"BLANK",H17),#REF!),H18) -> 45404 | I19: =IF(ISERROR(I18),IF(ISERROR(#REF!),IF(ISERROR(I17),"BLANK",I17),#REF!),I18) -> 1.5 | J19: =IF(ISERROR(J18),IF(ISERROR(#REF!),IF(ISERROR(J17),"BLANK",J17),#REF!),J18) -> SW | K19: =IF(ISERROR(K18),IF(ISERROR(#REF!),IF(ISERROR(K17),"BLANK",K17),#REF!),K18) -> 0.52986111 | L19: =IF(ISERROR(L18),IF(ISERROR(#REF!),IF(ISERROR(L17),"BLANK",L17),#REF!),L18) -> 8 | M19: =IF(ISERROR(M18),IF(ISERROR(#REF!),IF(ISERROR(M17),"BLANK",M17),#REF!),M18) -> 2 | N19: =IF(ISERROR(N18),IF(ISERROR(#REF!),IF(ISERROR(N17),"BLANK",N17),#REF!),N18) -> 1 | O19: 0 | P19: Mfra | Q19: =IF($M19=1,IF(ISERROR(VLOOKUP($P19,'M1'!$A:$C,Q$2,FALSE)),"NOT PRESENT",VLOOKUP($P19,'M1'!$A:$C,Q$2,FALSE)),IF($M19=2,IF(ISERROR(VLOOKUP(DATA!$P19,'M2'!$A:$C,Q$2,FALSE)),"NOT PRESENT",VLOOKUP(DATA!$P19,'M2'!$A:$C,Q$2,FALSE)),IF($M19=0,IF(ISERROR(VLOOKUP($P19,'M1'!$A:$C,Q$2,FALSE)),IF(ISERROR(VLOOKUP(DATA!$P19,'M2'!$A:$C,Q$2,FALSE)),"NOT PRESENT",VLOOKUP(DATA!$P19,'M2'!$A:$C,Q$2,FALSE)),VLOOKUP($P19,'M1'!$A:$C,Q$2,FALSE)),"SPECIFY METHOD"))) -> Mesocentrotus franciscanus | R19: =IF($M19=1,IF(ISERROR(VLOOKUP($P19,'M1'!$A:$C,R$2,FALSE)),"NOT PRESENT",VLOOKUP($P19,'M1'!$A:$C,R$2,FALSE)),IF($M19=2,IF(ISERROR(VLOOKUP(DATA!$P19,'M2'!$A:$C,R$2,FALSE)),"NOT PRESENT",VLOOKUP(DATA!$P19,'M2'!$A:$C,R$2,FALSE)),IF($M19=0,IF(ISERROR(VLOOKUP($P19,'M1'!$A:$C,R$2,FALSE)),IF(ISERROR(VLOOKUP(DATA!$P19,'M2'!$A:$C,R$2,FALSE)),"NOT PRESENT",VLOOKUP(DATA!$P19,'M2'!$A:$C,R$2,FALSE)),VLOOKUP($P19,'M1'!$A:$C,R$2,FALSE)),"SPECIFY METHOD"))) -> Red sea urchin | S19: =SUM(T19:AV19) -> 10 | T19: 0 | U19: 2 | V19: 8
A20: =MAX($A$1:$A19)+1 -> 18 | B20: =IF(ISERROR(B19),IF(ISERROR(B18),IF(ISERROR(#REF!),"BLANK",#REF!),B18),B19) -> Jasmin Schuster | C20: =IF(ISERROR(C19),IF(ISERROR(C18),IF(ISERROR(#REF!),"BLANK",#REF!),C18),C19) -> Tom Bird | D20: =IF(ISERROR(D19),IF(ISERROR(D18),IF(ISERROR(#REF!),"BLANK",#REF!),D18),D19) -> BMSC6 | E20: =IF(ISERROR(VLOOKUP($D20,SITES!$A:$E,2,FALSE)),"",VLOOKUP($D20,SITES!$A:$E,2,FALSE)) -> Baeria Rocks South Island | F20: =IF(ISERROR(VLOOKUP($D20,SITES!$A:$E,3,FALSE)),"",VLOOKUP($D20,SITES!$A:$E,3,FALSE)) -> 48.950233 | G20: =IF(ISERROR(VLOOKUP($D20,SITES!$A:$E,4,FALSE)),"",VLOOKUP($D20,SITES!$A:$E,4,FALSE)) -> -125.15555 | H20: =IF(ISERROR(H19),IF(ISERROR(H18),IF(ISERROR(#REF!),"BLANK",#REF!),H18),H19) -> 45404 | I20: =IF(ISERROR(I19),IF(ISERROR(I18),IF(ISERROR(#REF!),"BLANK",#REF!),I18),I19) -> 1.5 | J20: =IF(ISERROR(J19),IF(ISERROR(J18),IF(ISERROR(#REF!),"BLANK",#REF!),J18),J19) -> SW | K20: =IF(ISERROR(K19),IF(ISERROR(K18),IF(ISERROR(#REF!),"BLANK",#REF!),K18),K19) -> 0.52986111 | L20: =IF(ISERROR(L19),IF(ISERROR(L18),IF(ISERROR(#REF!),"BLANK",#REF!),L18),L19) -> 8 | M20: =IF(ISERROR(M19),IF(ISERROR(M18),IF(ISERROR(#REF!),"BLANK",#REF!),M18),M19) -> 2 | N20: =IF(ISERROR(N19),IF(ISERROR(N18),IF(ISERROR(#REF!),"BLANK",#REF!),N18),N19) -> 1 | O20: 0 | P20: Pmi | Q20: =IF($M20=1,IF(ISERROR(VLOOKUP($P20,'M1'!$A:$C,Q$2,FALSE)),"NOT PRESENT",VLOOKUP($P20,'M1'!$A:$C,Q$2,FALSE)),IF($M20=2,IF(ISERROR(VLOOKUP(DATA!$P20,'M2'!$A:$C,Q$2,FALSE)),"NOT PRESENT",VLOOKUP(DATA!$P20,'M2'!$A:$C,Q$2,FALSE)),IF($M20=0,IF(ISERROR(VLOOKUP($P20,'M1'!$A:$C,Q$2,FALSE)),IF(ISERROR(VLOOKUP(DATA!$P20,'M2'!$A:$C,Q$2,FALSE)),"NOT PRESENT",VLOOKUP(DATA!$P20,'M2'!$A:$C,Q$2,FALSE)),VLOOKUP($P20,'M1'!$A:$C,Q$2,FALSE)),"SPECIFY METHOD"))) -> Patiria miniata | R20: =IF($M20=1,IF(ISERROR(VLOOKUP($P20,'M1'!$A:$C,R$2,FALSE)),"NOT PRESENT",VLOOKUP($P20,'M1'!$A:$C,R$2,FALSE)),IF($M20=2,IF(ISERROR(VLOOKUP(DATA!$P20,'M2'!$A:$C,R$2,FALSE)),"NOT PRESENT",VLOOKUP(DATA!$P20,'M2'!$A:$C,R$2,FALSE)),IF($M20=0,IF(ISERROR(VLOOKUP($P20,'M1'!$A:$C,R$2,FALSE)),IF(ISERROR(VLOOKUP(DATA!$P20,'M2'!$A:$C,R$2,FALSE)),"NOT PRESENT",VLOOKUP(DATA!$P20,'M2'!$A:$C,R$2,FALSE)),VLOOKUP($P20,'M1'!$A:$C,R$2,FALSE)),"SPECIFY METHOD"))) -> Bat star | S20: =SUM(T20:AV20) -> 1 | T20: 0 | X20: 1
A21: =MAX($A$1:$A20)+1 -> 19 | B21: Em Lim | C21: Isabelle Cote | D21: BMSC8 | E21: =IF(ISERROR(VLOOKUP($D21,SITES!$A:$E,2,FALSE)),"",VLOOKUP($D21,SITES!$A:$E,2,FALSE)) -> Baeria Rocks North Island Northside | F21: =IF(ISERROR(VLOOKUP($D21,SITES!$A:$E,3,FALSE)),"",VLOOKUP($D21,SITES!$A:$E,3,FALSE)) -> 48.955082 | G21: =IF(ISERROR(VLOOKUP($D21,SITES!$A:$E,4,FALSE)),"",VLOOKUP($D21,SITES!$A:$E,4,FALSE)) -> -125.15337 | H21: 45404 | I21: 1.5 | J21: SE | K21: 0.425 | L21: 8.5 | M21: 2 | N21: 2 | O21: 40 | P21: poc | Q21: =IF($M21=1,IF(ISERROR(VLOOKUP($P21,'M1'!$A:$C,Q$2,FALSE)),"NOT PRESENT",VLOOKUP($P21,'M1'!$A:$C,Q$2,FALSE)),IF($M21=2,IF(ISERROR(VLOOKUP(DATA!$P21,'M2'!$A:$C,Q$2,FALSE)),"NOT PRESENT",VLOOKUP(DATA!$P21,'M2'!$A:$C,Q$2,FALSE)),IF($M21=0,IF(ISERROR(VLOOKUP($P21,'M1'!$A:$C,Q$2,FALSE)),IF(ISERROR(VLOOKUP(DATA!$P21,'M2'!$A:$C,Q$2,FALSE)),"NOT PRESENT",VLOOKUP(DATA!$P21,'M2'!$A:$C,Q$2,FALSE)),VLOOKUP($P21,'M1'!$A:$C,Q$2,FALSE)),"SPECIFY METHOD"))) -> Pisaster ochraceus | R21: =IF($M21=1,IF(ISERROR(VLOOKUP($P21,'M1'!$A:$C,R$2,FALSE)),"NOT PRESENT",VLOOKUP($P21,'M1'!$A:$C,R$2,FALSE)),IF($M21=2,IF(ISERROR(VLOOKUP(DATA!$P21,'M2'!$A:$C,R$2,FALSE)),"NOT PRESENT",VLOOKUP(DATA!$P21,'M2'!$A:$C,R$2,FALSE)),IF($M21=0,IF(ISERROR(VLOOKUP($P21,'M1'!$A:$C,R$2,FALSE)),IF(ISERROR(VLOOKUP(DATA!$P21,'M2'!$A:$C,R$2,FALSE)),"NOT PRESENT",VLOOKUP(DATA!$P21,'M2'!$A:$C,R$2,FALSE)),VLOOKUP($P21,'M1'!$A:$C,R$2,FALSE)),"SPECIFY METHOD"))) -> Purple sea star | S21: =SUM(T21:AV21) -> 8 | T21: 0 | AA21: 4 | AD21: 3 | AE21: 1
A22: =MAX($A$1:$A21)+1 -> 20 | B22: =IF(ISERROR(B21),IF(ISERROR(#REF!),IF(ISERROR(B20),"BLANK",B20),#REF!),B21) -> Em Lim | C22: =IF(ISERROR(C21),IF(ISERROR(#REF!),IF(ISERROR(C20),"BLANK",C20),#REF!),C21) -> Isabelle Cote | D22: =IF(ISERROR(D21),IF(ISERROR(#REF!),IF(ISERROR(D20),"BLANK",D20),#REF!),D21) -> BMSC8 | E22: =IF(ISERROR(VLOOKUP($D22,SITES!$A:$E,2,FALSE)),"",VLOOKUP($D22,SITES!$A:$E,2,FALSE)) -> Baeria Rocks North Island Northside | F22: =IF(ISERROR(VLOOKUP($D22,SITES!$A:$E,3,FALSE)),"",VLOOKUP($D22,SITES!$A:$E,3,FALSE)) -> 48.955082 | G22: =IF(ISERROR(VLOOKUP($D22,SITES!$A:$E,4,FALSE)),"",VLOOKUP($D22,SITES!$A:$E,4,FALSE)) -> -125.15337 | H22: =IF(ISERROR(H21),IF(ISERROR(#REF!),IF(ISERROR(H20),"BLANK",H20),#REF!),H21) -> 45404 | I22: =IF(ISERROR(I21),IF(ISERROR(#REF!),IF(ISERROR(I20),"BLANK",I20),#REF!),I21) -> 1.5 | J22: =IF(ISERROR(J21),IF(ISERROR(#REF!),IF(ISERROR(J20),"BLANK",J20),#REF!),J21) -> SE | K22: =IF(ISERROR(K21),IF(ISERROR(#REF!),IF(ISERROR(K20),"BLANK",K20),#REF!),K21) -> 0.425 | L22: =IF(ISERROR(L21),IF(ISERROR(#REF!),IF(ISERROR(L20),"BLANK",L20),#REF!),L21) -> 8.5 | M22: =IF(ISERROR(M21),IF(ISERROR(#REF!),IF(ISERROR(M20),"BLANK",M20),#REF!),M21) -> 2 | N22: =IF(ISERROR(N21),IF(ISERROR(#REF!),IF(ISERROR(N20),"BLANK",N20),#REF!),N21) -> 2 | O22: 40 | P22: dim | Q22: =IF($M22=1,IF(ISERROR(VLOOKUP($P22,'M1'!$A:$C,Q$2,FALSE)),"NOT PRESENT",VLOOKUP($P22,'M1'!$A:$C,Q$2,FALSE)),IF($M22=2,IF(ISERROR(VLOOKUP(DATA!$P22,'M2'!$A:$C,Q$2,FALSE)),"NOT PRESENT",VLOOKUP(DATA!$P22,'M2'!$A:$C,Q$2,FALSE)),IF($M22=0,IF(ISERROR(VLOOKUP($P22,'M1'!$A:$C,Q$2,FALSE)),IF(ISERROR(VLOOKUP(DATA!$P22,'M2'!$A:$C,Q$2,FALSE)),"NOT PRESENT",VLOOKUP(DATA!$P22,'M2'!$A:$C,Q$2,FALSE)),VLOOKUP($P22,'M1'!$A:$C,Q$2,FALSE)),"SPECIFY METHOD"))) -> Dermasterias imbricata | R22: =IF($M22=1,IF(ISERROR(VLOOKUP($P22,'M1'!$A:$C,R$2,FALSE)),"NOT PRESENT",VLOOKUP($P22,'M1'!$A:$C,R$2,FALSE)),IF($M22=2,IF(ISERROR(VLOOKUP(DATA!$P22,'M2'!$A:$C,R$2,FALSE)),"NOT PRESENT",VLOOKUP(DATA!$P22,'M2'!$A:$C,R$2,FALSE)),IF($M22=0,IF(ISERROR(VLOOKUP($P22,'M1'!$A:$C,R$2,FALSE)),IF(ISERROR(VLOOKUP(DATA!$P22,'M2'!$A:$C,R$2,FALSE)),"NOT PRESENT",VLOOKUP(DATA!$P22,'M2'!$A:$C,R$2,FALSE)),VLOOKUP($P22,'M1'!$A:$C,R$2,FALSE)),"SPECIFY METHOD"))) -> Leather star | S22: =SUM(T22:AV22) -> 1 | T22: 0 | Z22: 1
A23: =MAX($A$1:$A22)+1 -> 21 | B23: =IF(ISERROR(B22),IF(ISERROR(B21),IF(ISERROR(#REF!),"BLANK",#REF!),B21),B22) -> Em Lim | C23: =IF(ISERROR(C22),IF(ISERROR(C21),IF(ISERROR(#REF!),"BLANK",#REF!),C21),C22) -> Isabelle Cote | D23: =IF(ISERROR(D22),IF(ISERROR(D21),IF(ISERROR(#REF!),"BLANK",#REF!),D21),D22) -> BMSC8 | E23: =IF(ISERROR(VLOOKUP($D23,SITES!$A:$E,2,FALSE)),"",VLOOKUP($D23,SITES!$A:$E,2,FALSE)) -> Baeria Rocks North Island Northside | F23: =IF(ISERROR(VLOOKUP($D23,SITES!$A:$E,3,FALSE)),"",VLOOKUP($D23,SITES!$A:$E,3,FALSE)) -> 48.955082 | G23: =IF(ISERROR(VLOOKUP($D23,SITES!$A:$E,4,FALSE)),"",VLOOKUP($D23,SITES!$A:$E,4,FALSE)) -> -125.15337 | H23: =IF(ISERROR(H22),IF(ISERROR(H21),IF(ISERROR(#REF!),"BLANK",#REF!),H21),H22) -> 45404 | I23: =IF(ISERROR(I22),IF(ISERROR(I21),IF(ISERROR(#REF!),"BLANK",#REF!),I21),I22) -> 1.5 | J23: =IF(ISERROR(J22),IF(ISERROR(J21),IF(ISERROR(#REF!),"BLANK",#REF!),J21),J22) -> SE | K23: =IF(ISERROR(K22),IF(ISERROR(K21),IF(ISERROR(#REF!),"BLANK",#REF!),K21),K22) -> 0.425 | L23: =IF(ISERROR(L22),IF(ISERROR(L21),IF(ISERROR(#REF!),"BLANK",#REF!),L21),L22) -> 8.5 | M23: =IF(ISERROR(M22),IF(ISERROR(M21),IF(ISERROR(#REF!),"BLANK",#REF!),M21),M22) -> 2 | N23: =IF(ISERROR(N22),IF(ISERROR(N21),IF(ISERROR(#REF!),"BLANK",#REF!),N21),N22) -> 2 | O23: 40 | P23: pmi | Q23: =IF($M23=1,IF(ISERROR(VLOOKUP($P23,'M1'!$A:$C,Q$2,FALSE)),"NOT PRESENT",VLOOKUP($P23,'M1'!$A:$C,Q$2,FALSE)),IF($M23=2,IF(ISERROR(VLOOKUP(DATA!$P23,'M2'!$A:$C,Q$2,FALSE)),"NOT PRESENT",VLOOKUP(DATA!$P23,'M2'!$A:$C,Q$2,FALSE)),IF($M23=0,IF(ISERROR(VLOOKUP($P23,'M1'!$A:$C,Q$2,FALSE)),IF(ISERROR(VLOOKUP(DATA!$P23,'M2'!$A:$C,Q$2,FALSE)),"NOT PRESENT",VLOOKUP(DATA!$P23,'M2'!$A:$C,Q$2,FALSE)),VLOOKUP($P23,'M1'!$A:$C,Q$2,FALSE)),"SPECIFY METHOD"))) -> Patiria miniata | R23: =IF($M23=1,IF(ISERROR(VLOOKUP($P23,'M1'!$A:$C,R$2,FALSE)),"NOT PRESENT",VLOOKUP($P23,'M1'!$A:$C,R$2,FALSE)),IF($M23=2,IF(ISERROR(VLOOKUP(DATA!$P23,'M2'!$A:$C,R$2,FALSE)),"NOT PRESENT",VLOOKUP(DATA!$P23,'M2'!$A:$C,R$2,FALSE)),IF($M23=0,IF(ISERROR(VLOOKUP($P23,'M1'!$A:$C,R$2,FALSE)),IF(ISERROR(VLOOKUP(DATA!$P23,'M2'!$A:$C,R$2,FALSE)),"NOT PRESENT",VLOOKUP(DATA!$P23,'M2'!$A:$C,R$2,FALSE)),VLOOKUP($P23,'M1'!$A:$C,R$2,FALSE)),"SPECIFY METHOD"))) -> Bat star | S23: =SUM(T23:AV23) -> 1 | T23: 0 | Z23: 1
A24: =MAX($A$1:$A23)+1 -> 22 | B24: =IF(ISERROR(B23),IF(ISERROR(B22),IF(ISERROR(B21),"BLANK",B21),B22),B23) -> Em Lim | C24: =IF(ISERROR(C23),IF(ISERROR(C22),IF(ISERROR(C21),"BLANK",C21),C22),C23) -> Isabelle Cote | D24: =IF(ISERROR(D23),IF(ISERROR(D22),IF(ISERROR(D21),"BLANK",D21),D22),D23) -> BMSC8 | E24: =IF(ISERROR(VLOOKUP($D24,SITES!$A:$E,2,FALSE)),"",VLOOKUP($D24,SITES!$A:$E,2,FALSE)) -> Baeria Rocks North Island Northside | F24: =IF(ISERROR(VLOOKUP($D24,SITES!$A:$E,3,FALSE)),"",VLOOKUP($D24,SITES!$A:$E,3,FALSE)) -> 48.955082 | G24: =IF(ISERROR(VLOOKUP($D24,SITES!$A:$E,4,FALSE)),"",VLOOKUP($D24,SITES!$A:$E,4,FALSE)) -> -125.15337 | H24: =IF(ISERROR(H23),IF(ISERROR(H22),IF(ISERROR(H21),"BLANK",H21),H22),H23) -> 45404 | I24: =IF(ISERROR(I23),IF(ISERROR(I22),IF(ISERROR(I21),"BLANK",I21),I22),I23) -> 1.5 | J24: =IF(ISERROR(J23),IF(ISERROR(J22),IF(ISERROR(J21),"BLANK",J21),J22),J23) -> SE | K24: =IF(ISERROR(K23),IF(ISERROR(K22),IF(ISERROR(K21),"BLANK",K21),K22),K23) -> 0.425 | L24: =IF(ISERROR(L23),IF(ISERROR(L22),IF(ISERROR(L21),"BLANK",L21),L22),L23) -> 8.5 | M24: =IF(ISERROR(M23),IF(ISERROR(M22),IF(ISERROR(M21),"BLANK",M21),M22),M23) -> 2 | N24: =IF(ISERROR(N23),IF(ISERROR(N22),IF(ISERROR(N21),"BLANK",N21),N22),N23) -> 2 | O24: 40 | P24: mfra | Q24: =IF($M24=1,IF(ISERROR(VLOOKUP($P24,'M1'!$A:$C,Q$2,FALSE)),"NOT PRESENT",VLOOKUP($P24,'M1'!$A:$C,Q$2,FALSE)),IF($M24=2,IF(ISERROR(VLOOKUP(DATA!$P24,'M2'!$A:$C,Q$2,FALSE)),"NOT PRESENT",VLOOKUP(DATA!$P24,'M2'!$A:$C,Q$2,FALSE)),IF($M24=0,IF(ISERROR(VLOOKUP($P24,'M1'!$A:$C,Q$2,FALSE)),IF(ISERROR(VLOOKUP(DATA!$P24,'M2'!$A:$C,Q$2,FALSE)),"NOT PRESENT",VLOOKUP(DATA!$P24,'M2'!$A:$C,Q$2,FALSE)),VLOOKUP($P24,'M1'!$A:$C,Q$2,FALSE)),"SPECIFY METHOD"))) -> Mesocentrotus franciscanus | R24: =IF($M24=1,IF(ISERROR(VLOOKUP($P24,'M1'!$A:$C,R$2,FALSE)),"NOT PRESENT",VLOOKUP($P24,'M1'!$A:$C,R$2,FALSE)),IF($M24=2,IF(ISERROR(VLOOKUP(DATA!$P24,'M2'!$A:$C,R$2,FALSE)),"NOT PRESENT",VLOOKUP(DATA!$P24,'M2'!$A:$C,R$2,FALSE)),IF($M24=0,IF(ISERROR(VLOOKUP($P24,'M1'!$A:$C,R$2,FALSE)),IF(ISERROR(VLOOKUP(DATA!$P24,'M2'!$A:$C,R$2,FALSE)),"NOT PRESENT",VLOOKUP(DATA!$P24,'M2'!$A:$C,R$2,FALSE)),VLOOKUP($P24,'M1'!$A:$C,R$2,FALSE)),"SPECIFY METHOD"))) -> Red sea urchin | S24: =SUM(T24:AV24) -> 4 | T24: 0 | U24: 2 | V24: 2
A25: =MAX($A$1:$A24)+1 -> 23 | B25: =IF(ISERROR(B24),IF(ISERROR(B23),IF(ISERROR(B22),"BLANK",B22),B23),B24) -> Em Lim | C25: =IF(ISERROR(C24),IF(ISERROR(C23),IF(ISERROR(C22),"BLANK",C22),C23),C24) -> Isabelle Cote | D25: =IF(ISERROR(D24),IF(ISERROR(D23),IF(ISERROR(D22),"BLANK",D22),D23),D24) -> BMSC8 | E25: =IF(ISERROR(VLOOKUP($D25,SITES!$A:$E,2,FALSE)),"",VLOOKUP($D25,SITES!$A:$E,2,FALSE)) -> Baeria Rocks North Island Northside | F25: =IF(ISERROR(VLOOKUP($D25,SITES!$A:$E,3,FALSE)),"",VLOOKUP($D25,SITES!$A:$E,3,FALSE)) -> 48.955082 | G25: =IF(ISERROR(VLOOKUP($D25,SITES!$A:$E,4,FALSE)),"",VLOOKUP($D25,SITES!$A:$E,4,FALSE)) -> -125.15337 | H25: =IF(ISERROR(H24),IF(ISERROR(H23),IF(ISERROR(H22),"BLANK",H22),H23),H24) -> 45404 | I25: =IF(ISERROR(I24),IF(ISERROR(I23),IF(ISERROR(I22),"BLANK",I22),I23),I24) -> 1.5 | J25: =IF(ISERROR(J24),IF(ISERROR(J23),IF(ISERROR(J22),"BLANK",J22),J23),J24) -> SE | K25: =IF(ISERROR(K24),IF(ISERROR(K23),IF(ISERROR(K22),"BLANK",K22),K23),K24) -> 0.425 | L25: =IF(ISERROR(L24),IF(ISERROR(L23),IF(ISERROR(L22),"BLANK",L22),L23),L24) -> 8.5 | M25: =IF(ISERROR(M24),IF(ISERROR(M23),IF(ISERROR(M22),"BLANK",M22),M23),M24) -> 2 | N25: =IF(ISERROR(N24),IF(ISERROR(N23),IF(ISERROR(N22),"BLANK",N22),N23),N24) -> 2 | O25: 24 | P25: mfra | Q25: =IF($M25=1,IF(ISERROR(VLOOKUP($P25,'M1'!$A:$C,Q$2,FALSE)),"NOT PRESENT",VLOOKUP($P25,'M1'!$A:$C,Q$2,FALSE)),IF($M25=2,IF(ISERROR(VLOOKUP(DATA!$P25,'M2'!$A:$C,Q$2,FALSE)),"NOT PRESENT",VLOOKUP(DATA!$P25,'M2'!$A:$C,Q$2,FALSE)),IF($M25=0,IF(ISERROR(VLOOKUP($P25,'M1'!$A:$C,Q$2,FALSE)),IF(ISERROR(VLOOKUP(DATA!$P25,'M2'!$A:$C,Q$2,FALSE)),"NOT PRESENT",VLOOKUP(DATA!$P25,'M2'!$A:$C,Q$2,FALSE)),VLOOKUP($P25,'M1'!$A:$C,Q$2,FALSE)),"SPECIFY METHOD"))) -> Mesocentrotus franciscanus | R25: =IF($M25=1,IF(ISERROR(VLOOKUP($P25,'M1'!$A:$C,R$2,FALSE)),"NOT PRESENT",VLOOKUP($P25,'M1'!$A:$C,R$2,FALSE)),IF($M25=2,IF(ISERROR(VLOOKUP(DATA!$P25,'M2'!$A:$C,R$2,FALSE)),"NOT PRESENT",VLOOKUP(DATA!$P25,'M2'!$A:$C,R$2,FALSE)),IF($M25=0,IF(ISERROR(VLOOKUP($P25,'M1'!$A:$C,R$2,FALSE)),IF(ISERROR(VLOOKUP(DATA!$P25,'M2'!$A:$C,R$2,FALSE)),"NOT PRESENT",VLOOKUP(DATA!$P25,'M2'!$A:$C,R$2,FALSE)),VLOOKUP($P25,'M1'!$A:$C,R$2,FALSE)),"SPECIFY METHOD"))) -> Red sea urchin | S25: =SUM(T25:AV25) -> 10 | T25: 0 | U25: 3 | V25: 5 | W25: 2
A26: =MAX($A$1:$A25)+1 -> 24 | B26: =IF(ISERROR(B25),IF(ISERROR(B24),IF(ISERROR(B23),"BLANK",B23),B24),B25) -> Em Lim | C26: =IF(ISERROR(C25),IF(ISERROR(C24),IF(ISERROR(C23),"BLANK",C23),C24),C25) -> Isabelle Cote | D26: =IF(ISERROR(D25),IF(ISERROR(D24),IF(ISERROR(D23),"BLANK",D23),D24),D25) -> BMSC8 | E26: =IF(ISERROR(VLOOKUP($D26,SITES!$A:$E,2,FALSE)),"",VLOOKUP($D26,SITES!$A:$E,2,FALSE)) -> Baeria Rocks North Island Northside | F26: =IF(ISERROR(VLOOKUP($D26,SITES!$A:$E,3,FALSE)),"",VLOOKUP($D26,SITES!$A:$E,3,FALSE)) -> 48.955082 | G26: =IF(ISERROR(VLOOKUP($D26,SITES!$A:$E,4,FALSE)),"",VLOOKUP($D26,SITES!$A:$E,4,FALSE)) -> -125.15337 | H26: =IF(ISERROR(H25),IF(ISERROR(H24),IF(ISERROR(H23),"BLANK",H23),H24),H25) -> 45404 | I26: =IF(ISERROR(I25),IF(ISERROR(I24),IF(ISERROR(I23),"BLANK",I23),I24),I25) -> 1.5 | J26: =IF(ISERROR(J25),IF(ISERROR(J24),IF(ISERROR(J23),"BLANK",J23),J24),J25) -> SE | K26: =IF(ISERROR(K25),IF(ISERROR(K24),IF(ISERROR(K23),"BLANK",K23),K24),K25) -> 0.425 | L26: =IF(ISERROR(L25),IF(ISERROR(L24),IF(ISERROR(L23),"BLANK",L23),L24),L25) -> 8.5 | M26: =IF(ISERROR(M25),IF(ISERROR(M24),IF(ISERROR(M23),"BLANK",M23),M24),M25) -> 2 | N26: =IF(ISERROR(N25),IF(ISERROR(N24),IF(ISERROR(N23),"BLANK",N23),N24),N25) -> 2 | O26: 24 | P26: poc | Q26: =IF($M26=1,IF(ISERROR(VLOOKUP($P26,'M1'!$A:$C,Q$2,FALSE)),"NOT PRESENT",VLOOKUP($P26,'M1'!$A:$C,Q$2,FALSE)),IF($M26=2,IF(ISERROR(VLOOKUP(DATA!$P26,'M2'!$A:$C,Q$2,FALSE)),"NOT PRESENT",VLOOKUP(DATA!$P26,'M2'!$A:$C,Q$2,FALSE)),IF($M26=0,IF(ISERROR(VLOOKUP($P26,'M1'!$A:$C,Q$2,FALSE)),IF(ISERROR(VLOOKUP(DATA!$P26,'M2'!$A:$C,Q$2,FALSE)),"NOT PRESENT",VLOOKUP(DATA!$P26,'M2'!$A:$C,Q$2,FALSE)),VLOOKUP($P26,'M1'!$A:$C,Q$2,FALSE)),"SPECIFY METHOD"))) -> Pisaster ochraceus | R26: =IF($M26=1,IF(ISERROR(VLOOKUP($P26,'M1'!$A:$C,R$2,FALSE)),"NOT PRESENT",VLOOKUP($P26,'M1'!$A:$C,R$2,FALSE)),IF($M26=2,IF(ISERROR(VLOOKUP(DATA!$P26,'M2'!$A:$C,R$2,FALSE)),"NOT PRESENT",VLOOKUP(DATA!$P26,'M2'!$A:$C,R$2,FALSE)),IF($M26=0,IF(ISERROR(VLOOKUP($P26,'M1'!$A:$C,R$2,FALSE)),IF(ISERROR(VLOOKUP(DATA!$P26,'M2'!$A:$C,R$2,FALSE)),"NOT PRESENT",VLOOKUP(DATA!$P26,'M2'!$A:$C,R$2,FALSE)),VLOOKUP($P26,'M1'!$A:$C,R$2,FALSE)),"SPECIFY METHOD"))) -> Purple sea star | S26: =SUM(T26:AV26) -> 2 | T26: 0 | AC26: 2
A27: =MAX($A$1:$A26)+1 -> 25 | B27: =IF(ISERROR(B26),IF(ISERROR(B25),IF(ISERROR(B24),"BLANK",B24),B25),B26) -> Em Lim | C27: =IF(ISERROR(C26),IF(ISERROR(C25),IF(ISERROR(C24),"BLANK",C24),C25),C26) -> Isabelle Cote | D27: =IF(ISERROR(D26),IF(ISERROR(D25),IF(ISERROR(D24),"BLANK",D24),D25),D26) -> BMSC8 | E27: =IF(ISERROR(VLOOKUP($D27,SITES!$A:$E,2,FALSE)),"",VLOOKUP($D27,SITES!$A:$E,2,FALSE)) -> Baeria Rocks North Island Northside | F27: =IF(ISERROR(VLOOKUP($D27,SITES!$A:$E,3,FALSE)),"",VLOOKUP($D27,SITES!$A:$E,3,FALSE)) -> 48.955082 | G27: =IF(ISERROR(VLOOKUP($D27,SITES!$A:$E,4,FALSE)),"",VLOOKUP($D27,SITES!$A:$E,4,FALSE)) -> -125.15337 | H27: =IF(ISERROR(H26),IF(ISERROR(H25),IF(ISERROR(H24),"BLANK",H24),H25),H26) -> 45404 | I27: =IF(ISERROR(I26),IF(ISERROR(I25),IF(ISERROR(I24),"BLANK",I24),I25),I26) -> 1.5 | J27: =IF(ISERROR(J26),IF(ISERROR(J25),IF(ISERROR(J24),"BLANK",J24),J25),J26) -> SE | K27: =IF(ISERROR(K26),IF(ISERROR(K25),IF(ISERROR(K24),"BLANK",K24),K25),K26) -> 0.425 | L27: =IF(ISERROR(L26),IF(ISERROR(L25),IF(ISERROR(L24),"BLANK",L24),L25),L26) -> 8.5 | M27: =IF(ISERROR(M26),IF(ISERROR(M25),IF(ISERROR(M24),"BLANK",M24),M25),M26) -> 2 | N27: =IF(ISERROR(N26),IF(ISERROR(N25),IF(ISERROR(N24),"BLANK",N24),N25),N26) -> 2 | O27: 8 | P27: mfra | Q27: =IF($M27=1,IF(ISERROR(VLOOKUP($P27,'M1'!$A:$C,Q$2,FALSE)),"NOT PRESENT",VLOOKUP($P27,'M1'!$A:$C,Q$2,FALSE)),IF($M27=2,IF(ISERROR(VLOOKUP(DATA!$P27,'M2'!$A:$C,Q$2,FALSE)),"NOT PRESENT",VLOOKUP(DATA!$P27,'M2'!$A:$C,Q$2,FALSE)),IF($M27=0,IF(ISERROR(VLOOKUP($P27,'M1'!$A:$C,Q$2,FALSE)),IF(ISERROR(VLOOKUP(DATA!$P27,'M2'!$A:$C,Q$2,FALSE)),"NOT PRESENT",VLOOKUP(DATA!$P27,'M2'!$A:$C,Q$2,FALSE)),VLOOKUP($P27,'M1'!$A:$C,Q$2,FALSE)),"SPECIFY METHOD"))) -> Mesocentrotus franciscanus | R27: =IF($M27=1,IF(ISERROR(VLOOKUP($P27,'M1'!$A:$C,R$2,FALSE)),"NOT PRESENT",VLOOKUP($P27,'M1'!$A:$C,R$2,FALSE)),IF($M27=2,IF(ISERROR(VLOOKUP(DATA!$P27,'M2'!$A:$C,R$2,FALSE)),"NOT PRESENT",VLOOKUP(DATA!$P27,'M2'!$A:$C,R$2,FALSE)),IF($M27=0,IF(ISERROR(VLOOKUP($P27,'M1'!$A:$C,R$2,FALSE)),IF(ISERROR(VLOOKUP(DATA!$P27,'M2'!$A:$C,R$2,FALSE)),"NOT PRESENT",VLOOKUP(DATA!$P27,'M2'!$A:$C,R$2,FALSE)),VLOOKUP($P27,'M1'!$A:$C,R$2,FALSE)),"SPECIFY METHOD"))) -> Red sea urchin | S27: =SUM(T27:AV27) -> 7 | T27: 0 | V27: 3 | W27: 4
A28: =MAX($A$1:$A27)+1 -> 26 | B28: =IF(ISERROR(B27),IF(ISERROR(B26),IF(ISERROR(B25),"BLANK",B25),B26),B27) -> Em Lim | C28: =IF(ISERROR(C27),IF(ISERROR(C26),IF(ISERROR(C25),"BLANK",C25),C26),C27) -> Isabelle Cote | D28: BMSC6 | E28: =IF(ISERROR(VLOOKUP($D28,SITES!$A:$E,2,FALSE)),"",VLOOKUP($D28,SITES!$A:$E,2,FALSE)) -> Baeria Rocks South Island | F28: =IF(ISERROR(VLOOKUP($D28,SITES!$A:$E,3,FALSE)),"",VLOOKUP($D28,SITES!$A:$E,3,FALSE)) -> 48.950233 | G28: =IF(ISERROR(VLOOKUP($D28,SITES!$A:$E,4,FALSE)),"",VLOOKUP($D28,SITES!$A:$E,4,FALSE)) -> -125.15555 | H28: =IF(ISERROR(H27),IF(ISERROR(H26),IF(ISERROR(H25),"BLANK",H25),H26),H27) -> 45404 | I28: =IF(ISERROR(I27),IF(ISERROR(I26),IF(ISERROR(I25),"BLANK",I25),I26),I27) -> 1.5 | J28: SW | K28: 0.53125 | L28: 11 | M28: =IF(ISERROR(M27),IF(ISERROR(M26),IF(ISERROR(M25),"BLANK",M25),M26),M27) -> 2 | N28: =IF(ISERROR(N27),IF(ISERROR(N26),IF(ISERROR(N25),"BLANK",N25),N26),N27) -> 2 | O28: 40 | P28: mfra | Q28: =IF($M28=1,IF(ISERROR(VLOOKUP($P28,'M1'!$A:$C,Q$2,FALSE)),"NOT PRESENT",VLOOKUP($P28,'M1'!$A:$C,Q$2,FALSE)),IF($M28=2,IF(ISERROR(VLOOKUP(DATA!$P28,'M2'!$A:$C,Q$2,FALSE)),"NOT PRESENT",VLOOKUP(DATA!$P28,'M2'!$A:$C,Q$2,FALSE)),IF($M28=0,IF(ISERROR(VLOOKUP($P28,'M1'!$A:$C,Q$2,FALSE)),IF(ISERROR(VLOOKUP(DATA!$P28,'M2'!$A:$C,Q$2,FALSE)),"NOT PRESENT",VLOOKUP(DATA!$P28,'M2'!$A:$C,Q$2,FALSE)),VLOOKUP($P28,'M1'!$A:$C,Q$2,FALSE)),"SPECIFY METHOD"))) -> Mesocentrotus franciscanus | R28: =IF($M28=1,IF(ISERROR(VLOOKUP($P28,'M1'!$A:$C,R$2,FALSE)),"NOT PRESENT",VLOOKUP($P28,'M1'!$A:$C,R$2,FALSE)),IF($M28=2,IF(ISERROR(VLOOKUP(DATA!$P28,'M2'!$A:$C,R$2,FALSE)),"NOT PRESENT",VLOOKUP(DATA!$P28,'M2'!$A:$C,R$2,FALSE)),IF($M28=0,IF(ISERROR(VLOOKUP($P28,'M1'!$A:$C,R$2,FALSE)),IF(ISERROR(VLOOKUP(DATA!$P28,'M2'!$A:$C,R$2,FALSE)),"NOT PRESENT",VLOOKUP(DATA!$P28,'M2'!$A:$C,R$2,FALSE)),VLOOKUP($P28,'M1'!$A:$C,R$2,FALSE)),"SPECIFY METHOD"))) -> Red sea urchin | S28: =SUM(T28:AV28) -> 5 | T28: 0 | U28: 3 | V28: 1 | W28: 1
