Workbook
Name SpeciesList1: #REF!
Name SpeciesList2: #REF!

Sheet SUMMARY
A3: Sum of Total | C3: Date | D3: Site No. | E3: Depth
C4: 01/05/2024 | F4: 02/05/2024 | I4: 03/05/2024 | K4: 22/04/2024 | O4: 23/04/2024 | T4: 24/04/2024 | X4: 25/04/2024 | AB4: 26/04/2024 | AG4: 29/04/2024 | AJ4: 30/04/2024 | AL4: (blank) | AM4: Grand Total
C5: BMSC13 | D5: BMSC14 | E5: BMSC15 | F5: BMSC16 | G5: BMSC17 | H5: BMSC18 | I5: BMSC23 | J5: BMSC27 | K5: BMSC6 | M5: BMSC8 | O5: BMSC25 | Q5: BMSC5 | S5: BMSC9 | T5: BMSC24 | V5: BMSC26 | X5: BMSC1 | Z5: BMSC19 | AA5: BMSC20 | AB5: BMSC10 | AC5: BMSC11 | AE5: BMSC12 | AG5: BMSC2 | AH5: BMSC3 | AI5: BMSC4 | AJ5: BMSC21 | AK5: BMSC22 | AL5: (blank)
A6: Method | B6: Species | C6: 3 | D6: 6 | E6: 6.5 | F6: 7.5 | G6: 5.8 | H6: 8.5 | I6: 6.7 | J6: 8.5 | K6: 8 | L6: 11 | M6: 7.5 | N6: 8.5 | O6: 5.5 | P6: 6 | Q6: 6 | R6: 6.5 | S6: 6.5 | T6: 5.5 | U6: 10.5 | V6: 6.5 | W6: 8 | X6: 5 | Y6: 6.5 | Z6: 8.5 | AA6: 6.7 | AB6: 4.5 | AC6: 5 | AD6: 7.5 | AE6: 4.5 | AF6: 7 | AG6: 4 | AH6: 6 | AI6: 8.5 | AJ6: 6.5 | AK6: 5.5 | AL6: (blank)
A7: 0 | B7: Brachyistius frenatus | E7: 1 | V7: 1 | AM7: 2
B8: Cancer productus | AA8: 2 | AM8: 2
B9: Chirolophis nugator | S9: 1 | AM9: 1
B10: Crassadoma gigantea | F10: 2 | AM10: 2
B11: Diaulula sandiegensis | AB11: 1 | AD11: 1 | AM11: 2
B12: Echidnocerus cibarius | D12: 2 | AM12: 2
B13: Enophrys bison | S13: 1 | AM13: 1
B14: Enteroctopus dofleini | O14: 1 | AM14: 1
B15: Evasterias troschelii | G15: 1 | AM15: 1
B16: Haliotis kamtschatkana | W16: 1 | AM16: 1
B17: Hexagrammos decagrammus | E17: 1 | F17: 2 | G17: 3 | J17: 1 | P17: 1 | S17: 3 | U17: 1 | V17: 1 | Y17: 1 | AF17: 1 | AK17: 1 | AM17: 16
B18: Hexagrammos stelleri | Y18: 1 | AM18: 1
B19: Megaptera novaeangliae | Z19: 1 | AM19: 1
B20: Nautichthys oculofasciatus | S20: 1 | AM20: 1
B21: Neverita lewisii | S21: 1 | AM21: 1
B22: Ophiodon elongatus | D22: 1 | G22: 2 | J22: 2 | L22: 1 | Y22: 1 | AJ22: 1 | AM22: 8
B23: Oxylebius pictus | P23: 1 | U23: 2 | Y23: 1 | AB23: 1 | AE23: 1 | AF23: 1 | AG23: 1 | AJ23: 1 | AM23: 9
B24: Pisaster ochraceus | G24: 1 | M24: 3 | AM24: 4
B25: Pycnopodia helianthoides | Q25: 1 | AA25: 1 | AM25: 2
B26: Sebastes caurinus | F26: 3 | H26: 2 | I26: 1 | O26: 1 | P26: 1 | S26: 6 | U26: 1 | V26: 3 | W26: 1 | AB26: 6 | AC26: 1 | AE26: 1 | AJ26: 1 | AM26: 28
B27: Sebastes flavidus | H27: 27 | I27: 1 | U27: 1 | W27: 1 | AM27: 30
B28: Sebastes maliger | F28: 1 | K28: 1 | L28: 1 | Y28: 2 | AB28: 1 | AJ28: 2 | AK28: 2 | AM28: 10
B29: Sebastes melanops | D29: 10 | E29: 1 | H29: 2 | Q29: 1 | S29: 26 | AA29: 3 | AM29: 43
B30: Sebastes nebulosus | D30: 2 | G30: 1 | H30: 2 | L30: 1 | AA30: 1 | AM30: 7
B31: Sebastes nigrocinctus | U31: 1 | AM31: 1
B32: Sebastes spp. | D32: 2 | AB32: 1 | AM32: 3
A33: 1 | B33: Aequorea victoria | D33: 1 | E33: 1 | H33: 1 | AH33: 1 | AM33: 4
B34: Anarrhichthys ocellatus | L34: 2 | AM34: 2
B35: Artedius harringtoni | I35: 1 | N35: 1 | Y35: 1 | AF35: 1 | AG35: 1 | AM35: 5
B36: Bolinopsis infundubulum | G36: 1 | AM36: 1
B37: Brachyistius frenatus | V37: 7 | W37: 1 | AM37: 8
B38: Embiotoca lateralis | L38: 1 | T38: 13 | V38: 1 | AH38: 1 | AM38: 16
B39: Enophrys bison | R39: 1 | AM39: 1
B40: Hemilepidotus hemilepidotus | AC40: 1 | AM40: 1
B41: Hexagrammos decagrammus | C41: 10 | D41: 9 | E41: 1 | F41: 11 | G41: 5 | H41: 4 | I41: 5 | J41: 3 | K41: 3 | L41: 2 | M41: 2 | N41: 4 | O41: 2 | P41: 6 | Q41: 5 | S41: 8 | T41: 11 | U41: 9 | V41: 4 | W41: 1 | Y41: 3 | Z41: 8 | AA41: 9 | AB41: 8 | AC41: 7 | AD41: 1 | AE41: 11 | AG41: 24 | AH41: 1 | AI41: 6 | AJ41: 23 | AM41: 206
B42: Hexagrammos stelleri | C42: 1 | N42: 1 | AM42: 2
...

Sheet DATA
A1: ID | B1: Diver | C1: Buddy | D1: Site No. | E1: Site Name | F1: Latitude | G1: Longitude | H1: Date | I1: vis | J1: Direction | K1: Time | L1: P-Qs | M1: Depth | N1: Method | O1: Block | P1: Code | Q1: Species | R1: Common name | S1: Total | T1: Inverts | U1: =2.5*U2 -> 2.5 | V1: =2.5*V2 -> 5 | W1: =2.5*W2 -> 7.5 | X1: =2.5*X2 -> 10 | Y1: =2.5*Y2 -> 12.5 | Z1: =2.5*Z2 -> 15 | AA1: =2.5*AA2 -> 20 | AB1: =2.5*AB2 -> 25 | ... AR1: =2.5*AR2 -> 200 | AS1: 250 | AT1: 300 | AU1: 350 | AV1: 400
K2: 0.5 | N2: 0, 1, 2 | O2: 0, 1, 2 | Q2: 2 | R2: 3 | S2: =SUM(S3:S10028) -> 30552 | T2: =SUM(T3:T10028) -> 25101 | U2: 1 | V2: 2 | W2: 3 | X2: 4 | Y2: 5 | Z2: 6 | AA2: 8 | AB2: 10 | AC2: 12 | AD2: 14 | AE2: 16 | AF2: 20 | AG2: 25 | AH2: 30 | AI2: 35 | AJ2: 40 | AK2: 45 | AL2: 50 | AM2: 55 | AN2: 60 | AO2: 65 | AP2: 70 | AQ2: 75 | AR2: 80 | AS2: 100 | AT2: 120 | AU2: 140 | AV2: 160
A3: =MAX($A$1:$A2)+1 -> 1 | B3: Em Lim | C3: Isabelle Côté | D3: BMSC8 | E3: =IF(ISERROR(VLOOKUP($D3,SITES!$A:$E,2,FALSE)),"",VLOOKUP($D3,SITES!$A:$E,2,FALSE)) -> Baeria Rocks North Island Northside | F3: =IF(ISERROR(VLOOKUP($D3,SITES!$A:$E,3,FALSE)),"",VLOOKUP($D3,SITES!$A:$E,3,FALSE)) -> 48.955082 | G3: =IF(ISERROR(VLOOKUP($D3,SITES!$A:$E,4,FALSE)),"",VLOOKUP($D3,SITES!$A:$E,4,FALSE)) -> -125.15337 | H3: 22/04/2024 | I3: 1.5 | J3: SE | K3: 0.425 | L3: EGL | M3: 8.5 | N3: 1 | O3: 2 | P3: hde | Q3: =IF($N3=1,IF(ISERROR(VLOOKUP($P3,'M1'!$A:$C,Q$2,FALSE)),"NOT PRESENT",VLOOKUP($P3,'M1'!$A:$C,Q$2,FALSE)),IF($N3=2,IF(ISERROR(VLOOKUP(DATA!$P3,'M2'!$A:$C,Q$2,FALSE)),"NOT PRESENT",VLOOKUP(DATA!$P3,'M2'!$A:$C,Q$2,FALSE)),IF($N3=0,IF(ISERROR(VLOOKUP($P3,'M1'!$A:$C,Q$2,FALSE)),IF(ISERROR(VLOOKUP(DATA!$P3,'M2'!$A:$C,Q$2,FALSE)),"NOT PRESENT",VLOOKUP(DATA!$P3,'M2'!$A:$C,Q$2,FALSE)),VLOOKUP($P3,'M1'!$A:$C,Q$2,FALSE)),"SPECIFY METHOD"))) -> Hexagrammos decagrammus | R3: =IF($N3=1,IF(ISERROR(VLOOKUP($P3,'M1'!$A:$C,R$2,FALSE)),"NOT PRESENT",VLOOKUP($P3,'M1'!$A:$C,R$2,FALSE)),IF($N3=2,IF(ISERROR(VLOOKUP(DATA!$P3,'M2'!$A:$C,R$2,FALSE)),"NOT PRESENT",VLOOKUP(DATA!$P3,'M2'!$A:$C,R$2,FALSE)),IF($N3=0,IF(ISERROR(VLOOKUP($P3,'M1'!$A:$C,R$2,FALSE)),IF(ISERROR(VLOOKUP(DATA!$P3,'M2'!$A:$C,R$2,FALSE)),"NOT PRESENT",VLOOKUP(DATA!$P3,'M2'!$A:$C,R$2,FALSE)),VLOOKUP($P3,'M1'!$A:$C,R$2,FALSE)),"SPECIFY METHOD"))) -> Kelp greenling | S3: =SUM(T3:AV3) -> 2 | T3: 0 | Z3: 1 | AA3: 1
A4: =MAX($A$1:$A3)+1 -> 2 | B4: =IF(ISERROR(B3),IF(ISERROR(B2),IF(ISERROR(B1),"BLANK",B1),B2),B3) -> Em Lim | C4: =IF(ISERROR(C3),IF(ISERROR(C2),IF(ISERROR(C1),"BLANK",C1),C2),C3) -> Isabelle Côté | D4: =IF(ISERROR(D3),IF(ISERROR(D2),IF(ISERROR(D1),"BLANK",D1),D2),D3) -> BMSC8 | E4: =IF(ISERROR(VLOOKUP($D4,SITES!$A:$E,2,FALSE)),"",VLOOKUP($D4,SITES!$A:$E,2,FALSE)) -> Baeria Rocks North Island Northside | F4: =IF(ISERROR(VLOOKUP($D4,SITES!$A:$E,3,FALSE)),"",VLOOKUP($D4,SITES!$A:$E,3,FALSE)) -> 48.955082 | G4: =IF(ISERROR(VLOOKUP($D4,SITES!$A:$E,4,FALSE)),"",VLOOKUP($D4,SITES!$A:$E,4,FALSE)) -> -125.15337 | H4: =IF(ISERROR(H3),IF(ISERROR(H2),IF(ISERROR(H1),"BLANK",H1),H2),H3) -> 22/04/2024 | I4: =IF(ISERROR(I3),IF(ISERROR(I2),IF(ISERROR(I1),"BLANK",I1),I2),I3) -> 1.5 | J4: =IF(ISERROR(J3),IF(ISERROR(J2),IF(ISERROR(J1),"BLANK",J1),J2),J3) -> SE | K4: =IF(ISERROR(K3),IF(ISERROR(K2),IF(ISERROR(K1),"BLANK",K1),K2),K3) -> 0.425 | L4: =IF(ISERROR(L3),IF(ISERROR(L2),IF(ISERROR(L1),"BLANK",L1),L2),L3) -> EGL | M4: =IF(ISERROR(M3),IF(ISERROR(M2),IF(ISERROR(M1),"BLANK",M1),M2),M3) -> 8.5 | N4: =IF(ISERROR(N3),IF(ISERROR(N2),IF(ISERROR(N1),"BLANK",N1),N2),N3) -> 1 | O4: =IF(ISERROR(O3),IF(ISERROR(O2),IF(ISERROR(O1),"BLANK",O1),O2),O3) -> 2 | P4: aha | Q4: =IF($N4=1,IF(ISERROR(VLOOKUP($P4,'M1'!$A:$C,Q$2,FALSE)),"NOT PRESENT",VLOOKUP($P4,'M1'!$A:$C,Q$2,FALSE)),IF($N4=2,IF(ISERROR(VLOOKUP(DATA!$P4,'M2'!$A:$C,Q$2,FALSE)),"NOT PRESENT",VLOOKUP(DATA!$P4,'M2'!$A:$C,Q$2,FALSE)),IF($N4=0,IF(ISERROR(VLOOKUP($P4,'M1'!$A:$C,Q$2,FALSE)),IF(ISERROR(VLOOKUP(DATA!$P4,'M2'!$A:$C,Q$2,FALSE)),"NOT PRESENT",VLOOKUP(DATA!$P4,'M2'!$A:$C,Q$2,FALSE)),VLOOKUP($P4,'M1'!$A:$C,Q$2,FALSE)),"SPECIFY METHOD"))) -> Artedius harringtoni | R4: =IF($N4=1,IF(ISERROR(VLOOKUP($P4,'M1'!$A:$C,R$2,FALSE)),"NOT PRESENT",VLOOKUP($P4,'M1'!$A:$C,R$2,FALSE)),IF($N4=2,IF(ISERROR(VLOOKUP(DATA!$P4,'M2'!$A:$C,R$2,FALSE)),"NOT PRESENT",VLOOKUP(DATA!$P4,'M2'!$A:$C,R$2,FALSE)),IF($N4=0,IF(ISERROR(VLOOKUP($P4,'M1'!$A:$C,R$2,FALSE)),IF(ISERROR(VLOOKUP(DATA!$P4,'M2'!$A:$C,R$2,FALSE)),"NOT PRESENT",VLOOKUP(DATA!$P4,'M2'!$A:$C,R$2,FALSE)),VLOOKUP($P4,'M1'!$A:$C,R$2,FALSE)),"SPECIFY METHOD"))) -> Scalyhead sculpin | S4: =SUM(T4:AV4) -> 1 | T4: 0 | W4: 1
A5: =MAX($A$1:$A4)+1 -> 3 | B5: =IF(ISERROR(B4),IF(ISERROR(B3),IF(ISERROR(B2),"BLANK",B2),B3),B4) -> Em Lim | C5: =IF(ISERROR(C4),IF(ISERROR(C3),IF(ISERROR(C2),"BLANK",C2),C3),C4) -> Isabelle Côté | D5: =IF(ISERROR(D4),IF(ISERROR(D3),IF(ISERROR(D2),"BLANK",D2),D3),D4) -> BMSC8 | E5: =IF(ISERROR(VLOOKUP($D5,SITES!$A:$E,2,FALSE)),"",VLOOKUP($D5,SITES!$A:$E,2,FALSE)) -> Baeria Rocks North Island Northside | F5: =IF(ISERROR(VLOOKUP($D5,SITES!$A:$E,3,FALSE)),"",VLOOKUP($D5,SITES!$A:$E,3,FALSE)) -> 48.955082 | G5: =IF(ISERROR(VLOOKUP($D5,SITES!$A:$E,4,FALSE)),"",VLOOKUP($D5,SITES!$A:$E,4,FALSE)) -> -125.15337 | H5: =IF(ISERROR(H4),IF(ISERROR(H3),IF(ISERROR(H2),"BLANK",H2),H3),H4) -> 22/04/2024 | I5: =IF(ISERROR(I4),IF(ISERROR(I3),IF(ISERROR(I2),"BLANK",I2),I3),I4) -> 1.5 | J5: =IF(ISERROR(J4),IF(ISERROR(J3),IF(ISERROR(J2),"BLANK",J2),J3),J4) -> SE | K5: =IF(ISERROR(K4),IF(ISERROR(K3),IF(ISERROR(K2),"BLANK",K2),K3),K4) -> 0.425 | L5: =IF(ISERROR(L4),IF(ISERROR(L3),IF(ISERROR(L2),"BLANK",L2),L3),L4) -> EGL | M5: =IF(ISERROR(M4),IF(ISERROR(M3),IF(ISERROR(M2),"BLANK",M2),M3),M4) -> 8.5 | N5: 2 | O5: =IF(ISERROR(O4),IF(ISERROR(O3),IF(ISERROR(O2),"BLANK",O2),O3),O4) -> 2 | P5: mfra | Q5: =IF($N5=1,IF(ISERROR(VLOOKUP($P5,'M1'!$A:$C,Q$2,FALSE)),"NOT PRESENT",VLOOKUP($P5,'M1'!$A:$C,Q$2,FALSE)),IF($N5=2,IF(ISERROR(VLOOKUP(DATA!$P5,'M2'!$A:$C,Q$2,FALSE)),"NOT PRESENT",VLOOKUP(DATA!$P5,'M2'!$A:$C,Q$2,FALSE)),IF($N5=0,IF(ISERROR(VLOOKUP($P5,'M1'!$A:$C,Q$2,FALSE)),IF(ISERROR(VLOOKUP(DATA!$P5,'M2'!$A:$C,Q$2,FALSE)),"NOT PRESENT",VLOOKUP(DATA!$P5,'M2'!$A:$C,Q$2,FALSE)),VLOOKUP($P5,'M1'!$A:$C,Q$2,FALSE)),"SPECIFY METHOD"))) -> Mesocentrotus franciscanus | R5: =IF($N5=1,IF(ISERROR(VLOOKUP($P5,'M1'!$A:$C,R$2,FALSE)),"NOT PRESENT",VLOOKUP($P5,'M1'!$A:$C,R$2,FALSE)),IF($N5=2,IF(ISERROR(VLOOKUP(DATA!$P5,'M2'!$A:$C,R$2,FALSE)),"NOT PRESENT",VLOOKUP(DATA!$P5,'M2'!$A:$C,R$2,FALSE)),IF($N5=0,IF(ISERROR(VLOOKUP($P5,'M1'!$A:$C,R$2,FALSE)),IF(ISERROR(VLOOKUP(DATA!$P5,'M2'!$A:$C,R$2,FALSE)),"NOT PRESENT",VLOOKUP(DATA!$P5,'M2'!$A:$C,R$2,FALSE)),VLOOKUP($P5,'M1'!$A:$C,R$2,FALSE)),"SPECIFY METHOD"))) -> Red sea urchin | S5: =SUM(T5:AV5) -> 244 | T5: 244
A6: =MAX($A$1:$A5)+1 -> 4 | B6: =IF(ISERROR(B5),IF(ISERROR(B4),IF(ISERROR(B3),"BLANK",B3),B4),B5) -> Em Lim | C6: =IF(ISERROR(C5),IF(ISERROR(C4),IF(ISERROR(C3),"BLANK",C3),C4),C5) -> Isabelle Côté | D6: =IF(ISERROR(D5),IF(ISERROR(D4),IF(ISERROR(D3),"BLANK",D3),D4),D5) -> BMSC8 | E6: =IF(ISERROR(VLOOKUP($D6,SITES!$A:$E,2,FALSE)),"",VLOOKUP($D6,SITES!$A:$E,2,FALSE)) -> Baeria Rocks North Island Northside | F6: =IF(ISERROR(VLOOKUP($D6,SITES!$A:$E,3,FALSE)),"",VLOOKUP($D6,SITES!$A:$E,3,FALSE)) -> 48.955082 | G6: =IF(ISERROR(VLOOKUP($D6,SITES!$A:$E,4,FALSE)),"",VLOOKUP($D6,SITES!$A:$E,4,FALSE)) -> -125.15337 | H6: =IF(ISERROR(H5),IF(ISERROR(H4),IF(ISERROR(H3),"BLANK",H3),H4),H5) -> 22/04/2024 | I6: =IF(ISERROR(I5),IF(ISERROR(I4),IF(ISERROR(I3),"BLANK",I3),I4),I5) -> 1.5 | J6: =IF(ISERROR(J5),IF(ISERROR(J4),IF(ISERROR(J3),"BLANK",J3),J4),J5) -> SE | K6: =IF(ISERROR(K5),IF(ISERROR(K4),IF(ISERROR(K3),"BLANK",K3),K4),K5) -> 0.425 | L6: =IF(ISERROR(L5),IF(ISERROR(L4),IF(ISERROR(L3),"BLANK",L3),L4),L5) -> EGL | M6: =IF(ISERROR(M5),IF(ISERROR(M4),IF(ISERROR(M3),"BLANK",M3),M4),M5) -> 8.5 | N6: =IF(ISERROR(N5),IF(ISERROR(N4),IF(ISERROR(N3),"BLANK",N3),N4),N5) -> 2 | O6: =IF(ISERROR(O5),IF(ISERROR(O4),IF(ISERROR(O3),"BLANK",O3),O4),O5) -> 2 | P6: pgi | Q6: =IF($N6=1,IF(ISERROR(VLOOKUP($P6,'M1'!$A:$C,Q$2,FALSE)),"NOT PRESENT",VLOOKUP($P6,'M1'!$A:$C,Q$2,FALSE)),IF($N6=2,IF(ISERROR(VLOOKUP(DATA!$P6,'M2'!$A:$C,Q$2,FALSE)),"NOT PRESENT",VLOOKUP(DATA!$P6,'M2'!$A:$C,Q$2,FALSE)),IF($N6=0,IF(ISERROR(VLOOKUP($P6,'M1'!$A:$C,Q$2,FALSE)),IF(ISERROR(VLOOKUP(DATA!$P6,'M2'!$A:$C,Q$2,FALSE)),"NOT PRESENT",VLOOKUP(DATA!$P6,'M2'!$A:$C,Q$2,FALSE)),VLOOKUP($P6,'M1'!$A:$C,Q$2,FALSE)),"SPECIFY METHOD"))) -> Pomaulax gibberosus | R6: =IF($N6=1,IF(ISERROR(VLOOKUP($P6,'M1'!$A:$C,R$2,FALSE)),"NOT PRESENT",VLOOKUP($P6,'M1'!$A:$C,R$2,FALSE)),IF($N6=2,IF(ISERROR(VLOOKUP(DATA!$P6,'M2'!$A:$C,R$2,FALSE)),"NOT PRESENT",VLOOKUP(DATA!$P6,'M2'!$A:$C,R$2,FALSE)),IF($N6=0,IF(ISERROR(VLOOKUP($P6,'M1'!$A:$C,R$2,FALSE)),IF(ISERROR(VLOOKUP(DATA!$P6,'M2'!$A:$C,R$2,FALSE)),"NOT PRESENT",VLOOKUP(DATA!$P6,'M2'!$A:$C,R$2,FALSE)),VLOOKUP($P6,'M1'!$A:$C,R$2,FALSE)),"SPECIFY METHOD"))) -> Red turban shell | S6: =SUM(T6:AV6) -> 67 | T6: 67
A7: =MAX($A$1:$A6)+1 -> 5 | B7: =IF(ISERROR(B6),IF(ISERROR(B5),IF(ISERROR(B4),"BLANK",B4),B5),B6) -> Em Lim | C7: =IF(ISERROR(C6),IF(ISERROR(C5),IF(ISERROR(C4),"BLANK",C4),C5),C6) -> Isabelle Côté | D7: =IF(ISERROR(D6),IF(ISERROR(D5),IF(ISERROR(D4),"BLANK",D4),D5),D6) -> BMSC8 | E7: =IF(ISERROR(VLOOKUP($D7,SITES!$A:$E,2,FALSE)),"",VLOOKUP($D7,SITES!$A:$E,2,FALSE)) -> Baeria Rocks North Island Northside | F7: =IF(ISERROR(VLOOKUP($D7,SITES!$A:$E,3,FALSE)),"",VLOOKUP($D7,SITES!$A:$E,3,FALSE)) -> 48.955082 | G7: =IF(ISERROR(VLOOKUP($D7,SITES!$A:$E,4,FALSE)),"",VLOOKUP($D7,SITES!$A:$E,4,FALSE)) -> -125.15337 | H7: =IF(ISERROR(H6),IF(ISERROR(H5),IF(ISERROR(H4),"BLANK",H4),H5),H6) -> 22/04/2024 | I7: =IF(ISERROR(I6),IF(ISERROR(I5),IF(ISERROR(I4),"BLANK",I4),I5),I6) -> 1.5 | J7: =IF(ISERROR(J6),IF(ISERROR(J5),IF(ISERROR(J4),"BLANK",J4),J5),J6) -> SE | K7: =IF(ISERROR(K6),IF(ISERROR(K5),IF(ISERROR(K4),"BLANK",K4),K5),K6) -> 0.425 | L7: =IF(ISERROR(L6),IF(ISERROR(L5),IF(ISERROR(L4),"BLANK",L4),L5),L6) -> EGL | M7: =IF(ISERROR(M6),IF(ISERROR(M5),IF(ISERROR(M4),"BLANK",M4),M5),M6) -> 8.5 | N7: =IF(ISERROR(N6),IF(ISERROR(N5),IF(ISERROR(N4),"BLANK",N4),N5),N6) -> 2 | O7: =IF(ISERROR(O6),IF(ISERROR(O5),IF(ISERROR(O4),"BLANK",O4),O5),O6) -> 2 | P7: pmi | Q7: =IF($N7=1,IF(ISERROR(VLOOKUP($P7,'M1'!$A:$C,Q$2,FALSE)),"NOT PRESENT",VLOOKUP($P7,'M1'!$A:$C,Q$2,FALSE)),IF($N7=2,IF(ISERROR(VLOOKUP(DATA!$P7,'M2'!$A:$C,Q$2,FALSE)),"NOT PRESENT",VLOOKUP(DATA!$P7,'M2'!$A:$C,Q$2,FALSE)),IF($N7=0,IF(ISERROR(VLOOKUP($P7,'M1'!$A:$C,Q$2,FALSE)),IF(ISERROR(VLOOKUP(DATA!$P7,'M2'!$A:$C,Q$2,FALSE)),"NOT PRESENT",VLOOKUP(DATA!$P7,'M2'!$A:$C,Q$2,FALSE)),VLOOKUP($P7,'M1'!$A:$C,Q$2,FALSE)),"SPECIFY METHOD"))) -> Patiria miniata | R7: =IF($N7=1,IF(ISERROR(VLOOKUP($P7,'M1'!$A:$C,R$2,FALSE)),"NOT PRESENT",VLOOKUP($P7,'M1'!$A:$C,R$2,FALSE)),IF($N7=2,IF(ISERROR(VLOOKUP(DATA!$P7,'M2'!$A:$C,R$2,FALSE)),"NOT PRESENT",VLOOKUP(DATA!$P7,'M2'!$A:$C,R$2,FALSE)),IF($N7=0,IF(ISERROR(VLOOKUP($P7,'M1'!$A:$C,R$2,FALSE)),IF(ISERROR(VLOOKUP(DATA!$P7,'M2'!$A:$C,R$2,FALSE)),"NOT PRESENT",VLOOKUP(DATA!$P7,'M2'!$A:$C,R$2,FALSE)),VLOOKUP($P7,'M1'!$A:$C,R$2,FALSE)),"SPECIFY METHOD"))) -> Bat star | S7: =SUM(T7:AV7) -> 41 | T7: 41
A8: =MAX($A$1:$A7)+1 -> 6 | B8: =IF(ISERROR(B7),IF(ISERROR(B6),IF(ISERROR(B5),"BLANK",B5),B6),B7) -> Em Lim | C8: =IF(ISERROR(C7),IF(ISERROR(C6),IF(ISERROR(C5),"BLANK",C5),C6),C7) -> Isabelle Côté | D8: =IF(ISERROR(D7),IF(ISERROR(D6),IF(ISERROR(D5),"BLANK",D5),D6),D7) -> BMSC8 | E8: =IF(ISERROR(VLOOKUP($D8,SITES!$A:$E,2,FALSE)),"",VLOOKUP($D8,SITES!$A:$E,2,FALSE)) -> Baeria Rocks North Island Northside | F8: =IF(ISERROR(VLOOKUP($D8,SITES!$A:$E,3,FALSE)),"",VLOOKUP($D8,SITES!$A:$E,3,FALSE)) -> 48.955082 | G8: =IF(ISERROR(VLOOKUP($D8,SITES!$A:$E,4,FALSE)),"",VLOOKUP($D8,SITES!$A:$E,4,FALSE)) -> -125.15337 | H8: =IF(ISERROR(H7),IF(ISERROR(H6),IF(ISERROR(H5),"BLANK",H5),H6),H7) -> 22/04/2024 | I8: =IF(ISERROR(I7),IF(ISERROR(I6),IF(ISERROR(I5),"BLANK",I5),I6),I7) -> 1.5 | J8: =IF(ISERROR(J7),IF(ISERROR(J6),IF(ISERROR(J5),"BLANK",J5),J6),J7) -> SE | K8: =IF(ISERROR(K7),IF(ISERROR(K6),IF(ISERROR(K5),"BLANK",K5),K6),K7) -> 0.425 | L8: =IF(ISERROR(L7),IF(ISERROR(L6),IF(ISERROR(L5),"BLANK",L5),L6),L7) -> EGL | M8: =IF(ISERROR(M7),IF(ISERROR(M6),IF(ISERROR(M5),"BLANK",M5),M6),M7) -> 8.5 | N8: =IF(ISERROR(N7),IF(ISERROR(N6),IF(ISERROR(N5),"BLANK",N5),N6),N7) -> 2 | O8: =IF(ISERROR(O7),IF(ISERROR(O6),IF(ISERROR(O5),"BLANK",O5),O6),O7) -> 2 | P8: ami | Q8: =IF($N8=1,IF(ISERROR(VLOOKUP($P8,'M1'!$A:$C,Q$2,FALSE)),"NOT PRESENT",VLOOKUP($P8,'M1'!$A:$C,Q$2,FALSE)),IF($N8=2,IF(ISERROR(VLOOKUP(DATA!$P8,'M2'!$A:$C,Q$2,FALSE)),"NOT PRESENT",VLOOKUP(DATA!$P8,'M2'!$A:$C,Q$2,FALSE)),IF($N8=0,IF(ISERROR(VLOOKUP($P8,'M1'!$A:$C,Q$2,FALSE)),IF(ISERROR(VLOOKUP(DATA!$P8,'M2'!$A:$C,Q$2,FALSE)),"NOT PRESENT",VLOOKUP(DATA!$P8,'M2'!$A:$C,Q$2,FALSE)),VLOOKUP($P8,'M1'!$A:$C,Q$2,FALSE)),"SPECIFY METHOD"))) -> Acmaea mitra | R8: =IF($N8=1,IF(ISERROR(VLOOKUP($P8,'M1'!$A:$C,R$2,FALSE)),"NOT PRESENT",VLOOKUP($P8,'M1'!$A:$C,R$2,FALSE)),IF($N8=2,IF(ISERROR(VLOOKUP(DATA!$P8,'M2'!$A:$C,R$2,FALSE)),"NOT PRESENT",VLOOKUP(DATA!$P8,'M2'!$A:$C,R$2,FALSE)),IF($N8=0,IF(ISERROR(VLOOKUP($P8,'M1'!$A:$C,R$2,FALSE)),IF(ISERROR(VLOOKUP(DATA!$P8,'M2'!$A:$C,R$2,FALSE)),"NOT PRESENT",VLOOKUP(DATA!$P8,'M2'!$A:$C,R$2,FALSE)),VLOOKUP($P8,'M1'!$A:$C,R$2,FALSE)),"SPECIFY METHOD"))) -> Whitecap limpet | S8: =SUM(T8:AV8) -> 17 | T8: 17
A9: =MAX($A$1:$A8)+1 -> 7 | B9: =IF(ISERROR(B8),IF(ISERROR(B7),IF(ISERROR(B6),"BLANK",B6),B7),B8) -> Em Lim | C9: =IF(ISERROR(C8),IF(ISERROR(C7),IF(ISERROR(C6),"BLANK",C6),C7),C8) -> Isabelle Côté | D9: =IF(ISERROR(D8),IF(ISERROR(D7),IF(ISERROR(D6),"BLANK",D6),D7),D8) -> BMSC8 | E9: =IF(ISERROR(VLOOKUP($D9,SITES!$A:$E,2,FALSE)),"",VLOOKUP($D9,SITES!$A:$E,2,FALSE)) -> Baeria Rocks North Island Northside | F9: =IF(ISERROR(VLOOKUP($D9,SITES!$A:$E,3,FALSE)),"",VLOOKUP($D9,SITES!$A:$E,3,FALSE)) -> 48.955082 | G9: =IF(ISERROR(VLOOKUP($D9,SITES!$A:$E,4,FALSE)),"",VLOOKUP($D9,SITES!$A:$E,4,FALSE)) -> -125.15337 | H9: =IF(ISERROR(H8),IF(ISERROR(H7),IF(ISERROR(H6),"BLANK",H6),H7),H8) -> 22/04/2024 | I9: =IF(ISERROR(I8),IF(ISERROR(I7),IF(ISERROR(I6),"BLANK",I6),I7),I8) -> 1.5 | J9: =IF(ISERROR(J8),IF(ISERROR(J7),IF(ISERROR(J6),"BLANK",J6),J7),J8) -> SE | K9: =IF(ISERROR(K8),IF(ISERROR(K7),IF(ISERROR(K6),"BLANK",K6),K7),K8) -> 0.425 | L9: =IF(ISERROR(L8),IF(ISERROR(L7),IF(ISERROR(L6),"BLANK",L6),L7),L8) -> EGL | M9: =IF(ISERROR(M8),IF(ISERROR(M7),IF(ISERROR(M6),"BLANK",M6),M7),M8) -> 8.5 | N9: =IF(ISERROR(N8),IF(ISERROR(N7),IF(ISERROR(N6),"BLANK",N6),N7),N8) -> 2 | O9: =IF(ISERROR(O8),IF(ISERROR(O7),IF(ISERROR(O6),"BLANK",O6),O7),O8) -> 2 | P9: aca | Q9: =IF($N9=1,IF(ISERROR(VLOOKUP($P9,'M1'!$A:$C,Q$2,FALSE)),"NOT PRESENT",VLOOKUP($P9,'M1'!$A:$C,Q$2,FALSE)),IF($N9=2,IF(ISERROR(VLOOKUP(DATA!$P9,'M2'!$A:$C,Q$2,FALSE)),"NOT PRESENT",VLOOKUP(DATA!$P9,'M2'!$A:$C,Q$2,FALSE)),IF($N9=0,IF(ISERROR(VLOOKUP($P9,'M1'!$A:$C,Q$2,FALSE)),IF(ISERROR(VLOOKUP(DATA!$P9,'M2'!$A:$C,Q$2,FALSE)),"NOT PRESENT",VLOOKUP(DATA!$P9,'M2'!$A:$C,Q$2,FALSE)),VLOOKUP($P9,'M1'!$A:$C,Q$2,FALSE)),"SPECIFY METHOD"))) -> Apostichopus californicus | R9: =IF($N9=1,IF(ISERROR(VLOOKUP($P9,'M1'!$A:$C,R$2,FALSE)),"NOT PRESENT",VLOOKUP($P9,'M1'!$A:$C,R$2,FALSE)),IF($N9=2,IF(ISERROR(VLOOKUP(DATA!$P9,'M2'!$A:$C,R$2,FALSE)),"NOT PRESENT",VLOOKUP(DATA!$P9,'M2'!$A:$C,R$2,FALSE)),IF($N9=0,IF(ISERROR(VLOOKUP($P9,'M1'!$A:$C,R$2,FALSE)),IF(ISERROR(VLOOKUP(DATA!$P9,'M2'!$A:$C,R$2,FALSE)),"NOT PRESENT",VLOOKUP(DATA!$P9,'M2'!$A:$C,R$2,FALSE)),VLOOKUP($P9,'M1'!$A:$C,R$2,FALSE)),"SPECIFY METHOD"))) -> California sea cucumber | S9: =SUM(T9:AV9) -> 4 | T9: 4
A10: =MAX($A$1:$A9)+1 -> 8 | B10: =IF(ISERROR(B9),IF(ISERROR(B8),IF(ISERROR(B7),"BLANK",B7),B8),B9) -> Em Lim | C10: =IF(ISERROR(C9),IF(ISERROR(C8),IF(ISERROR(C7),"BLANK",C7),C8),C9) -> Isabelle Côté | D10: =IF(ISERROR(D9),IF(ISERROR(D8),IF(ISERROR(D7),"BLANK",D7),D8),D9) -> BMSC8 | E10: =IF(ISERROR(VLOOKUP($D10,SITES!$A:$E,2,FALSE)),"",VLOOKUP($D10,SITES!$A:$E,2,FALSE)) -> Baeria Rocks North Island Northside | F10: =IF(ISERROR(VLOOKUP($D10,SITES!$A:$E,3,FALSE)),"",VLOOKUP($D10,SITES!$A:$E,3,FALSE)) -> 48.955082 | G10: =IF(ISERROR(VLOOKUP($D10,SITES!$A:$E,4,FALSE)),"",VLOOKUP($D10,SITES!$A:$E,4,FALSE)) -> -125.15337 | H10: =IF(ISERROR(H9),IF(ISERROR(H8),IF(ISERROR(H7),"BLANK",H7),H8),H9) -> 22/04/2024 | I10: =IF(ISERROR(I9),IF(ISERROR(I8),IF(ISERROR(I7),"BLANK",I7),I8),I9) -> 1.5 | J10: =IF(ISERROR(J9),IF(ISERROR(J8),IF(ISERROR(J7),"BLANK",J7),J8),J9) -> SE | K10: =IF(ISERROR(K9),IF(ISERROR(K8),IF(ISERROR(K7),"BLANK",K7),K8),K9) -> 0.425 | L10: =IF(ISERROR(L9),IF(ISERROR(L8),IF(ISERROR(L7),"BLANK",L7),L8),L9) -> EGL | M10: =IF(ISERROR(M9),IF(ISERROR(M8),IF(ISERROR(M7),"BLANK",M7),M8),M9) -> 8.5 | N10: =IF(ISERROR(N9),IF(ISERROR(N8),IF(ISERROR(N7),"BLANK",N7),N8),N9) -> 2 | O10: =IF(ISERROR(O9),IF(ISERROR(O8),IF(ISERROR(O7),"BLANK",O7),O8),O9) -> 2 | P10: phem | Q10: =IF($N10=1,IF(ISERROR(VLOOKUP($P10,'M1'!$A:$C,Q$2,FALSE)),"NOT PRESENT",VLOOKUP($P10,'M1'!$A:$C,Q$2,FALSE)),IF($N10=2,IF(ISERROR(VLOOKUP(DATA!$P10,'M2'!$A:$C,Q$2,FALSE)),"NOT PRESENT",VLOOKUP(DATA!$P10,'M2'!$A:$C,Q$2,FALSE)),IF($N10=0,IF(ISERROR(VLOOKUP($P10,'M1'!$A:$C,Q$2,FALSE)),IF(ISERROR(VLOOKUP(DATA!$P10,'M2'!$A:$C,Q$2,FALSE)),"NOT PRESENT",VLOOKUP(DATA!$P10,'M2'!$A:$C,Q$2,FALSE)),VLOOKUP($P10,'M1'!$A:$C,Q$2,FALSE)),"SPECIFY METHOD"))) -> Pagurus hemphilli | R10: =IF($N10=1,IF(ISERROR(VLOOKUP($P10,'M1'!$A:$C,R$2,FALSE)),"NOT PRESENT",VLOOKUP($P10,'M1'!$A:$C,R$2,FALSE)),IF($N10=2,IF(ISERROR(VLOOKUP(DATA!$P10,'M2'!$A:$C,R$2,FALSE)),"NOT PRESENT",VLOOKUP(DATA!$P10,'M2'!$A:$C,R$2,FALSE)),IF($N10=0,IF(ISERROR(VLOOKUP($P10,'M1'!$A:$C,R$2,FALSE)),IF(ISERROR(VLOOKUP(DATA!$P10,'M2'!$A:$C,R$2,FALSE)),"NOT PRESENT",VLOOKUP(DATA!$P10,'M2'!$A:$C,R$2,FALSE)),VLOOKUP($P10,'M1'!$A:$C,R$2,FALSE)),"SPECIFY METHOD"))) -> Maroon hermit | S10: =SUM(T10:AV10) -> 30 | T10: 30
A11: =MAX($A$1:$A10)+1 -> 9 | B11: =IF(ISERROR(B10),IF(ISERROR(B9),IF(ISERROR(B8),"BLANK",B8),B9),B10) -> Em Lim | C11: =IF(ISERROR(C10),IF(ISERROR(C9),IF(ISERROR(C8),"BLANK",C8),C9),C10) -> Isabelle Côté | D11: =IF(ISERROR(D10),IF(ISERROR(D9),IF(ISERROR(D8),"BLANK",D8),D9),D10) -> BMSC8 | E11: =IF(ISERROR(VLOOKUP($D11,SITES!$A:$E,2,FALSE)),"",VLOOKUP($D11,SITES!$A:$E,2,FALSE)) -> Baeria Rocks North Island Northside | F11: =IF(ISERROR(VLOOKUP($D11,SITES!$A:$E,3,FALSE)),"",VLOOKUP($D11,SITES!$A:$E,3,FALSE)) -> 48.955082 | G11: =IF(ISERROR(VLOOKUP($D11,SITES!$A:$E,4,FALSE)),"",VLOOKUP($D11,SITES!$A:$E,4,FALSE)) -> -125.15337 | H11: =IF(ISERROR(H10),IF(ISERROR(H9),IF(ISERROR(H8),"BLANK",H8),H9),H10) -> 22/04/2024 | I11: =IF(ISERROR(I10),IF(ISERROR(I9),IF(ISERROR(I8),"BLANK",I8),I9),I10) -> 1.5 | J11: =IF(ISERROR(J10),IF(ISERROR(J9),IF(ISERROR(J8),"BLANK",J8),J9),J10) -> SE | K11: =IF(ISERROR(K10),IF(ISERROR(K9),IF(ISERROR(K8),"BLANK",K8),K9),K10) -> 0.425 | L11: =IF(ISERROR(L10),IF(ISERROR(L9),IF(ISERROR(L8),"BLANK",L8),L9),L10) -> EGL | M11: =IF(ISERROR(M10),IF(ISERROR(M9),IF(ISERROR(M8),"BLANK",M8),M9),M10) -> 8.5 | N11: =IF(ISERROR(N10),IF(ISERROR(N9),IF(ISERROR(N8),"BLANK",N8),N9),N10) -> 2 | O11: =IF(ISERROR(O10),IF(ISERROR(O9),IF(ISERROR(O8),"BLANK",O8),O9),O10) -> 2 | P11: oko | Q11: =IF($N11=1,IF(ISERROR(VLOOKUP($P11,'M1'!$A:$C,Q$2,FALSE)),"NOT PRESENT",VLOOKUP($P11,'M1'!$A:$C,Q$2,FALSE)),IF($N11=2,IF(ISERROR(VLOOKUP(DATA!$P11,'M2'!$A:$C,Q$2,FALSE)),"NOT PRESENT",VLOOKUP(DATA!$P11,'M2'!$A:$C,Q$2,FALSE)),IF($N11=0,IF(ISERROR(VLOOKUP($P11,'M1'!$A:$C,Q$2,FALSE)),IF(ISERROR(VLOOKUP(DATA!$P11,'M2'!$A:$C,Q$2,FALSE)),"NOT PRESENT",VLOOKUP(DATA!$P11,'M2'!$A:$C,Q$2,FALSE)),VLOOKUP($P11,'M1'!$A:$C,Q$2,FALSE)),"SPECIFY METHOD"))) -> Orthasterias koehleri | R11: =IF($N11=1,IF(ISERROR(VLOOKUP($P11,'M1'!$A:$C,R$2,FALSE)),"NOT PRESENT",VLOOKUP($P11,'M1'!$A:$C,R$2,FALSE)),IF($N11=2,IF(ISERROR(VLOOKUP(DATA!$P11,'M2'!$A:$C,R$2,FALSE)),"NOT PRESENT",VLOOKUP(DATA!$P11,'M2'!$A:$C,R$2,FALSE)),IF($N11=0,IF(ISERROR(VLOOKUP($P11,'M1'!$A:$C,R$2,FALSE)),IF(ISERROR(VLOOKUP(DATA!$P11,'M2'!$A:$C,R$2,FALSE)),"NOT PRESENT",VLOOKUP(DATA!$P11,'M2'!$A:$C,R$2,FALSE)),VLOOKUP($P11,'M1'!$A:$C,R$2,FALSE)),"SPECIFY METHOD"))) -> Rainbow star | S11: =SUM(T11:AV11) -> 10 | T11: 10
A12: =MAX($A$1:$A11)+1 -> 10 | B12: =IF(ISERROR(#REF!),IF(ISERROR(#REF!),IF(ISERROR(B11),"BLANK",B11),#REF!),#REF!) -> Em Lim | C12: =IF(ISERROR(#REF!),IF(ISERROR(#REF!),IF(ISERROR(C11),"BLANK",C11),#REF!),#REF!) -> Isabelle Côté | D12: =IF(ISERROR(#REF!),IF(ISERROR(#REF!),IF(ISERROR(D11),"BLANK",D11),#REF!),#REF!) -> BMSC8 | E12: =IF(ISERROR(VLOOKUP($D12,SITES!$A:$E,2,FALSE)),"",VLOOKUP($D12,SITES!$A:$E,2,FALSE)) -> Baeria Rocks North Island Northside | F12: =IF(ISERROR(VLOOKUP($D12,SITES!$A:$E,3,FALSE)),"",VLOOKUP($D12,SITES!$A:$E,3,FALSE)) -> 48.955082 | G12: =IF(ISERROR(VLOOKUP($D12,SITES!$A:$E,4,FALSE)),"",VLOOKUP($D12,SITES!$A:$E,4,FALSE)) -> -125.15337 | H12: =IF(ISERROR(#REF!),IF(ISERROR(#REF!),IF(ISERROR(H11),"BLANK",H11),#REF!),#REF!) -> 22/04/2024 | I12: =IF(ISERROR(#REF!),IF(ISERROR(#REF!),IF(ISERROR(I11),"BLANK",I11),#REF!),#REF!) -> 1.5 | J12: =IF(ISERROR(#REF!),IF(ISERROR(#REF!),IF(ISERROR(J11),"BLANK",J11),#REF!),#REF!) -> SE | K12: =IF(ISERROR(#REF!),IF(ISERROR(#REF!),IF(ISERROR(K11),"BLANK",K11),#REF!),#REF!) -> 0.425 | L12: =IF(ISERROR(#REF!),IF(ISERROR(#REF!),IF(ISERROR(L11),"BLANK",L11),#REF!),#REF!) -> EGL | M12: =IF(ISERROR(#REF!),IF(ISERROR(#REF!),IF(ISERROR(M11),"BLANK",M11),#REF!),#REF!) -> 8.5 | N12: =IF(ISERROR(#REF!),IF(ISERROR(#REF!),IF(ISERROR(N11),"BLANK",N11),#REF!),#REF!) -> 2 | O12: =IF(ISERROR(#REF!),IF(ISERROR(#REF!),IF(ISERROR(O11),"BLANK",O11),#REF!),#REF!) -> 2 | P12: hka | Q12: =IF($N12=1,IF(ISERROR(VLOOKUP($P12,'M1'!$A:$C,Q$2,FALSE)),"NOT PRESENT",VLOOKUP($P12,'M1'!$A:$C,Q$2,FALSE)),IF($N12=2,IF(ISERROR(VLOOKUP(DATA!$P12,'M2'!$A:$C,Q$2,FALSE)),"NOT PRESENT",VLOOKUP(DATA!$P12,'M2'!$A:$C,Q$2,FALSE)),IF($N12=0,IF(ISERROR(VLOOKUP($P12,'M1'!$A:$C,Q$2,FALSE)),IF(ISERROR(VLOOKUP(DATA!$P12,'M2'!$A:$C,Q$2,FALSE)),"NOT PRESENT",VLOOKUP(DATA!$P12,'M2'!$A:$C,Q$2,FALSE)),VLOOKUP($P12,'M1'!$A:$C,Q$2,FALSE)),"SPECIFY METHOD"))) -> Haliotis kamtschatkana | R12: =IF($N12=1,IF(ISERROR(VLOOKUP($P12,'M1'!$A:$C,R$2,FALSE)),"NOT PRESENT",VLOOKUP($P12,'M1'!$A:$C,R$2,FALSE)),IF($N12=2,IF(ISERROR(VLOOKUP(DATA!$P12,'M2'!$A:$C,R$2,FALSE)),"NOT PRESENT",VLOOKUP(DATA!$P12,'M2'!$A:$C,R$2,FALSE)),IF($N12=0,IF(ISERROR(VLOOKUP($P12,'M1'!$A:$C,R$2,FALSE)),IF(ISERROR(VLOOKUP(DATA!$P12,'M2'!$A:$C,R$2,FALSE)),"NOT PRESENT",VLOOKUP(DATA!$P12,'M2'!$A:$C,R$2,FALSE)),VLOOKUP($P12,'M1'!$A:$C,R$2,FALSE)),"SPECIFY METHOD"))) -> Pinto abalone | S12: =SUM(T12:AV12) -> 29 | T12: 0 | U12: 6 | V12: 14 | W12: 9
A13: =MAX($A$1:$A12)+1 -> 11 | B13: =IF(ISERROR(B12),IF(ISERROR(#REF!),IF(ISERROR(#REF!),"BLANK",#REF!),#REF!),B12) -> Em Lim | C13: =IF(ISERROR(C12),IF(ISERROR(#REF!),IF(ISERROR(#REF!),"BLANK",#REF!),#REF!),C12) -> Isabelle Côté | D13: =IF(ISERROR(D12),IF(ISERROR(#REF!),IF(ISERROR(#REF!),"BLANK",#REF!),#REF!),D12) -> BMSC8 | E13: =IF(ISERROR(VLOOKUP($D13,SITES!$A:$E,2,FALSE)),"",VLOOKUP($D13,SITES!$A:$E,2,FALSE)) -> Baeria Rocks North Island Northside | F13: =IF(ISERROR(VLOOKUP($D13,SITES!$A:$E,3,FALSE)),"",VLOOKUP($D13,SITES!$A:$E,3,FALSE)) -> 48.955082 | G13: =IF(ISERROR(VLOOKUP($D13,SITES!$A:$E,4,FALSE)),"",VLOOKUP($D13,SITES!$A:$E,4,FALSE)) -> -125.15337 | H13: =IF(ISERROR(H12),IF(ISERROR(#REF!),IF(ISERROR(#REF!),"BLANK",#REF!),#REF!),H12) -> 22/04/2024 | I13: =IF(ISERROR(I12),IF(ISERROR(#REF!),IF(ISERROR(#REF!),"BLANK",#REF!),#REF!),I12) -> 1.5 | J13: =IF(ISERROR(J12),IF(ISERROR(#REF!),IF(ISERROR(#REF!),"BLANK",#REF!),#REF!),J12) -> SE | K13: =IF(ISERROR(K12),IF(ISERROR(#REF!),IF(ISERROR(#REF!),"BLANK",#REF!),#REF!),K12) -> 0.425 | L13: =IF(ISERROR(L12),IF(ISERROR(#REF!),IF(ISERROR(#REF!),"BLANK",#REF!),#REF!),L12) -> EGL | M13: =IF(ISERROR(M12),IF(ISERROR(#REF!),IF(ISERROR(#REF!),"BLANK",#REF!),#REF!),M12) -> 8.5 | N13: =IF(ISERROR(N12),IF(ISERROR(#REF!),IF(ISERROR(#REF!),"BLANK",#REF!),#REF!),N12) -> 2 | O13: =IF(ISERROR(O12),IF(ISERROR(#REF!),IF(ISERROR(#REF!),"BLANK",#REF!),#REF!),O12) -> 2 | P13: cfo | Q13: =IF($N13=1,IF(ISERROR(VLOOKUP($P13,'M1'!$A:$C,Q$2,FALSE)),"NOT PRESENT",VLOOKUP($P13,'M1'!$A:$C,Q$2,FALSE)),IF($N13=2,IF(ISERROR(VLOOKUP(DATA!$P13,'M2'!$A:$C,Q$2,FALSE)),"NOT PRESENT",VLOOKUP(DATA!$P13,'M2'!$A:$C,Q$2,FALSE)),IF($N13=0,IF(ISERROR(VLOOKUP($P13,'M1'!$A:$C,Q$2,FALSE)),IF(ISERROR(VLOOKUP(DATA!$P13,'M2'!$A:$C,Q$2,FALSE)),"NOT PRESENT",VLOOKUP(DATA!$P13,'M2'!$A:$C,Q$2,FALSE)),VLOOKUP($P13,'M1'!$A:$C,Q$2,FALSE)),"SPECIFY METHOD"))) -> Ceratostoma foliatum | R13: =IF($N13=1,IF(ISERROR(VLOOKUP($P13,'M1'!$A:$C,R$2,FALSE)),"NOT PRESENT",VLOOKUP($P13,'M1'!$A:$C,R$2,FALSE)),IF($N13=2,IF(ISERROR(VLOOKUP(DATA!$P13,'M2'!$A:$C,R$2,FALSE)),"NOT PRESENT",VLOOKUP(DATA!$P13,'M2'!$A:$C,R$2,FALSE)),IF($N13=0,IF(ISERROR(VLOOKUP($P13,'M1'!$A:$C,R$2,FALSE)),IF(ISERROR(VLOOKUP(DATA!$P13,'M2'!$A:$C,R$2,FALSE)),"NOT PRESENT",VLOOKUP(DATA!$P13,'M2'!$A:$C,R$2,FALSE)),VLOOKUP($P13,'M1'!$A:$C,R$2,FALSE)),"SPECIFY METHOD"))) -> Leafy hornmouth | S13: =SUM(T13:AV13) -> 10 | T13: 10
A14: =MAX($A$1:$A13)+1 -> 12 | B14: =IF(ISERROR(B13),IF(ISERROR(B12),IF(ISERROR(#REF!),"BLANK",#REF!),B12),B13) -> Em Lim | C14: =IF(ISERROR(C13),IF(ISERROR(C12),IF(ISERROR(#REF!),"BLANK",#REF!),C12),C13) -> Isabelle Côté | D14: =IF(ISERROR(D13),IF(ISERROR(D12),IF(ISERROR(#REF!),"BLANK",#REF!),D12),D13) -> BMSC8 | E14: =IF(ISERROR(VLOOKUP($D14,SITES!$A:$E,2,FALSE)),"",VLOOKUP($D14,SITES!$A:$E,2,FALSE)) -> Baeria Rocks North Island Northside | F14: =IF(ISERROR(VLOOKUP($D14,SITES!$A:$E,3,FALSE)),"",VLOOKUP($D14,SITES!$A:$E,3,FALSE)) -> 48.955082 | G14: =IF(ISERROR(VLOOKUP($D14,SITES!$A:$E,4,FALSE)),"",VLOOKUP($D14,SITES!$A:$E,4,FALSE)) -> -125.15337 | H14: =IF(ISERROR(H13),IF(ISERROR(H12),IF(ISERROR(#REF!),"BLANK",#REF!),H12),H13) -> 22/04/2024 | I14: =IF(ISERROR(I13),IF(ISERROR(I12),IF(ISERROR(#REF!),"BLANK",#REF!),I12),I13) -> 1.5 | J14: =IF(ISERROR(J13),IF(ISERROR(J12),IF(ISERROR(#REF!),"BLANK",#REF!),J12),J13) -> SE | K14: =IF(ISERROR(K13),IF(ISERROR(K12),IF(ISERROR(#REF!),"BLANK",#REF!),K12),K13) -> 0.425 | L14: =IF(ISERROR(L13),IF(ISERROR(L12),IF(ISERROR(#REF!),"BLANK",#REF!),L12),L13) -> EGL | M14: =IF(ISERROR(M13),IF(ISERROR(M12),IF(ISERROR(#REF!),"BLANK",#REF!),M12),M13) -> 8.5 | N14: =IF(ISERROR(N13),IF(ISERROR(N12),IF(ISERROR(#REF!),"BLANK",#REF!),N12),N13) -> 2 | O14: =IF(ISERROR(O13),IF(ISERROR(O12),IF(ISERROR(#REF!),"BLANK",#REF!),O12),O13) -> 2 | P14: aha | Q14: =IF($N14=1,IF(ISERROR(VLOOKUP($P14,'M1'!$A:$C,Q$2,FALSE)),"NOT PRESENT",VLOOKUP($P14,'M1'!$A:$C,Q$2,FALSE)),IF($N14=2,IF(ISERROR(VLOOKUP(DATA!$P14,'M2'!$A:$C,Q$2,FALSE)),"NOT PRESENT",VLOOKUP(DATA!$P14,'M2'!$A:$C,Q$2,FALSE)),IF($N14=0,IF(ISERROR(VLOOKUP($P14,'M1'!$A:$C,Q$2,FALSE)),IF(ISERROR(VLOOKUP(DATA!$P14,'M2'!$A:$C,Q$2,FALSE)),"NOT PRESENT",VLOOKUP(DATA!$P14,'M2'!$A:$C,Q$2,FALSE)),VLOOKUP($P14,'M1'!$A:$C,Q$2,FALSE)),"SPECIFY METHOD"))) -> Artedius harringtoni | R14: =IF($N14=1,IF(ISERROR(VLOOKUP($P14,'M1'!$A:$C,R$2,FALSE)),"NOT PRESENT",VLOOKUP($P14,'M1'!$A:$C,R$2,FALSE)),IF($N14=2,IF(ISERROR(VLOOKUP(DATA!$P14,'M2'!$A:$C,R$2,FALSE)),"NOT PRESENT",VLOOKUP(DATA!$P14,'M2'!$A:$C,R$2,FALSE)),IF($N14=0,IF(ISERROR(VLOOKUP($P14,'M1'!$A:$C,R$2,FALSE)),IF(ISERROR(VLOOKUP(DATA!$P14,'M2'!$A:$C,R$2,FALSE)),"NOT PRESENT",VLOOKUP(DATA!$P14,'M2'!$A:$C,R$2,FALSE)),VLOOKUP($P14,'M1'!$A:$C,R$2,FALSE)),"SPECIFY METHOD"))) -> Scalyhead sculpin | S14: =SUM(T14:AV14) -> 1 | T14: 0 | V14: 1
A15: =MAX($A$1:$A14)+1 -> 13 | B15: =IF(ISERROR(B14),IF(ISERROR(B13),IF(ISERROR(B12),"BLANK",B12),B13),B14) -> Em Lim | C15: =IF(ISERROR(C14),IF(ISERROR(C13),IF(ISERROR(C12),"BLANK",C12),C13),C14) -> Isabelle Côté | D15: =IF(ISERROR(D14),IF(ISERROR(D13),IF(ISERROR(D12),"BLANK",D12),D13),D14) -> BMSC8 | E15: =IF(ISERROR(VLOOKUP($D15,SITES!$A:$E,2,FALSE)),"",VLOOKUP($D15,SITES!$A:$E,2,FALSE)) -> Baeria Rocks North Island Northside | F15: =IF(ISERROR(VLOOKUP($D15,SITES!$A:$E,3,FALSE)),"",VLOOKUP($D15,SITES!$A:$E,3,FALSE)) -> 48.955082 | G15: =IF(ISERROR(VLOOKUP($D15,SITES!$A:$E,4,FALSE)),"",VLOOKUP($D15,SITES!$A:$E,4,FALSE)) -> -125.15337 | H15: =IF(ISERROR(H14),IF(ISERROR(H13),IF(ISERROR(H12),"BLANK",H12),H13),H14) -> 22/04/2024 | I15: =IF(ISERROR(I14),IF(ISERROR(I13),IF(ISERROR(I12),"BLANK",I12),I13),I14) -> 1.5 | J15: =IF(ISERROR(J14),IF(ISERROR(J13),IF(ISERROR(J12),"BLANK",J12),J13),J14) -> SE | K15: =IF(ISERROR(K14),IF(ISERROR(K13),IF(ISERROR(K12),"BLANK",K12),K13),K14) -> 0.425 | L15: =IF(ISERROR(L14),IF(ISERROR(L13),IF(ISERROR(L12),"BLANK",L12),L13),L14) -> EGL | M15: =IF(ISERROR(M14),IF(ISERROR(M13),IF(ISERROR(M12),"BLANK",M12),M13),M14) -> 8.5 | N15: =IF(ISERROR(N14),IF(ISERROR(N13),IF(ISERROR(N12),"BLANK",N12),N13),N14) -> 2 | O15: =IF(ISERROR(O14),IF(ISERROR(O13),IF(ISERROR(O12),"BLANK",O12),O13),O14) -> 2 | P15: cgi | Q15: =IF($N15=1,IF(ISERROR(VLOOKUP($P15,'M1'!$A:$C,Q$2,FALSE)),"NOT PRESENT",VLOOKUP($P15,'M1'!$A:$C,Q$2,FALSE)),IF($N15=2,IF(ISERROR(VLOOKUP(DATA!$P15,'M2'!$A:$C,Q$2,FALSE)),"NOT PRESENT",VLOOKUP(DATA!$P15,'M2'!$A:$C,Q$2,FALSE)),IF($N15=0,IF(ISERROR(VLOOKUP($P15,'M1'!$A:$C,Q$2,FALSE)),IF(ISERROR(VLOOKUP(DATA!$P15,'M2'!$A:$C,Q$2,FALSE)),"NOT PRESENT",VLOOKUP(DATA!$P15,'M2'!$A:$C,Q$2,FALSE)),VLOOKUP($P15,'M1'!$A:$C,Q$2,FALSE)),"SPECIFY METHOD"))) -> Crassadoma gigantea | R15: =IF($N15=1,IF(ISERROR(VLOOKUP($P15,'M1'!$A:$C,R$2,FALSE)),"NOT PRESENT",VLOOKUP($P15,'M1'!$A:$C,R$2,FALSE)),IF($N15=2,IF(ISERROR(VLOOKUP(DATA!$P15,'M2'!$A:$C,R$2,FALSE)),"NOT PRESENT",VLOOKUP(DATA!$P15,'M2'!$A:$C,R$2,FALSE)),IF($N15=0,IF(ISERROR(VLOOKUP($P15,'M1'!$A:$C,R$2,FALSE)),IF(ISERROR(VLOOKUP(DATA!$P15,'M2'!$A:$C,R$2,FALSE)),"NOT PRESENT",VLOOKUP(DATA!$P15,'M2'!$A:$C,R$2,FALSE)),VLOOKUP($P15,'M1'!$A:$C,R$2,FALSE)),"SPECIFY METHOD"))) -> Purple-hinged rock scallop | S15: =SUM(T15:AV15) -> 3 | T15: 0 | V15: 1 | W15: 1 | Y15: 1
A16: =MAX($A$1:$A15)+1 -> 14 | B16: =IF(ISERROR(B15),IF(ISERROR(B14),IF(ISERROR(B13),"BLANK",B13),B14),B15) -> Em Lim | C16: =IF(ISERROR(C15),IF(ISERROR(C14),IF(ISERROR(C13),"BLANK",C13),C14),C15) -> Isabelle Côté | D16: =IF(ISERROR(D15),IF(ISERROR(D14),IF(ISERROR(D13),"BLANK",D13),D14),D15) -> BMSC8 | E16: =IF(ISERROR(VLOOKUP($D16,SITES!$A:$E,2,FALSE)),"",VLOOKUP($D16,SITES!$A:$E,2,FALSE)) -> Baeria Rocks North Island Northside | F16: =IF(ISERROR(VLOOKUP($D16,SITES!$A:$E,3,FALSE)),"",VLOOKUP($D16,SITES!$A:$E,3,FALSE)) -> 48.955082 | G16: =IF(ISERROR(VLOOKUP($D16,SITES!$A:$E,4,FALSE)),"",VLOOKUP($D16,SITES!$A:$E,4,FALSE)) -> -125.15337 | H16: =IF(ISERROR(H15),IF(ISERROR(H14),IF(ISERROR(H13),"BLANK",H13),H14),H15) -> 22/04/2024 | I16: =IF(ISERROR(I15),IF(ISERROR(I14),IF(ISERROR(I13),"BLANK",I13),I14),I15) -> 1.5 | J16: =IF(ISERROR(J15),IF(ISERROR(J14),IF(ISERROR(J13),"BLANK",J13),J14),J15) -> SE | K16: =IF(ISERROR(K15),IF(ISERROR(K14),IF(ISERROR(K13),"BLANK",K13),K14),K15) -> 0.425 | L16: =IF(ISERROR(L15),IF(ISERROR(L14),IF(ISERROR(L13),"BLANK",L13),L14),L15) -> EGL | M16: =IF(ISERROR(M15),IF(ISERROR(M14),IF(ISERROR(M13),"BLANK",M13),M14),M15) -> 8.5 | N16: =IF(ISERROR(N15),IF(ISERROR(N14),IF(ISERROR(N13),"BLANK",N13),N14),N15) -> 2 | O16: =IF(ISERROR(O15),IF(ISERROR(O14),IF(ISERROR(O13),"BLANK",O13),O14),O15) -> 2 | P16: hcr | Q16: =IF($N16=1,IF(ISERROR(VLOOKUP($P16,'M1'!$A:$C,Q$2,FALSE)),"NOT PRESENT",VLOOKUP($P16,'M1'!$A:$C,Q$2,FALSE)),IF($N16=2,IF(ISERROR(VLOOKUP(DATA!$P16,'M2'!$A:$C,Q$2,FALSE)),"NOT PRESENT",VLOOKUP(DATA!$P16,'M2'!$A:$C,Q$2,FALSE)),IF($N16=0,IF(ISERROR(VLOOKUP($P16,'M1'!$A:$C,Q$2,FALSE)),IF(ISERROR(VLOOKUP(DATA!$P16,'M2'!$A:$C,Q$2,FALSE)),"NOT PRESENT",VLOOKUP(DATA!$P16,'M2'!$A:$C,Q$2,FALSE)),VLOOKUP($P16,'M1'!$A:$C,Q$2,FALSE)),"SPECIFY METHOD"))) -> Hermissenda crassicornis | R16: =IF($N16=1,IF(ISERROR(VLOOKUP($P16,'M1'!$A:$C,R$2,FALSE)),"NOT PRESENT",VLOOKUP($P16,'M1'!$A:$C,R$2,FALSE)),IF($N16=2,IF(ISERROR(VLOOKUP(DATA!$P16,'M2'!$A:$C,R$2,FALSE)),"NOT PRESENT",VLOOKUP(DATA!$P16,'M2'!$A:$C,R$2,FALSE)),IF($N16=0,IF(ISERROR(VLOOKUP($P16,'M1'!$A:$C,R$2,FALSE)),IF(ISERROR(VLOOKUP(DATA!$P16,'M2'!$A:$C,R$2,FALSE)),"NOT PRESENT",VLOOKUP(DATA!$P16,'M2'!$A:$C,R$2,FALSE)),VLOOKUP($P16,'M1'!$A:$C,R$2,FALSE)),"SPECIFY METHOD"))) -> Opalescent nudibranch | S16: =SUM(T16:AV16) -> 3 | T16: 3
A17: =MAX($A$1:$A16)+1 -> 15 | B17: =IF(ISERROR(B16),IF(ISERROR(B15),IF(ISERROR(B14),"BLANK",B14),B15),B16) -> Em Lim | C17: =IF(ISERROR(C16),IF(ISERROR(C15),IF(ISERROR(C14),"BLANK",C14),C15),C16) -> Isabelle Côté | D17: =IF(ISERROR(D16),IF(ISERROR(D15),IF(ISERROR(D14),"BLANK",D14),D15),D16) -> BMSC8 | E17: =IF(ISERROR(VLOOKUP($D17,SITES!$A:$E,2,FALSE)),"",VLOOKUP($D17,SITES!$A:$E,2,FALSE)) -> Baeria Rocks North Island Northside | F17: =IF(ISERROR(VLOOKUP($D17,SITES!$A:$E,3,FALSE)),"",VLOOKUP($D17,SITES!$A:$E,3,FALSE)) -> 48.955082 | G17: =IF(ISERROR(VLOOKUP($D17,SITES!$A:$E,4,FALSE)),"",VLOOKUP($D17,SITES!$A:$E,4,FALSE)) -> -125.15337 | H17: =IF(ISERROR(H16),IF(ISERROR(H15),IF(ISERROR(H14),"BLANK",H14),H15),H16) -> 22/04/2024 | I17: =IF(ISERROR(I16),IF(ISERROR(I15),IF(ISERROR(I14),"BLANK",I14),I15),I16) -> 1.5 | J17: =IF(ISERROR(J16),IF(ISERROR(J15),IF(ISERROR(J14),"BLANK",J14),J15),J16) -> SE | K17: =IF(ISERROR(K16),IF(ISERROR(K15),IF(ISERROR(K14),"BLANK",K14),K15),K16) -> 0.425 | L17: =IF(ISERROR(L16),IF(ISERROR(L15),IF(ISERROR(L14),"BLANK",L14),L15),L16) -> EGL | M17: =IF(ISERROR(M16),IF(ISERROR(M15),IF(ISERROR(M14),"BLANK",M14),M15),M16) -> 8.5 | N17: =IF(ISERROR(N16),IF(ISERROR(N15),IF(ISERROR(N14),"BLANK",N14),N15),N16) -> 2 | O17: =IF(ISERROR(O16),IF(ISERROR(O15),IF(ISERROR(O14),"BLANK",O14),O15),O16) -> 2 | P17: pbe | Q17: =IF($N17=1,IF(ISERROR(VLOOKUP($P17,'M1'!$A:$C,Q$2,FALSE)),"NOT PRESENT",VLOOKUP($P17,'M1'!$A:$C,Q$2,FALSE)),IF($N17=2,IF(ISERROR(VLOOKUP(DATA!$P17,'M2'!$A:$C,Q$2,FALSE)),"NOT PRESENT",VLOOKUP(DATA!$P17,'M2'!$A:$C,Q$2,FALSE)),IF($N17=0,IF(ISERROR(VLOOKUP($P17,'M1'!$A:$C,Q$2,FALSE)),IF(ISERROR(VLOOKUP(DATA!$P17,'M2'!$A:$C,Q$2,FALSE)),"NOT PRESENT",VLOOKUP(DATA!$P17,'M2'!$A:$C,Q$2,FALSE)),VLOOKUP($P17,'M1'!$A:$C,Q$2,FALSE)),"SPECIFY METHOD"))) -> Pagurus beringanus | R17: =IF($N17=1,IF(ISERROR(VLOOKUP($P17,'M1'!$A:$C,R$2,FALSE)),"NOT PRESENT",VLOOKUP($P17,'M1'!$A:$C,R$2,FALSE)),IF($N17=2,IF(ISERROR(VLOOKUP(DATA!$P17,'M2'!$A:$C,R$2,FALSE)),"NOT PRESENT",VLOOKUP(DATA!$P17,'M2'!$A:$C,R$2,FALSE)),IF($N17=0,IF(ISERROR(VLOOKUP($P17,'M1'!$A:$C,R$2,FALSE)),IF(ISERROR(VLOOKUP(DATA!$P17,'M2'!$A:$C,R$2,FALSE)),"NOT PRESENT",VLOOKUP(DATA!$P17,'M2'!$A:$C,R$2,FALSE)),VLOOKUP($P17,'M1'!$A:$C,R$2,FALSE)),"SPECIFY METHOD"))) -> Bering hermit crab | S17: =SUM(T17:AV17) -> 2 | T17: 2
A18: =MAX($A$1:$A17)+1 -> 16 | B18: =IF(ISERROR(B17),IF(ISERROR(B16),IF(ISERROR(B15),"BLANK",B15),B16),B17) -> Em Lim | C18: =IF(ISERROR(C17),IF(ISERROR(C16),IF(ISERROR(C15),"BLANK",C15),C16),C17) -> Isabelle Côté | D18: =IF(ISERROR(D17),IF(ISERROR(D16),IF(ISERROR(D15),"BLANK",D15),D16),D17) -> BMSC8 | E18: =IF(ISERROR(VLOOKUP($D18,SITES!$A:$E,2,FALSE)),"",VLOOKUP($D18,SITES!$A:$E,2,FALSE)) -> Baeria Rocks North Island Northside | F18: =IF(ISERROR(VLOOKUP($D18,SITES!$A:$E,3,FALSE)),"",VLOOKUP($D18,SITES!$A:$E,3,FALSE)) -> 48.955082 | G18: =IF(ISERROR(VLOOKUP($D18,SITES!$A:$E,4,FALSE)),"",VLOOKUP($D18,SITES!$A:$E,4,FALSE)) -> -125.15337 | H18: =IF(ISERROR(H17),IF(ISERROR(H16),IF(ISERROR(H15),"BLANK",H15),H16),H17) -> 22/04/2024 | I18: =IF(ISERROR(I17),IF(ISERROR(I16),IF(ISERROR(I15),"BLANK",I15),I16),I17) -> 1.5 | J18: =IF(ISERROR(J17),IF(ISERROR(J16),IF(ISERROR(J15),"BLANK",J15),J16),J17) -> SE | K18: =IF(ISERROR(K17),IF(ISERROR(K16),IF(ISERROR(K15),"BLANK",K15),K16),K17) -> 0.425 | L18: =IF(ISERROR(L17),IF(ISERROR(L16),IF(ISERROR(L15),"BLANK",L15),L16),L17) -> EGL | M18: =IF(ISERROR(M17),IF(ISERROR(M16),IF(ISERROR(M15),"BLANK",M15),M16),M17) -> 8.5 | N18: =IF(ISERROR(N17),IF(ISERROR(N16),IF(ISERROR(N15),"BLANK",N15),N16),N17) -> 2 | O18: =IF(ISERROR(O17),IF(ISERROR(O16),IF(ISERROR(O15),"BLANK",O15),O16),O17) -> 2 | P18: poc | Q18: =IF($N18=1,IF(ISERROR(VLOOKUP($P18,'M1'!$A:$C,Q$2,FALSE)),"NOT PRESENT",VLOOKUP($P18,'M1'!$A:$C,Q$2,FALSE)),IF($N18=2,IF(ISERROR(VLOOKUP(DATA!$P18,'M2'!$A:$C,Q$2,FALSE)),"NOT PRESENT",VLOOKUP(DATA!$P18,'M2'!$A:$C,Q$2,FALSE)),IF($N18=0,IF(ISERROR(VLOOKUP($P18,'M1'!$A:$C,Q$2,FALSE)),IF(ISERROR(VLOOKUP(DATA!$P18,'M2'!$A:$C,Q$2,FALSE)),"NOT PRESENT",VLOOKUP(DATA!$P18,'M2'!$A:$C,Q$2,FALSE)),VLOOKUP($P18,'M1'!$A:$C,Q$2,FALSE)),"SPECIFY METHOD"))) -> Pisaster ochraceus | R18: =IF($N18=1,IF(ISERROR(VLOOKUP($P18,'M1'!$A:$C,R$2,FALSE)),"NOT PRESENT",VLOOKUP($P18,'M1'!$A:$C,R$2,FALSE)),IF($N18=2,IF(ISERROR(VLOOKUP(DATA!$P18,'M2'!$A:$C,R$2,FALSE)),"NOT PRESENT",VLOOKUP(DATA!$P18,'M2'!$A:$C,R$2,FALSE)),IF($N18=0,IF(ISERROR(VLOOKUP($P18,'M1'!$A:$C,R$2,FALSE)),IF(ISERROR(VLOOKUP(DATA!$P18,'M2'!$A:$C,R$2,FALSE)),"NOT PRESENT",VLOOKUP(DATA!$P18,'M2'!$A:$C,R$2,FALSE)),VLOOKUP($P18,'M1'!$A:$C,R$2,FALSE)),"SPECIFY METHOD"))) -> Purple sea star | S18: =SUM(T18:AV18) -> 41 | T18: 41
A19: =MAX($A$1:$A18)+1 -> 17 | B19: =IF(ISERROR(B18),IF(ISERROR(B17),IF(ISERROR(B16),"BLANK",B16),B17),B18) -> Em Lim | C19: =IF(ISERROR(C18),IF(ISERROR(C17),IF(ISERROR(C16),"BLANK",C16),C17),C18) -> Isabelle Côté | D19: =IF(ISERROR(D18),IF(ISERROR(D17),IF(ISERROR(D16),"BLANK",D16),D17),D18) -> BMSC8 | E19: =IF(ISERROR(VLOOKUP($D19,SITES!$A:$E,2,FALSE)),"",VLOOKUP($D19,SITES!$A:$E,2,FALSE)) -> Baeria Rocks North Island Northside | F19: =IF(ISERROR(VLOOKUP($D19,SITES!$A:$E,3,FALSE)),"",VLOOKUP($D19,SITES!$A:$E,3,FALSE)) -> 48.955082 | G19: =IF(ISERROR(VLOOKUP($D19,SITES!$A:$E,4,FALSE)),"",VLOOKUP($D19,SITES!$A:$E,4,FALSE)) -> -125.15337 | H19: =IF(ISERROR(H18),IF(ISERROR(H17),IF(ISERROR(H16),"BLANK",H16),H17),H18) -> 22/04/2024 | I19: =IF(ISERROR(I18),IF(ISERROR(I17),IF(ISERROR(I16),"BLANK",I16),I17),I18) -> 1.5 | J19: =IF(ISERROR(J18),IF(ISERROR(J17),IF(ISERROR(J16),"BLANK",J16),J17),J18) -> SE | K19: =IF(ISERROR(K18),IF(ISERROR(K17),IF(ISERROR(K16),"BLANK",K16),K17),K18) -> 0.425 | L19: =IF(ISERROR(L18),IF(ISERROR(L17),IF(ISERROR(L16),"BLANK",L16),L17),L18) -> EGL | M19: =IF(ISERROR(M18),IF(ISERROR(M17),IF(ISERROR(M16),"BLANK",M16),M17),M18) -> 8.5 | N19: =IF(ISERROR(N18),IF(ISERROR(N17),IF(ISERROR(N16),"BLANK",N16),N17),N18) -> 2 | O19: =IF(ISERROR(O18),IF(ISERROR(O17),IF(ISERROR(O16),"BLANK",O16),O17),O18) -> 2 | P19: dim | Q19: =IF($N19=1,IF(ISERROR(VLOOKUP($P19,'M1'!$A:$C,Q$2,FALSE)),"NOT PRESENT",VLOOKUP($P19,'M1'!$A:$C,Q$2,FALSE)),IF($N19=2,IF(ISERROR(VLOOKUP(DATA!$P19,'M2'!$A:$C,Q$2,FALSE)),"NOT PRESENT",VLOOKUP(DATA!$P19,'M2'!$A:$C,Q$2,FALSE)),IF($N19=0,IF(ISERROR(VLOOKUP($P19,'M1'!$A:$C,Q$2,FALSE)),IF(ISERROR(VLOOKUP(DATA!$P19,'M2'!$A:$C,Q$2,FALSE)),"NOT PRESENT",VLOOKUP(DATA!$P19,'M2'!$A:$C,Q$2,FALSE)),VLOOKUP($P19,'M1'!$A:$C,Q$2,FALSE)),"SPECIFY METHOD"))) -> Dermasterias imbricata | R19: =IF($N19=1,IF(ISERROR(VLOOKUP($P19,'M1'!$A:$C,R$2,FALSE)),"NOT PRESENT",VLOOKUP($P19,'M1'!$A:$C,R$2,FALSE)),IF($N19=2,IF(ISERROR(VLOOKUP(DATA!$P19,'M2'!$A:$C,R$2,FALSE)),"NOT PRESENT",VLOOKUP(DATA!$P19,'M2'!$A:$C,R$2,FALSE)),IF($N19=0,IF(ISERROR(VLOOKUP($P19,'M1'!$A:$C,R$2,FALSE)),IF(ISERROR(VLOOKUP(DATA!$P19,'M2'!$A:$C,R$2,FALSE)),"NOT PRESENT",VLOOKUP(DATA!$P19,'M2'!$A:$C,R$2,FALSE)),VLOOKUP($P19,'M1'!$A:$C,R$2,FALSE)),"SPECIFY METHOD"))) -> Leather star | S19: =SUM(T19:AV19) -> 4 | T19: 4
A20: =MAX($A$1:$A19)+1 -> 18 | B20: =IF(ISERROR(B19),IF(ISERROR(B18),IF(ISERROR(B17),"BLANK",B17),B18),B19) -> Em Lim | C20: =IF(ISERROR(C19),IF(ISERROR(C18),IF(ISERROR(C17),"BLANK",C17),C18),C19) -> Isabelle Côté | D20: =IF(ISERROR(D19),IF(ISERROR(D18),IF(ISERROR(D17),"BLANK",D17),D18),D19) -> BMSC8 | E20: =IF(ISERROR(VLOOKUP($D20,SITES!$A:$E,2,FALSE)),"",VLOOKUP($D20,SITES!$A:$E,2,FALSE)) -> Baeria Rocks North Island Northside | F20: =IF(ISERROR(VLOOKUP($D20,SITES!$A:$E,3,FALSE)),"",VLOOKUP($D20,SITES!$A:$E,3,FALSE)) -> 48.955082 | G20: =IF(ISERROR(VLOOKUP($D20,SITES!$A:$E,4,FALSE)),"",VLOOKUP($D20,SITES!$A:$E,4,FALSE)) -> -125.15337 | H20: =IF(ISERROR(H19),IF(ISERROR(H18),IF(ISERROR(H17),"BLANK",H17),H18),H19) -> 22/04/2024 | I20: =IF(ISERROR(I19),IF(ISERROR(I18),IF(ISERROR(I17),"BLANK",I17),I18),I19) -> 1.5 | J20: =IF(ISERROR(J19),IF(ISERROR(J18),IF(ISERROR(J17),"BLANK",J17),J18),J19) -> SE | K20: =IF(ISERROR(K19),IF(ISERROR(K18),IF(ISERROR(K17),"BLANK",K17),K18),K19) -> 0.425 | L20: =IF(ISERROR(L19),IF(ISERROR(L18),IF(ISERROR(L17),"BLANK",L17),L18),L19) -> EGL | M20: =IF(ISERROR(M19),IF(ISERROR(M18),IF(ISERROR(M17),"BLANK",M17),M18),M19) -> 8.5 | N20: =IF(ISERROR(N19),IF(ISERROR(N18),IF(ISERROR(N17),"BLANK",N17),N18),N19) -> 2 | O20: =IF(ISERROR(O19),IF(ISERROR(O18),IF(ISERROR(O17),"BLANK",O17),O18),O19) -> 2 | P20: sdr | Q20: =IF($N20=1,IF(ISERROR(VLOOKUP($P20,'M1'!$A:$C,Q$2,FALSE)),"NOT PRESENT",VLOOKUP($P20,'M1'!$A:$C,Q$2,FALSE)),IF($N20=2,IF(ISERROR(VLOOKUP(DATA!$P20,'M2'!$A:$C,Q$2,FALSE)),"NOT PRESENT",VLOOKUP(DATA!$P20,'M2'!$A:$C,Q$2,FALSE)),IF($N20=0,IF(ISERROR(VLOOKUP($P20,'M1'!$A:$C,Q$2,FALSE)),IF(ISERROR(VLOOKUP(DATA!$P20,'M2'!$A:$C,Q$2,FALSE)),"NOT PRESENT",VLOOKUP(DATA!$P20,'M2'!$A:$C,Q$2,FALSE)),VLOOKUP($P20,'M1'!$A:$C,Q$2,FALSE)),"SPECIFY METHOD"))) -> Strongylocentrotus droebachiensis | R20: =IF($N20=1,IF(ISERROR(VLOOKUP($P20,'M1'!$A:$C,R$2,FALSE)),"NOT PRESENT",VLOOKUP($P20,'M1'!$A:$C,R$2,FALSE)),IF($N20=2,IF(ISERROR(VLOOKUP(DATA!$P20,'M2'!$A:$C,R$2,FALSE)),"NOT PRESENT",VLOOKUP(DATA!$P20,'M2'!$A:$C,R$2,FALSE)),IF($N20=0,IF(ISERROR(VLOOKUP($P20,'M1'!$A:$C,R$2,FALSE)),IF(ISERROR(VLOOKUP(DATA!$P20,'M2'!$A:$C,R$2,FALSE)),"NOT PRESENT",VLOOKUP(DATA!$P20,'M2'!$A:$C,R$2,FALSE)),VLOOKUP($P20,'M1'!$A:$C,R$2,FALSE)),"SPECIFY METHOD"))) -> Northern sea urchin | S20: =SUM(T20:AV20) -> 1 | T20: 1
A21: =MAX($A$1:$A20)+1 -> 19 | B21: =IF(ISERROR(B20),IF(ISERROR(B19),IF(ISERROR(B18),"BLANK",B18),B19),B20) -> Em Lim | C21: =IF(ISERROR(C20),IF(ISERROR(C19),IF(ISERROR(C18),"BLANK",C18),C19),C20) -> Isabelle Côté | D21: =IF(ISERROR(D20),IF(ISERROR(D19),IF(ISERROR(D18),"BLANK",D18),D19),D20) -> BMSC8 | E21: =IF(ISERROR(VLOOKUP($D21,SITES!$A:$E,2,FALSE)),"",VLOOKUP($D21,SITES!$A:$E,2,FALSE)) -> Baeria Rocks North Island Northside | F21: =IF(ISERROR(VLOOKUP($D21,SITES!$A:$E,3,FALSE)),"",VLOOKUP($D21,SITES!$A:$E,3,FALSE)) -> 48.955082 | G21: =IF(ISERROR(VLOOKUP($D21,SITES!$A:$E,4,FALSE)),"",VLOOKUP($D21,SITES!$A:$E,4,FALSE)) -> -125.15337 | H21: =IF(ISERROR(H20),IF(ISERROR(H19),IF(ISERROR(H18),"BLANK",H18),H19),H20) -> 22/04/2024 | I21: =IF(ISERROR(I20),IF(ISERROR(I19),IF(ISERROR(I18),"BLANK",I18),I19),I20) -> 1.5 | J21: =IF(ISERROR(J20),IF(ISERROR(J19),IF(ISERROR(J18),"BLANK",J18),J19),J20) -> SE | K21: =IF(ISERROR(K20),IF(ISERROR(K19),IF(ISERROR(K18),"BLANK",K18),K19),K20) -> 0.425 | L21: =IF(ISERROR(L20),IF(ISERROR(L19),IF(ISERROR(L18),"BLANK",L18),L19),L20) -> EGL | M21: =IF(ISERROR(M20),IF(ISERROR(M19),IF(ISERROR(M18),"BLANK",M18),M19),M20) -> 8.5 | N21: =IF(ISERROR(N20),IF(ISERROR(N19),IF(ISERROR(N18),"BLANK",N18),N19),N20) -> 2 | O21: =IF(ISERROR(O20),IF(ISERROR(O19),IF(ISERROR(O18),"BLANK",O18),O19),O20) -> 2 | P21: spu | Q21: =IF($N21=1,IF(ISERROR(VLOOKUP($P21,'M1'!$A:$C,Q$2,FALSE)),"NOT PRESENT",VLOOKUP($P21,'M1'!$A:$C,Q$2,FALSE)),IF($N21=2,IF(ISERROR(VLOOKUP(DATA!$P21,'M2'!$A:$C,Q$2,FALSE)),"NOT PRESENT",VLOOKUP(DATA!$P21,'M2'!$A:$C,Q$2,FALSE)),IF($N21=0,IF(ISERROR(VLOOKUP($P21,'M1'!$A:$C,Q$2,FALSE)),IF(ISERROR(VLOOKUP(DATA!$P21,'M2'!$A:$C,Q$2,FALSE)),"NOT PRESENT",VLOOKUP(DATA!$P21,'M2'!$A:$C,Q$2,FALSE)),VLOOKUP($P21,'M1'!$A:$C,Q$2,FALSE)),"SPECIFY METHOD"))) -> Strongylocentrotus purpuratus | R21: =IF($N21=1,IF(ISERROR(VLOOKUP($P21,'M1'!$A:$C,R$2,FALSE)),"NOT PRESENT",VLOOKUP($P21,'M1'!$A:$C,R$2,FALSE)),IF($N21=2,IF(ISERROR(VLOOKUP(DATA!$P21,'M2'!$A:$C,R$2,FALSE)),"NOT PRESENT",VLOOKUP(DATA!$P21,'M2'!$A:$C,R$2,FALSE)),IF($N21=0,IF(ISERROR(VLOOKUP($P21,'M1'!$A:$C,R$2,FALSE)),IF(ISERROR(VLOOKUP(DATA!$P21,'M2'!$A:$C,R$2,FALSE)),"NOT PRESENT",VLOOKUP(DATA!$P21,'M2'!$A:$C,R$2,FALSE)),VLOOKUP($P21,'M1'!$A:$C,R$2,FALSE)),"SPECIFY METHOD"))) -> Purple sea urchin (?) | S21: =SUM(T21:AV21) -> 1 | T21: 1
A22: =MAX($A$1:$A21)+1 -> 20 | B22: =IF(ISERROR(B21),IF(ISERROR(B20),IF(ISERROR(B19),"BLANK",B19),B20),B21) -> Em Lim | C22: =IF(ISERROR(C21),IF(ISERROR(C20),IF(ISERROR(C19),"BLANK",C19),C20),C21) -> Isabelle Côté | D22: =IF(ISERROR(D21),IF(ISERROR(D20),IF(ISERROR(D19),"BLANK",D19),D20),D21) -> BMSC8 | E22: =IF(ISERROR(VLOOKUP($D22,SITES!$A:$E,2,FALSE)),"",VLOOKUP($D22,SITES!$A:$E,2,FALSE)) -> Baeria Rocks North Island Northside | F22: =IF(ISERROR(VLOOKUP($D22,SITES!$A:$E,3,FALSE)),"",VLOOKUP($D22,SITES!$A:$E,3,FALSE)) -> 48.955082 | G22: =IF(ISERROR(VLOOKUP($D22,SITES!$A:$E,4,FALSE)),"",VLOOKUP($D22,SITES!$A:$E,4,FALSE)) -> -125.15337 | H22: =IF(ISERROR(H21),IF(ISERROR(H20),IF(ISERROR(H19),"BLANK",H19),H20),H21) -> 22/04/2024 | I22: =IF(ISERROR(I21),IF(ISERROR(I20),IF(ISERROR(I19),"BLANK",I19),I20),I21) -> 1.5 | J22: =IF(ISERROR(J21),IF(ISERROR(J20),IF(ISERROR(J19),"BLANK",J19),J20),J21) -> SE | K22: =IF(ISERROR(K21),IF(ISERROR(K20),IF(ISERROR(K19),"BLANK",K19),K20),K21) -> 0.425 | L22: =IF(ISERROR(L21),IF(ISERROR(L20),IF(ISERROR(L19),"BLANK",L19),L20),L21) -> EGL | M22: =IF(ISERROR(M21),IF(ISERROR(M20),IF(ISERROR(M19),"BLANK",M19),M20),M21) -> 8.5 | N22: =IF(ISERROR(N21),IF(ISERROR(N20),IF(ISERROR(N19),"BLANK",N19),N20),N21) -> 2 | O22: =IF(ISERROR(O21),IF(ISERROR(O20),IF(ISERROR(O19),"BLANK",O19),O20),O21) -> 2 | P22: das | Q22: =IF($N22=1,IF(ISERROR(VLOOKUP($P22,'M1'!$A:$C,Q$2,FALSE)),"NOT PRESENT",VLOOKUP($P22,'M1'!$A:$C,Q$2,FALSE)),IF($N22=2,IF(ISERROR(VLOOKUP(DATA!$P22,'M2'!$A:$C,Q$2,FALSE)),"NOT PRESENT",VLOOKUP(DATA!$P22,'M2'!$A:$C,Q$2,FALSE)),IF($N22=0,IF(ISERROR(VLOOKUP($P22,'M1'!$A:$C,Q$2,FALSE)),IF(ISERROR(VLOOKUP(DATA!$P22,'M2'!$A:$C,Q$2,FALSE)),"NOT PRESENT",VLOOKUP(DATA!$P22,'M2'!$A:$C,Q$2,FALSE)),VLOOKUP($P22,'M1'!$A:$C,Q$2,FALSE)),"SPECIFY METHOD"))) -> Diodora aspera | R22: =IF($N22=1,IF(ISERROR(VLOOKUP($P22,'M1'!$A:$C,R$2,FALSE)),"NOT PRESENT",VLOOKUP($P22,'M1'!$A:$C,R$2,FALSE)),IF($N22=2,IF(ISERROR(VLOOKUP(DATA!$P22,'M2'!$A:$C,R$2,FALSE)),"NOT PRESENT",VLOOKUP(DATA!$P22,'M2'!$A:$C,R$2,FALSE)),IF($N22=0,IF(ISERROR(VLOOKUP($P22,'M1'!$A:$C,R$2,FALSE)),IF(ISERROR(VLOOKUP(DATA!$P22,'M2'!$A:$C,R$2,FALSE)),"NOT PRESENT",VLOOKUP(DATA!$P22,'M2'!$A:$C,R$2,FALSE)),VLOOKUP($P22,'M1'!$A:$C,R$2,FALSE)),"SPECIFY METHOD"))) -> Rough keyhole limpet | S22: =SUM(T22:AV22) -> 1 | T22: 1
A23: =MAX($A$1:$A22)+1 -> 21 | B23: =IF(ISERROR(B22),IF(ISERROR(B21),IF(ISERROR(B20),"BLANK",B20),B21),B22) -> Em Lim | C23: =IF(ISERROR(C22),IF(ISERROR(C21),IF(ISERROR(C20),"BLANK",C20),C21),C22) -> Isabelle Côté | D23: =IF(ISERROR(D22),IF(ISERROR(D21),IF(ISERROR(D20),"BLANK",D20),D21),D22) -> BMSC8 | E23: =IF(ISERROR(VLOOKUP($D23,SITES!$A:$E,2,FALSE)),"",VLOOKUP($D23,SITES!$A:$E,2,FALSE)) -> Baeria Rocks North Island Northside | F23: =IF(ISERROR(VLOOKUP($D23,SITES!$A:$E,3,FALSE)),"",VLOOKUP($D23,SITES!$A:$E,3,FALSE)) -> 48.955082 | G23: =IF(ISERROR(VLOOKUP($D23,SITES!$A:$E,4,FALSE)),"",VLOOKUP($D23,SITES!$A:$E,4,FALSE)) -> -125.15337 | H23: =IF(ISERROR(H22),IF(ISERROR(H21),IF(ISERROR(H20),"BLANK",H20),H21),H22) -> 22/04/2024 | I23: =IF(ISERROR(I22),IF(ISERROR(I21),IF(ISERROR(I20),"BLANK",I20),I21),I22) -> 1.5 | J23: =IF(ISERROR(J22),IF(ISERROR(J21),IF(ISERROR(J20),"BLANK",J20),J21),J22) -> SE | K23: =IF(ISERROR(K22),IF(ISERROR(K21),IF(ISERROR(K20),"BLANK",K20),K21),K22) -> 0.425 | L23: =IF(ISERROR(L22),IF(ISERROR(L21),IF(ISERROR(L20),"BLANK",L20),L21),L22) -> EGL | M23: =IF(ISERROR(M22),IF(ISERROR(M21),IF(ISERROR(M20),"BLANK",M20),M21),M22) -> 8.5 | N23: =IF(ISERROR(N22),IF(ISERROR(N21),IF(ISERROR(N20),"BLANK",N20),N21),N22) -> 2 | O23: =IF(ISERROR(O22),IF(ISERROR(O21),IF(ISERROR(O20),"BLANK",O20),O21),O22) -> 2 | P23: opi | Q23: =IF($N23=1,IF(ISERROR(VLOOKUP($P23,'M1'!$A:$C,Q$2,FALSE)),"NOT PRESENT",VLOOKUP($P23,'M1'!$A:$C,Q$2,FALSE)),IF($N23=2,IF(ISERROR(VLOOKUP(DATA!$P23,'M2'!$A:$C,Q$2,FALSE)),"NOT PRESENT",VLOOKUP(DATA!$P23,'M2'!$A:$C,Q$2,FALSE)),IF($N23=0,IF(ISERROR(VLOOKUP($P23,'M1'!$A:$C,Q$2,FALSE)),IF(ISERROR(VLOOKUP(DATA!$P23,'M2'!$A:$C,Q$2,FALSE)),"NOT PRESENT",VLOOKUP(DATA!$P23,'M2'!$A:$C,Q$2,FALSE)),VLOOKUP($P23,'M1'!$A:$C,Q$2,FALSE)),"SPECIFY METHOD"))) -> Oxylebius pictus | R23: =IF($N23=1,IF(ISERROR(VLOOKUP($P23,'M1'!$A:$C,R$2,FALSE)),"NOT PRESENT",VLOOKUP($P23,'M1'!$A:$C,R$2,FALSE)),IF($N23=2,IF(ISERROR(VLOOKUP(DATA!$P23,'M2'!$A:$C,R$2,FALSE)),"NOT PRESENT",VLOOKUP(DATA!$P23,'M2'!$A:$C,R$2,FALSE)),IF($N23=0,IF(ISERROR(VLOOKUP($P23,'M1'!$A:$C,R$2,FALSE)),IF(ISERROR(VLOOKUP(DATA!$P23,'M2'!$A:$C,R$2,FALSE)),"NOT PRESENT",VLOOKUP(DATA!$P23,'M2'!$A:$C,R$2,FALSE)),VLOOKUP($P23,'M1'!$A:$C,R$2,FALSE)),"SPECIFY METHOD"))) -> Painted greenling | S23: =SUM(T23:AV23) -> 1 | T23: 0 | Z23: 1
A24: =MAX($A$1:$A23)+1 -> 22 | B24: =IF(ISERROR(B23),IF(ISERROR(B22),IF(ISERROR(B21),"BLANK",B21),B22),B23) -> Em Lim | C24: =IF(ISERROR(C23),IF(ISERROR(C22),IF(ISERROR(C21),"BLANK",C21),C22),C23) -> Isabelle Côté | D24: =IF(ISERROR(D23),IF(ISERROR(D22),IF(ISERROR(D21),"BLANK",D21),D22),D23) -> BMSC8 | E24: =IF(ISERROR(VLOOKUP($D24,SITES!$A:$E,2,FALSE)),"",VLOOKUP($D24,SITES!$A:$E,2,FALSE)) -> Baeria Rocks North Island Northside | F24: =IF(ISERROR(VLOOKUP($D24,SITES!$A:$E,3,FALSE)),"",VLOOKUP($D24,SITES!$A:$E,3,FALSE)) -> 48.955082 | G24: =IF(ISERROR(VLOOKUP($D24,SITES!$A:$E,4,FALSE)),"",VLOOKUP($D24,SITES!$A:$E,4,FALSE)) -> -125.15337 | H24: =IF(ISERROR(H23),IF(ISERROR(H22),IF(ISERROR(H21),"BLANK",H21),H22),H23) -> 22/04/2024 | I24: =IF(ISERROR(I23),IF(ISERROR(I22),IF(ISERROR(I21),"BLANK",I21),I22),I23) -> 1.5 | J24: =IF(ISERROR(J23),IF(ISERROR(J22),IF(ISERROR(J21),"BLANK",J21),J22),J23) -> SE | K24: =IF(ISERROR(K23),IF(ISERROR(K22),IF(ISERROR(K21),"BLANK",K21),K22),K23) -> 0.425 | L24: =IF(ISERROR(L23),IF(ISERROR(L22),IF(ISERROR(L21),"BLANK",L21),L22),L23) -> EGL | M24: =IF(ISERROR(M23),IF(ISERROR(M22),IF(ISERROR(M21),"BLANK",M21),M22),M23) -> 8.5 | N24: =IF(ISERROR(N23),IF(ISERROR(N22),IF(ISERROR(N21),"BLANK",N21),N22),N23) -> 2 | O24: =IF(ISERROR(O23),IF(ISERROR(O22),IF(ISERROR(O21),"BLANK",O21),O22),O23) -> 2 | P24: gor | Q24: =IF($N24=1,IF(ISERROR(VLOOKUP($P24,'M1'!$A:$C,Q$2,FALSE)),"NOT PRESENT",VLOOKUP($P24,'M1'!$A:$C,Q$2,FALSE)),IF($N24=2,IF(ISERROR(VLOOKUP(DATA!$P24,'M2'!$A:$C,Q$2,FALSE)),"NOT PRESENT",VLOOKUP(DATA!$P24,'M2'!$A:$C,Q$2,FALSE)),IF($N24=0,IF(ISERROR(VLOOKUP($P24,'M1'!$A:$C,Q$2,FALSE)),IF(ISERROR(VLOOKUP(DATA!$P24,'M2'!$A:$C,Q$2,FALSE)),"NOT PRESENT",VLOOKUP(DATA!$P24,'M2'!$A:$C,Q$2,FALSE)),VLOOKUP($P24,'M1'!$A:$C,Q$2,FALSE)),"SPECIFY METHOD"))) -> Glebocarcinus oregonensis | R24: =IF($N24=1,IF(ISERROR(VLOOKUP($P24,'M1'!$A:$C,R$2,FALSE)),"NOT PRESENT",VLOOKUP($P24,'M1'!$A:$C,R$2,FALSE)),IF($N24=2,IF(ISERROR(VLOOKUP(DATA!$P24,'M2'!$A:$C,R$2,FALSE)),"NOT PRESENT",VLOOKUP(DATA!$P24,'M2'!$A:$C,R$2,FALSE)),IF($N24=0,IF(ISERROR(VLOOKUP($P24,'M1'!$A:$C,R$2,FALSE)),IF(ISERROR(VLOOKUP(DATA!$P24,'M2'!$A:$C,R$2,FALSE)),"NOT PRESENT",VLOOKUP(DATA!$P24,'M2'!$A:$C,R$2,FALSE)),VLOOKUP($P24,'M1'!$A:$C,R$2,FALSE)),"SPECIFY METHOD"))) -> Pygmy rock crab | S24: =SUM(T24:AV24) -> 1 | T24: 1
A25: =MAX($A$1:$A24)+1 -> 23 | B25: =IF(ISERROR(B24),IF(ISERROR(B23),IF(ISERROR(B22),"BLANK",B22),B23),B24) -> Em Lim | C25: =IF(ISERROR(C24),IF(ISERROR(C23),IF(ISERROR(C22),"BLANK",C22),C23),C24) -> Isabelle Côté | D25: =IF(ISERROR(D24),IF(ISERROR(D23),IF(ISERROR(D22),"BLANK",D22),D23),D24) -> BMSC8 | E25: =IF(ISERROR(VLOOKUP($D25,SITES!$A:$E,2,FALSE)),"",VLOOKUP($D25,SITES!$A:$E,2,FALSE)) -> Baeria Rocks North Island Northside | F25: =IF(ISERROR(VLOOKUP($D25,SITES!$A:$E,3,FALSE)),"",VLOOKUP($D25,SITES!$A:$E,3,FALSE)) -> 48.955082 | G25: =IF(ISERROR(VLOOKUP($D25,SITES!$A:$E,4,FALSE)),"",VLOOKUP($D25,SITES!$A:$E,4,FALSE)) -> -125.15337 | H25: =IF(ISERROR(H24),IF(ISERROR(H23),IF(ISERROR(H22),"BLANK",H22),H23),H24) -> 22/04/2024 | I25: =IF(ISERROR(I24),IF(ISERROR(I23),IF(ISERROR(I22),"BLANK",I22),I23),I24) -> 1.5 | J25: =IF(ISERROR(J24),IF(ISERROR(J23),IF(ISERROR(J22),"BLANK",J22),J23),J24) -> SE | K25: =IF(ISERROR(K24),IF(ISERROR(K23),IF(ISERROR(K22),"BLANK",K22),K23),K24) -> 0.425 | L25: =IF(ISERROR(L24),IF(ISERROR(L23),IF(ISERROR(L22),"BLANK",L22),L23),L24) -> EGL | M25: =IF(ISERROR(M24),IF(ISERROR(M23),IF(ISERROR(M22),"BLANK",M22),M23),M24) -> 8.5 | N25: =IF(ISERROR(N24),IF(ISERROR(N23),IF(ISERROR(N22),"BLANK",N22),N23),N24) -> 2 | O25: =IF(ISERROR(O24),IF(ISERROR(O23),IF(ISERROR(O22),"BLANK",O22),O23),O24) -> 2 | P25: pcau | Q25: =IF($N25=1,IF(ISERROR(VLOOKUP($P25,'M1'!$A:$C,Q$2,FALSE)),"NOT PRESENT",VLOOKUP($P25,'M1'!$A:$C,Q$2,FALSE)),IF($N25=2,IF(ISERROR(VLOOKUP(DATA!$P25,'M2'!$A:$C,Q$2,FALSE)),"NOT PRESENT",VLOOKUP(DATA!$P25,'M2'!$A:$C,Q$2,FALSE)),IF($N25=0,IF(ISERROR(VLOOKUP($P25,'M1'!$A:$C,Q$2,FALSE)),IF(ISERROR(VLOOKUP(DATA!$P25,'M2'!$A:$C,Q$2,FALSE)),"NOT PRESENT",VLOOKUP(DATA!$P25,'M2'!$A:$C,Q$2,FALSE)),VLOOKUP($P25,'M1'!$A:$C,Q$2,FALSE)),"SPECIFY METHOD"))) -> Pagurus caurinus | R25: =IF($N25=1,IF(ISERROR(VLOOKUP($P25,'M1'!$A:$C,R$2,FALSE)),"NOT PRESENT",VLOOKUP($P25,'M1'!$A:$C,R$2,FALSE)),IF($N25=2,IF(ISERROR(VLOOKUP(DATA!$P25,'M2'!$A:$C,R$2,FALSE)),"NOT PRESENT",VLOOKUP(DATA!$P25,'M2'!$A:$C,R$2,FALSE)),IF($N25=0,IF(ISERROR(VLOOKUP($P25,'M1'!$A:$C,R$2,FALSE)),IF(ISERROR(VLOOKUP(DATA!$P25,'M2'!$A:$C,R$2,FALSE)),"NOT PRESENT",VLOOKUP(DATA!$P25,'M2'!$A:$C,R$2,FALSE)),VLOOKUP($P25,'M1'!$A:$C,R$2,FALSE)),"SPECIFY METHOD"))) -> Greenmark hermit crab | S25: =SUM(T25:AV25) -> 1 | T25: 1
A26: =MAX($A$1:$A25)+1 -> 24 | B26: =IF(ISERROR(B25),IF(ISERROR(B24),IF(ISERROR(B23),"BLANK",B23),B24),B25) -> Em Lim | C26: =IF(ISERROR(C25),IF(ISERROR(C24),IF(ISERROR(C23),"BLANK",C23),C24),C25) -> Isabelle Côté | D26: =IF(ISERROR(D25),IF(ISERROR(D24),IF(ISERROR(D23),"BLANK",D23),D24),D25) -> BMSC8 | E26: =IF(ISERROR(VLOOKUP($D26,SITES!$A:$E,2,FALSE)),"",VLOOKUP($D26,SITES!$A:$E,2,FALSE)) -> Baeria Rocks North Island Northside | F26: =IF(ISERROR(VLOOKUP($D26,SITES!$A:$E,3,FALSE)),"",VLOOKUP($D26,SITES!$A:$E,3,FALSE)) -> 48.955082 | G26: =IF(ISERROR(VLOOKUP($D26,SITES!$A:$E,4,FALSE)),"",VLOOKUP($D26,SITES!$A:$E,4,FALSE)) -> -125.15337 | H26: =IF(ISERROR(H25),IF(ISERROR(H24),IF(ISERROR(H23),"BLANK",H23),H24),H25) -> 22/04/2024 | I26: =IF(ISERROR(I25),IF(ISERROR(I24),IF(ISERROR(I23),"BLANK",I23),I24),I25) -> 1.5 | J26: =IF(ISERROR(J25),IF(ISERROR(J24),IF(ISERROR(J23),"BLANK",J23),J24),J25) -> SE | K26: =IF(ISERROR(K25),IF(ISERROR(K24),IF(ISERROR(K23),"BLANK",K23),K24),K25) -> 0.425 | L26: =IF(ISERROR(L25),IF(ISERROR(L24),IF(ISERROR(L23),"BLANK",L23),L24),L25) -> EGL | M26: =IF(ISERROR(M25),IF(ISERROR(M24),IF(ISERROR(M23),"BLANK",M23),M24),M25) -> 8.5 | N26: =IF(ISERROR(N25),IF(ISERROR(N24),IF(ISERROR(N23),"BLANK",N23),N24),N25) -> 2 | O26: =IF(ISERROR(O25),IF(ISERROR(O24),IF(ISERROR(O23),"BLANK",O23),O24),O25) -> 2 | P26: dez | Q26: =IF($N26=1,IF(ISERROR(VLOOKUP($P26,'M1'!$A:$C,Q$2,FALSE)),"NOT PRESENT",VLOOKUP($P26,'M1'!$A:$C,Q$2,FALSE)),IF($N26=2,IF(ISERROR(VLOOKUP(DATA!$P26,'M2'!$A:$C,Q$2,FALSE)),"NOT PRESENT",VLOOKUP(DATA!$P26,'M2'!$A:$C,Q$2,FALSE)),IF($N26=0,IF(ISERROR(VLOOKUP($P26,'M1'!$A:$C,Q$2,FALSE)),IF(ISERROR(VLOOKUP(DATA!$P26,'M2'!$A:$C,Q$2,FALSE)),"NOT PRESENT",VLOOKUP(DATA!$P26,'M2'!$A:$C,Q$2,FALSE)),VLOOKUP($P26,'M1'!$A:$C,Q$2,FALSE)),"SPECIFY METHOD"))) -> Debris - Zero | R26: =IF($N26=1,IF(ISERROR(VLOOKUP($P26,'M1'!$A:$C,R$2,FALSE)),"NOT PRESENT",VLOOKUP($P26,'M1'!$A:$C,R$2,FALSE)),IF($N26=2,IF(ISERROR(VLOOKUP(DATA!$P26,'M2'!$A:$C,R$2,FALSE)),"NOT PRESENT",VLOOKUP(DATA!$P26,'M2'!$A:$C,R$2,FALSE)),IF($N26=0,IF(ISERROR(VLOOKUP($P26,'M1'!$A:$C,R$2,FALSE)),IF(ISERROR(VLOOKUP(DATA!$P26,'M2'!$A:$C,R$2,FALSE)),"NOT PRESENT",VLOOKUP(DATA!$P26,'M2'!$A:$C,R$2,FALSE)),VLOOKUP($P26,'M1'!$A:$C,R$2,FALSE)),"SPECIFY METHOD"))) -> No Debris found | S26: =SUM(T26:AV26) -> 1 | T26: 1
